Workbook

Sheet Start Here
A1: EXCEL LAB · 06 DATA CLEANING & TEXT
A2: The workbook that turns a copy-pasted mess into usable data: TRIM and PROPER, splitting codes with FIND and MID, rescuing numbers and dates trapped in text, duplicates, match keys and a full import validator.
A4: HOW TO USE THIS WORKBOOK
A5: 1 | B5: Work through the lessons in order — each one is harder than the last (★ to ★★★★★).
A6: 2 | B6: Read the Concept box at the top of each lesson, then look at the data.
A7: 3 | B7: Type a FORMULA in each yellow cell. The Check column marks it ✓ or ✗ instantly.
A8: 4 | B8: Blue cells are inputs. Change them and watch every answer update — that is how you know your formula is really right.
A9: 5 | B9: Stuck? Read the Hint. Still stuck? The Solutions sheet shows the model answer and other ways to do it.
A11: COLOUR CODE
B12: Yellow — your answer goes here (always a formula)
B13: Blue — an input you can change
B14: ✓ Correct — marked automatically
B15: ✗ Check again — the result does not match
B16: ✎ You typed a value — replace it with a formula
A18: # | B18: Lesson | C18: Difficulty | D18: Tasks | E18: Solved | F18: Progress
A19: 1 | B19: L1 Spaces and capitals | C19: ★☆☆☆☆ | D19: 5 | E19: =COUNTIF('L1 Spaces and capitals'!H9:H13,"✓*") -> 0 | F19: =IFERROR(E19/D19,0) -> 0
A20: 2 | B20: L2 Cutting text apart | C20: ★★☆☆☆ | D20: 6 | E20: =COUNTIF('L2 Cutting text apart'!J9:J14,"✓*") -> 0 | F20: =IFERROR(E20/D20,0) -> 0
A21: 3 | B21: L3 Numbers and dates trapped in | C21: ★★★☆☆ | D21: 6 | E21: =COUNTIF('L3 Numbers and dates trapped in'!J9:J14,"✓*") -> 0 | F21: =IFERROR(E21/D21,0) -> 0
A22: 4 | B22: L4 Duplicates | C22: ★★★☆☆ | D22: 5 | E22: =COUNTIF('L4 Duplicates'!J9:J13,"✓*") -> 0 | F22: =IFERROR(E22/D22,0) -> 0
A23: 5 | B23: L5 Joining text and building ke | C23: ★★★★☆ | D23: 5 | E23: =COUNTIF('L5 Joining text and building ke'!J9:J13,"✓*") -> 0 | F23: =IFERROR(E23/D23,0) -> 0
A24: 6 | B24: L6 Boss round — validate the im | C24: ★★★★★ | D24: 6 | E24: =COUNTIF('L6 Boss round — validate the im'!J9:J14,"✓*") -> 0 | F24: =IFERROR(E24/D24,0) -> 0
B25: OVERALL | D25: =SUM(D19:D24) -> 33 | E25: =SUM(E19:E24) -> 0 | F25: =IFERROR(E25/D25,0) -> 0
A27: Excel Lab — created by Pranay · excel-lab-by-pranay.vercel.app · free for every student

Sheet L1 Spaces and capitals
A1: LESSON 1 · SPACES AND CAPITALS
A2: ★☆☆☆☆ Make a copy-pasted name list look like it came from a system, not a chat window.
A3: CONCEPT · TRIM removes leading and trailing spaces AND squeezes runs of spaces inside the text down to one. PROPER capitalises the first letter of each word; UPPER and LOWER do what they say. LEN counts characters — comparing LEN before and after TRIM tells you how dirty the data really was. Clean first, capitalise second: PROPER(TRIM(text)), never the other way round.
A8: Raw Name | B8: Clean Name | C8: Chars removed | E8: # | F8: Task | G8: Your answer | H8: Check | I8: Hint
A9: Rahul Kulkarni | E9: 1 | F9: Fill Clean Name: no stray spaces, each word capitalised. | G9: → fill column B | H9: =IF(COUNTA($B$9:$B$36)=0,"◯ Not attempted",IF(NOT(_xlfn.ISFORMULA(B9)),"✎ Use a formula",IFERROR(IF(SUMPRODUCT(--(UPPER(TRIM($B$9:$B$36&""))=UPPER(TRIM($K$9:$K$36&""))))=ROWS($B$9:$B$36),"✓ Correct","✗ "&(ROWS($B$9:$B$36)-SUMPRODUCT(--(UPPER(TRIM($B$9:$B$36&""))=UPPER(TRIM($K$9:$K$36&"")))))&" rows differ"),"✗ Check the column"))) -> ◯ Not attempted | I9: =PROPER(TRIM(A9)) | K9: =PROPER(TRIM(A9)) -> Rahul Kulkarni | L9: =LEN(A9)-LEN(TRIM(A9)) -> 0
A10: PRIYA GUPTA | E10: 2 | F10: Fill Chars removed: how many characters TRIM took out of each raw name. | G10: → fill column C | H10: =IF(COUNTA($C$9:$C$36)=0,"◯ Not attempted",IF(NOT(_xlfn.ISFORMULA(C9)),"✎ Use a formula",IFERROR(IF(SUMPRODUCT(--(ABS($C$9:$C$36-$L$9:$L$36)<0.01))=ROWS($C$9:$C$36),"✓ Correct","✗ "&(ROWS($C$9:$C$36)-SUMPRODUCT(--(ABS($C$9:$C$36-$L$9:$L$36)<0.01)))&" rows differ"),"✗ Check the column"))) -> ◯ Not attempted | I10: =LEN(A9)-LEN(TRIM(A9)) | K10: =PROPER(TRIM(A10)) -> Priya Gupta | L10: =LEN(A10)-LEN(TRIM(A10)) -> 4
A11: AMIT NAIK | E11: 3 | F11: How many names needed cleaning at all? | H11: =IF(ISBLANK(G11),"◯ Not attempted",IF(NOT(_xlfn.ISFORMULA(G11)),"✎ Use a formula",IF(ISNUMBER(G11),IF(ABS(G11-$J$11)<0.005,"✓ Correct","✗ Check again"),"✗ Not a number"))) -> ◯ Not attempted | I11: Count the rows where something was removed. | J11: =15 -> 15 | K11: =PROPER(TRIM(A11)) -> Amit Naik | L11: =LEN(A11)-LEN(TRIM(A11)) -> 0
A12: SNEHA RAO | E12: 4 | F12: Total characters removed across the whole list. | H12: =IF(ISBLANK(G12),"◯ Not attempted",IF(NOT(_xlfn.ISFORMULA(G12)),"✎ Use a formula",IF(ISNUMBER(G12),IF(ABS(G12-$J$12)<0.005,"✓ Correct","✗ Check again"),"✗ Not a number"))) -> ◯ Not attempted | I12: SUM your new column. | J12: =50 -> 50 | K12: =PROPER(TRIM(A12)) -> Sneha Rao | L12: =LEN(A12)-LEN(TRIM(A12)) -> 0
A13: VIKRAM REDDY | E13: 5 | F13: How many cleaned names are longer than 12 characters? | H13: =IF(ISBLANK(G13),"◯ Not attempted",IF(NOT(_xlfn.ISFORMULA(G13)),"✎ Use a formula",IF(ISNUMBER(G13),IF(ABS(G13-$J$13)<0.005,"✓ Correct","✗ Check again"),"✗ Not a number"))) -> ◯ Not attempted | I13: SUMPRODUCT can apply LEN to a whole column at once; the -- turns TRUE/FALSE into 1/0. | J13: =6 -> 6 | K13: =PROPER(TRIM(A13)) -> Vikram Reddy | L13: =LEN(A13)-LEN(TRIM(A13)) -> 4
A14: Neha Verma | K14: =PROPER(TRIM(A14)) -> Neha Verma | L14: =LEN(A14)-LEN(TRIM(A14)) -> 3
A15: ARJUN JOSHI | K15: =PROPER(TRIM(A15)) -> Arjun Joshi | L15: =LEN(A15)-LEN(TRIM(A15)) -> 4
A16: Kavya Chopra | K16: =PROPER(TRIM(A16)) -> Kavya Chopra | L16: =LEN(A16)-LEN(TRIM(A16)) -> 0
A17: ROHIT GHOSH | K17: =PROPER(TRIM(A17)) -> Rohit Ghosh | L17: =LEN(A17)-LEN(TRIM(A17)) -> 0
A18: ANANYA NAIR | K18: =PROPER(TRIM(A18)) -> Ananya Nair | L18: =LEN(A18)-LEN(TRIM(A18)) -> 4
A19: Siddharth Pillai | K19: =PROPER(TRIM(A19)) -> Siddharth Pillai | L19: =LEN(A19)-LEN(TRIM(A19)) -> 0
A20: ishita sharma | K20: =PROPER(TRIM(A20)) -> Ishita Sharma | L20: =LEN(A20)-LEN(TRIM(A20)) -> 2
A21: MANISH DESAI | K21: =PROPER(TRIM(A21)) -> Manish Desai | L21: =LEN(A21)-LEN(TRIM(A21)) -> 4
A22: pooja shetty | K22: =PROPER(TRIM(A22)) -> Pooja Shetty | L22: =LEN(A22)-LEN(TRIM(A22)) -> 2
A23: karan iyer | K23: =PROPER(TRIM(A23)) -> Karan Iyer | L23: =LEN(A23)-LEN(TRIM(A23)) -> 2
A24: Divya Mehta | K24: =PROPER(TRIM(A24)) -> Divya Mehta | L24: =LEN(A24)-LEN(TRIM(A24)) -> 0
A25: NIKHIL MALHOTRA | K25: =PROPER(TRIM(A25)) -> Nikhil Malhotra | L25: =LEN(A25)-LEN(TRIM(A25)) -> 4
... A36: KAVYA CHOPRA | K36: =PROPER(TRIM(A36)) -> Kavya Chopra | L36: =LEN(A36)-LEN(TRIM(A36)) -> 0

Sheet L2 Cutting text apart
A1: LESSON 2 · CUTTING TEXT APART
A2: ★★☆☆☆ Split a product code and an email into the pieces you can actually filter on.
A3: CONCEPT · LEFT(text,n) takes characters from the start, RIGHT(text,n) from the end, MID(text,start,n) from anywhere. FIND(what,text) returns the POSITION of a character — that is how you cut at a separator you cannot count to. FIND is case-sensitive; SEARCH is not and accepts wildcards. VALUE turns a text digit string into a real number.
A8: Code | B8: Email | C8: State | D8: Serial | E8: Domain | G8: # | H8: Task | I8: Your answer | J8: Check | K8: Hint
A9: MH-40000-TX | B9: rahul.kulkarni@gmail.com | G9: 1 | H9: Fill State: the two letters before the first dash. | I9: → fill column C | J9: =IF(COUNTA($C$9:$C$34)=0,"◯ Not attempted",IF(NOT(_xlfn.ISFORMULA(C9)),"✎ Use a formula",IFERROR(IF(SUMPRODUCT(--(UPPER(TRIM($C$9:$C$34&""))=UPPER(TRIM($M$9:$M$34&""))))=ROWS($C$9:$C$34),"✓ Correct","✗ "&(ROWS($C$9:$C$34)-SUMPRODUCT(--(UPPER(TRIM($C$9:$C$34&""))=UPPER(TRIM($M$9:$M$34&"")))))&" rows differ"),"✗ Check the column"))) -> ◯ Not attempted | K9: =LEFT(A9,2) | M9: =LEFT(A9,2) -> MH | N9: =VALUE(MID(A9,FIND("-",A9)+1,5)) -> 40000 | O9: =LOWER(MID(B9,FIND("@",B9)+1,99)) -> gmail.com
A10: GJ-40137-IT | B10: priya.gupta@outlook.com | G10: 2 | H10: Fill Serial: the number between the two dashes, as a real number. | I10: → fill column D | J10: =IF(COUNTA($D$9:$D$34)=0,"◯ Not attempted",IF(NOT(_xlfn.ISFORMULA(D9)),"✎ Use a formula",IFERROR(IF(SUMPRODUCT(--(ABS($D$9:$D$34-$N$9:$N$34)<0.01))=ROWS($D$9:$D$34),"✓ Correct","✗ "&(ROWS($D$9:$D$34)-SUMPRODUCT(--(ABS($D$9:$D$34-$N$9:$N$34)<0.01)))&" rows differ"),"✗ Check the column"))) -> ◯ Not attempted | K10: =VALUE(MID(A9,FIND("-",A9)+1,5)) | M10: =LEFT(A10,2) -> GJ | N10: =VALUE(MID(A10,FIND("-",A10)+1,5)) -> 40137 | O10: =LOWER(MID(B10,FIND("@",B10)+1,99)) -> outlook.com
A11: KA-40274-SV | B11: amit.naik@gmail.com | G11: 3 | H11: Fill Domain: everything after the @, in lower case. | I11: → fill column E | J11: =IF(COUNTA($E$9:$E$34)=0,"◯ Not attempted",IF(NOT(_xlfn.ISFORMULA(E9)),"✎ Use a formula",IFERROR(IF(SUMPRODUCT(--(UPPER(TRIM($E$9:$E$34&""))=UPPER(TRIM($O$9:$O$34&""))))=ROWS($E$9:$E$34),"✓ Correct","✗ "&(ROWS($E$9:$E$34)-SUMPRODUCT(--(UPPER(TRIM($E$9:$E$34&""))=UPPER(TRIM($O$9:$O$34&"")))))&" rows differ"),"✗ Check the column"))) -> ◯ Not attempted | K11: =LOWER(MID(B9,FIND("@",B9)+1,99)) — 99 just means "to the end". | M11: =LEFT(A11,2) -> KA | N11: =VALUE(MID(A11,FIND("-",A11)+1,5)) -> 40274 | O11: =LOWER(MID(B11,FIND("@",B11)+1,99)) -> gmail.com
A12: TN-40411-PK | B12: sneha.rao@company.co.in | G12: 4 | H12: How many contacts use gmail.com? | J12: =IF(ISBLANK(I12),"◯ Not attempted",IF(NOT(_xlfn.ISFORMULA(I12)),"✎ Use a formula",IF(ISNUMBER(I12),IF(ABS(I12-$L$12)<0.005,"✓ Correct","✗ Check again"),"✗ Not a number"))) -> ◯ Not attempted | K12: COUNTIF on your Domain column. | L12: =COUNTIF($B$9:$B$34,"*@gmail.com") -> 13 | M12: =LEFT(A12,2) -> TN | N12: =VALUE(MID(A12,FIND("-",A12)+1,5)) -> 40411 | O12: =LOWER(MID(B12,FIND("@",B12)+1,99)) -> company.co.in
A13: DL-40548-LG | B13: vikram.reddy@gmail.com | G13: 5 | H13: The highest serial number in the list. | J13: =IF(ISBLANK(I13),"◯ Not attempted",IF(NOT(_xlfn.ISFORMULA(I13)),"✎ Use a formula",IF(ISNUMBER(I13),IF(ABS(I13-$L$13)<0.005,"✓ Correct","✗ Check again"),"✗ Not a number"))) -> ◯ Not attempted | K13: MAX on your Serial column. | L13: =43425 -> 43425 | M13: =LEFT(A13,2) -> DL | N13: =VALUE(MID(A13,FIND("-",A13)+1,5)) -> 40548 | O13: =LOWER(MID(B13,FIND("@",B13)+1,99)) -> gmail.com
A14: MH-40685-TX | B14: neha.verma@yahoo.in | G14: 6 | H14: How many codes are from Maharashtra (MH)? | J14: =IF(ISBLANK(I14),"◯ Not attempted",IF(NOT(_xlfn.ISFORMULA(I14)),"✎ Use a formula",IF(ISNUMBER(I14),IF(ABS(I14-$L$14)<0.005,"✓ Correct","✗ Check again"),"✗ Not a number"))) -> ◯ Not attempted | K14: COUNTIF on State, or SUMPRODUCT straight off the code. | L14: =SUMPRODUCT(--(LEFT($A$9:$A$34,2)="MH")) -> 6 | M14: =LEFT(A14,2) -> MH | N14: =VALUE(MID(A14,FIND("-",A14)+1,5)) -> 40685 | O14: =LOWER(MID(B14,FIND("@",B14)+1,99)) -> yahoo.in
A15: GJ-40822-IT | B15: arjun.joshi@gmail.com | M15: =LEFT(A15,2) -> GJ | N15: =VALUE(MID(A15,FIND("-",A15)+1,5)) -> 40822 | O15: =LOWER(MID(B15,FIND("@",B15)+1,99)) -> gmail.com
A16: KA-40959-SV | B16: kavya.chopra@outlook.com | M16: =LEFT(A16,2) -> KA | N16: =VALUE(MID(A16,FIND("-",A16)+1,5)) -> 40959 | O16: =LOWER(MID(B16,FIND("@",B16)+1,99)) -> outlook.com
A17: TN-41096-PK | B17: rohit.ghosh@gmail.com | M17: =LEFT(A17,2) -> TN | N17: =VALUE(MID(A17,FIND("-",A17)+1,5)) -> 41096 | O17: =LOWER(MID(B17,FIND("@",B17)+1,99)) -> gmail.com
A18: DL-41233-LG | B18: ananya.nair@company.co.in | M18: =LEFT(A18,2) -> DL | N18: =VALUE(MID(A18,FIND("-",A18)+1,5)) -> 41233 | O18: =LOWER(MID(B18,FIND("@",B18)+1,99)) -> company.co.in
A19: MH-41370-TX | B19: siddharth.pillai@gmail.com | M19: =LEFT(A19,2) -> MH | N19: =VALUE(MID(A19,FIND("-",A19)+1,5)) -> 41370 | O19: =LOWER(MID(B19,FIND("@",B19)+1,99)) -> gmail.com
A20: GJ-41507-IT | B20: ishita.sharma@yahoo.in | M20: =LEFT(A20,2) -> GJ | N20: =VALUE(MID(A20,FIND("-",A20)+1,5)) -> 41507 | O20: =LOWER(MID(B20,FIND("@",B20)+1,99)) -> yahoo.in
A21: KA-41644-SV | B21: manish.desai@gmail.com | M21: =LEFT(A21,2) -> KA | N21: =VALUE(MID(A21,FIND("-",A21)+1,5)) -> 41644 | O21: =LOWER(MID(B21,FIND("@",B21)+1,99)) -> gmail.com
A22: TN-41781-PK | B22: pooja.shetty@outlook.com | M22: =LEFT(A22,2) -> TN | N22: =VALUE(MID(A22,FIND("-",A22)+1,5)) -> 41781 | O22: =LOWER(MID(B22,FIND("@",B22)+1,99)) -> outlook.com
A23: DL-41918-LG | B23: karan.iyer@gmail.com | M23: =LEFT(A23,2) -> DL | N23: =VALUE(MID(A23,FIND("-",A23)+1,5)) -> 41918 | O23: =LOWER(MID(B23,FIND("@",B23)+1,99)) -> gmail.com
A24: MH-42055-TX | B24: divya.mehta@company.co.in | M24: =LEFT(A24,2) -> MH | N24: =VALUE(MID(A24,FIND("-",A24)+1,5)) -> 42055 | O24: =LOWER(MID(B24,FIND("@",B24)+1,99)) -> company.co.in
A25: GJ-42192-IT | B25: nikhil.malhotra@gmail.com | M25: =LEFT(A25,2) -> GJ | N25: =VALUE(MID(A25,FIND("-",A25)+1,5)) -> 42192 | O25: =LOWER(MID(B25,FIND("@",B25)+1,99)) -> gmail.com
A26: KA-42329-SV | B26: meghna.patel@yahoo.in | M26: =LEFT(A26,2) -> KA | N26: =VALUE(MID(A26,FIND("-",A26)+1,5)) -> 42329 | O26: =LOWER(MID(B26,FIND("@",B26)+1,99)) -> yahoo.in
... A34: MH-43425-TX | B34: neha.verma@outlook.com | M34: =LEFT(A34,2) -> MH | N34: =VALUE(MID(A34,FIND("-",A34)+1,5)) -> 43425 | O34: =LOWER(MID(B34,FIND("@",B34)+1,99)) -> outlook.com

Sheet L3 Numbers and dates trapped in
A1: LESSON 3 · NUMBERS AND DATES TRAPPED IN TEXT
A2: ★★★☆☆ A bank download where nothing adds up — because nothing is a number.
A3: CONCEPT · A cell that looks like an amount but sits on the LEFT of the cell is text. SUBSTITUTE(text, old, new) deletes the currency symbol and the commas; VALUE then converts what is left. Dates are worse: DATEVALUE depends on the computer's regional settings and fails on "12-05-2025" in half the world. Build the date yourself with DATE(year, month, day) and MID — that formula gives the same answer on every machine on earth.
A8: Amount (text) | B8: Date (text) | C8: Amount | D8: Date | E8: Month | G8: # | H8: Task | I8: Your answer | J8: Check | K8: Hint
A9: ₹ 75,423.57 | B9: 23-12-2025 | G9: 1 | H9: Fill Amount: a real number, from the text in column A. | I9: → fill column C | J9: =IF(COUNTA($C$9:$C$32)=0,"◯ Not attempted",IF(NOT(_xlfn.ISFORMULA(C9)),"✎ Use a formula",IFERROR(IF(SUMPRODUCT(--(ABS($C$9:$C$32-$M$9:$M$32)<0.02))=ROWS($C$9:$C$32),"✓ Correct","✗ "&(ROWS($C$9:$C$32)-SUMPRODUCT(--(ABS($C$9:$C$32-$M$9:$M$32)<0.02)))&" rows differ"),"✗ Check the column"))) -> ◯ Not attempted | K9: =VALUE(SUBSTITUTE(SUBSTITUTE(A9,",",""),"₹","")) — strip the commas, strip the symbol, then convert. | M9: =VALUE(SUBSTITUTE(SUBSTITUTE(A9,",",""),"₹","")) -> 75423.57 | N9: =DATE(VALUE(MID(B9,7,4)),VALUE(MID(B9,4,2)),VALUE(MID(B9,1,2))) -> 46014 | O9: =TEXT(DATE(VALUE(MID(B9,7,4)),VALUE(MID(B9,4,2)),VALUE(MID(B9,1,2))),"mmm-yy") -> Dec-25
A10: ₹ 5,27,254.52 | B10: 01-09-2025 | G10: 2 | H10: Fill Date: a real date, built from the dd-mm-yyyy text in column B. | I10: → fill column D | J10: =IF(COUNTA($D$9:$D$32)=0,"◯ Not attempted",IF(NOT(_xlfn.ISFORMULA(D9)),"✎ Use a formula",IFERROR(IF(SUMPRODUCT(--(ABS($D$9:$D$32-$N$9:$N$32)<0.5))=ROWS($D$9:$D$32),"✓ Correct","✗ "&(ROWS($D$9:$D$32)-SUMPRODUCT(--(ABS($D$9:$D$32-$N$9:$N$32)<0.5)))&" rows differ"),"✗ Check the column"))) -> ◯ Not attempted | K10: =DATE(VALUE(MID(B9,7,4)),VALUE(MID(B9,4,2)),VALUE(MID(B9,1,2))) | M10: =VALUE(SUBSTITUTE(SUBSTITUTE(A10,",",""),"₹","")) -> 527254.52 | N10: =DATE(VALUE(MID(B10,7,4)),VALUE(MID(B10,4,2)),VALUE(MID(B10,1,2))) -> 45901 | O10: =TEXT(DATE(VALUE(MID(B10,7,4)),VALUE(MID(B10,4,2)),VALUE(MID(B10,1,2))),"mmm-yy") -> Sep-25
A11: ₹ 9,72,242.09 | B11: 20-09-2025 | G11: 3 | H11: Fill Month as a label like "Jul-25". | I11: → fill column E | J11: =IF(COUNTA($E$9:$E$32)=0,"◯ Not attempted",IF(NOT(_xlfn.ISFORMULA(E9)),"✎ Use a formula",IFERROR(IF(SUMPRODUCT(--(UPPER(TRIM($E$9:$E$32&""))=UPPER(TRIM($O$9:$O$32&""))))=ROWS($E$9:$E$32),"✓ Correct","✗ "&(ROWS($E$9:$E$32)-SUMPRODUCT(--(UPPER(TRIM($E$9:$E$32&""))=UPPER(TRIM($O$9:$O$32&"")))))&" rows differ"),"✗ Check the column"))) -> ◯ Not attempted | K11: =TEXT(D9,"mmm-yy") | M11: =VALUE(SUBSTITUTE(SUBSTITUTE(A11,",",""),"₹","")) -> 972242.09 | N11: =DATE(VALUE(MID(B11,7,4)),VALUE(MID(B11,4,2)),VALUE(MID(B11,1,2))) -> 45920 | O11: =TEXT(DATE(VALUE(MID(B11,7,4)),VALUE(MID(B11,4,2)),VALUE(MID(B11,1,2))),"mmm-yy") -> Sep-25
A12: ₹ 3,59,761.10 | B12: 13-04-2025 | G12: 4 | H12: Total of all the amounts. | J12: =IF(ISBLANK(I12),"◯ Not attempted",IF(NOT(_xlfn.ISFORMULA(I12)),"✎ Use a formula",IF(ISNUMBER(I12),IF(ABS(I12-$L$12)<0.05,"✓ Correct","✗ Check again"),"✗ Not a number"))) -> ◯ Not attempted | K12: SUM your converted column. If it returns 0, your column is still text. | L12: =12181037.84 -> 12181038 | M12: =VALUE(SUBSTITUTE(SUBSTITUTE(A12,",",""),"₹","")) -> 359761.1 | N12: =DATE(VALUE(MID(B12,7,4)),VALUE(MID(B12,4,2)),VALUE(MID(B12,1,2))) -> 45760 | O12: =TEXT(DATE(VALUE(MID(B12,7,4)),VALUE(MID(B12,4,2)),VALUE(MID(B12,1,2))),"mmm-yy") -> Apr-25
A13: ₹ 79,767.32 | B13: 05-05-2025 | G13: 5 | H13: How many transactions fall in May 2025? | J13: =IF(ISBLANK(I13),"◯ Not attempted",IF(NOT(_xlfn.ISFORMULA(I13)),"✎ Use a formula",IF(ISNUMBER(I13),IF(ABS(I13-$L$13)<0.005,"✓ Correct","✗ Check again"),"✗ Not a number"))) -> ◯ Not attempted | K13: COUNTIF on your Month label. | L13: =1 -> 1 | M13: =VALUE(SUBSTITUTE(SUBSTITUTE(A13,",",""),"₹","")) -> 79767.32 | N13: =DATE(VALUE(MID(B13,7,4)),VALUE(MID(B13,4,2)),VALUE(MID(B13,1,2))) -> 45782 | O13: =TEXT(DATE(VALUE(MID(B13,7,4)),VALUE(MID(B13,4,2)),VALUE(MID(B13,1,2))),"mmm-yy") -> May-25
A14: ₹ 3,55,481.55 | B14: 05-11-2025 | G14: 6 | H14: Largest single amount. | J14: =IF(ISBLANK(I14),"◯ Not attempted",IF(NOT(_xlfn.ISFORMULA(I14)),"✎ Use a formula",IF(ISNUMBER(I14),IF(ABS(I14-$L$14)<0.05,"✓ Correct","✗ Check again"),"✗ Not a number"))) -> ◯ Not attempted | K14: MAX on the converted column. | L14: =972242.09 -> 972242.09 | M14: =VALUE(SUBSTITUTE(SUBSTITUTE(A14,",",""),"₹","")) -> 355481.55 | N14: =DATE(VALUE(MID(B14,7,4)),VALUE(MID(B14,4,2)),VALUE(MID(B14,1,2))) -> 45966 | O14: =TEXT(DATE(VALUE(MID(B14,7,4)),VALUE(MID(B14,4,2)),VALUE(MID(B14,1,2))),"mmm-yy") -> Nov-25
A15: ₹ 75,132.68 | B15: 03-01-2026 | M15: =VALUE(SUBSTITUTE(SUBSTITUTE(A15,",",""),"₹","")) -> 75132.68 | N15: =DATE(VALUE(MID(B15,7,4)),VALUE(MID(B15,4,2)),VALUE(MID(B15,1,2))) -> 46025 | O15: =TEXT(DATE(VALUE(MID(B15,7,4)),VALUE(MID(B15,4,2)),VALUE(MID(B15,1,2))),"mmm-yy") -> Jan-26
A16: ₹ 51,040.99 | B16: 13-04-2025 | M16: =VALUE(SUBSTITUTE(SUBSTITUTE(A16,",",""),"₹","")) -> 51040.99 | N16: =DATE(VALUE(MID(B16,7,4)),VALUE(MID(B16,4,2)),VALUE(MID(B16,1,2))) -> 45760 | O16: =TEXT(DATE(VALUE(MID(B16,7,4)),VALUE(MID(B16,4,2)),VALUE(MID(B16,1,2))),"mmm-yy") -> Apr-25
A17: ₹ 7,64,826.84 | B17: 11-06-2025 | M17: =VALUE(SUBSTITUTE(SUBSTITUTE(A17,",",""),"₹","")) -> 764826.84 | N17: =DATE(VALUE(MID(B17,7,4)),VALUE(MID(B17,4,2)),VALUE(MID(B17,1,2))) -> 45819 | O17: =TEXT(DATE(VALUE(MID(B17,7,4)),VALUE(MID(B17,4,2)),VALUE(MID(B17,1,2))),"mmm-yy") -> Jun-25
A18: ₹ 9,20,100.91 | B18: 01-10-2025 | M18: =VALUE(SUBSTITUTE(SUBSTITUTE(A18,",",""),"₹","")) -> 920100.91 | N18: =DATE(VALUE(MID(B18,7,4)),VALUE(MID(B18,4,2)),VALUE(MID(B18,1,2))) -> 45931 | O18: =TEXT(DATE(VALUE(MID(B18,7,4)),VALUE(MID(B18,4,2)),VALUE(MID(B18,1,2))),"mmm-yy") -> Oct-25
A19: ₹ 3,21,624.98 | B19: 29-07-2025 | M19: =VALUE(SUBSTITUTE(SUBSTITUTE(A19,",",""),"₹","")) -> 321624.98 | N19: =DATE(VALUE(MID(B19,7,4)),VALUE(MID(B19,4,2)),VALUE(MID(B19,1,2))) -> 45867 | O19: =TEXT(DATE(VALUE(MID(B19,7,4)),VALUE(MID(B19,4,2)),VALUE(MID(B19,1,2))),"mmm-yy") -> Jul-25
A20: ₹ 9,46,751.87 | B20: 14-11-2025 | M20: =VALUE(SUBSTITUTE(SUBSTITUTE(A20,",",""),"₹","")) -> 946751.87 | N20: =DATE(VALUE(MID(B20,7,4)),VALUE(MID(B20,4,2)),VALUE(MID(B20,1,2))) -> 45975 | O20: =TEXT(DATE(VALUE(MID(B20,7,4)),VALUE(MID(B20,4,2)),VALUE(MID(B20,1,2))),"mmm-yy") -> Nov-25
A21: ₹ 4,92,089.84 | B21: 10-06-2025 | M21: =VALUE(SUBSTITUTE(SUBSTITUTE(A21,",",""),"₹","")) -> 492089.84 | N21: =DATE(VALUE(MID(B21,7,4)),VALUE(MID(B21,4,2)),VALUE(MID(B21,1,2))) -> 45818 | O21: =TEXT(DATE(VALUE(MID(B21,7,4)),VALUE(MID(B21,4,2)),VALUE(MID(B21,1,2))),"mmm-yy") -> Jun-25
A22: ₹ 3,14,019.46 | B22: 03-04-2025 | M22: =VALUE(SUBSTITUTE(SUBSTITUTE(A22,",",""),"₹","")) -> 314019.46 | N22: =DATE(VALUE(MID(B22,7,4)),VALUE(MID(B22,4,2)),VALUE(MID(B22,1,2))) -> 45750 | O22: =TEXT(DATE(VALUE(MID(B22,7,4)),VALUE(MID(B22,4,2)),VALUE(MID(B22,1,2))),"mmm-yy") -> Apr-25
A23: ₹ 6,41,211.35 | B23: 25-08-2025 | M23: =VALUE(SUBSTITUTE(SUBSTITUTE(A23,",",""),"₹","")) -> 641211.35 | N23: =DATE(VALUE(MID(B23,7,4)),VALUE(MID(B23,4,2)),VALUE(MID(B23,1,2))) -> 45894 | O23: =TEXT(DATE(VALUE(MID(B23,7,4)),VALUE(MID(B23,4,2)),VALUE(MID(B23,1,2))),"mmm-yy") -> Aug-25
A24: ₹ 9,49,831.74 | B24: 28-01-2026 | M24: =VALUE(SUBSTITUTE(SUBSTITUTE(A24,",",""),"₹","")) -> 949831.74 | N24: =DATE(VALUE(MID(B24,7,4)),VALUE(MID(B24,4,2)),VALUE(MID(B24,1,2))) -> 46050 | O24: =TEXT(DATE(VALUE(MID(B24,7,4)),VALUE(MID(B24,4,2)),VALUE(MID(B24,1,2))),"mmm-yy") -> Jan-26
A25: ₹ 6,18,189.80 | B25: 11-09-2025 | M25: =VALUE(SUBSTITUTE(SUBSTITUTE(A25,",",""),"₹","")) -> 618189.8 | N25: =DATE(VALUE(MID(B25,7,4)),VALUE(MID(B25,4,2)),VALUE(MID(B25,1,2))) -> 45911 | O25: =TEXT(DATE(VALUE(MID(B25,7,4)),VALUE(MID(B25,4,2)),VALUE(MID(B25,1,2))),"mmm-yy") -> Sep-25
A26: ₹ 5,96,795.80 | B26: 26-11-2025 | M26: =VALUE(SUBSTITUTE(SUBSTITUTE(A26,",",""),"₹","")) -> 596795.8 | N26: =DATE(VALUE(MID(B26,7,4)),VALUE(MID(B26,4,2)),VALUE(MID(B26,1,2))) -> 45987 | O26: =TEXT(DATE(VALUE(MID(B26,7,4)),VALUE(MID(B26,4,2)),VALUE(MID(B26,1,2))),"mmm-yy") -> Nov-25
... A32: ₹ 5,86,832.13 | B32: 31-10-2025 | M32: =VALUE(SUBSTITUTE(SUBSTITUTE(A32,",",""),"₹","")) -> 586832.13 | N32: =DATE(VALUE(MID(B32,7,4)),VALUE(MID(B32,4,2)),VALUE(MID(B32,1,2))) -> 45961 | O32: =TEXT(DATE(VALUE(MID(B32,7,4)),VALUE(MID(B32,4,2)),VALUE(MID(B32,1,2))),"mmm-yy") -> Oct-25

Sheet L4 Duplicates
A1: LESSON 4 · DUPLICATES
A2: ★★★☆☆ Twenty-five rows, twenty invoices. Find the five that got pasted twice.
A3: CONCEPT · COUNTIF(whole column, this value) tells you how many times a value appears — more than 1 means a duplicate. To mark only the SECOND and later copies, lock just the top of the range: COUNTIF($A$9:A9, A9) counts from the top down to the current row, so the first occurrence is 1 and every repeat is 2, 3, … . The expanding-range trick is worth memorising.
A8: Invoice | B8: Party | C8: Amount | D8: Times seen | E8: Keep? | G8: # | H8: Task | I8: Your answer | J8: Check | K8: Hint
A9: INV-2112 | B9: Kiran Agencies | C9: 22000 | G9: 1 | H9: Fill Times seen: how many times this invoice number appears in the whole column. | I9: → fill column D | J9: =IF(COUNTA($D$9:$D$33)=0,"◯ Not attempted",IF(NOT(_xlfn.ISFORMULA(D9)),"✎ Use a formula",IFERROR(IF(SUMPRODUCT(--(ABS($D$9:$D$33-$M$9:$M$33)<0.01))=ROWS($D$9:$D$33),"✓ Correct","✗ "&(ROWS($D$9:$D$33)-SUMPRODUCT(--(ABS($D$9:$D$33-$M$9:$M$33)<0.01)))&" rows differ"),"✗ Check the column"))) -> ◯ Not attempted | K9: =COUNTIF($A$9:$A$33,A9) — the range must be locked with $. | M9: =COUNTIF($A$9:$A$33,A9) -> 1 | N9: =IF(COUNTIF($A$9:A9,A9)=1,"Keep","Duplicate") -> Keep
A10: INV-2100 | B10: Orbit Systems | C10: 277500 | G10: 2 | H10: Fill Keep?: "Keep" for the first time an invoice appears, "Duplicate" for every later copy. | I10: → fill column E | J10: =IF(COUNTA($E$9:$E$33)=0,"◯ Not attempted",IF(NOT(_xlfn.ISFORMULA(E9)),"✎ Use a formula",IFERROR(IF(SUMPRODUCT(--(UPPER(TRIM($E$9:$E$33&""))=UPPER(TRIM($N$9:$N$33&""))))=ROWS($E$9:$E$33),"✓ Correct","✗ "&(ROWS($E$9:$E$33)-SUMPRODUCT(--(UPPER(TRIM($E$9:$E$33&""))=UPPER(TRIM($N$9:$N$33&"")))))&" rows differ"),"✗ Check the column"))) -> ◯ Not attempted | K10: =IF(COUNTIF($A$9:A9,A9)=1,"Keep","Duplicate") — note only the FIRST A9 is locked. | M10: =COUNTIF($A$9:$A$33,A10) -> 2 | N10: =IF(COUNTIF($A$9:A10,A10)=1,"Keep","Duplicate") -> Keep
A11: INV-2103 | B11: Patel & Co | C11: 190500 | G11: 3 | H11: How many DIFFERENT invoice numbers are there? | J11: =IF(ISBLANK(I11),"◯ Not attempted",IF(NOT(_xlfn.ISFORMULA(I11)),"✎ Use a formula",IF(ISNUMBER(I11),IF(ABS(I11-$L$11)<0.005,"✓ Correct","✗ Check again"),"✗ Not a number"))) -> ◯ Not attempted | K11: Count the "Keep" rows. | L11: =20 -> 20 | M11: =COUNTIF($A$9:$A$33,A11) -> 2 | N11: =IF(COUNTIF($A$9:A11,A11)=1,"Keep","Duplicate") -> Keep
A12: INV-2115 | B12: Vaibhav Textiles | C12: 109000 | G12: 4 | H12: How many rows are duplicates? | J12: =IF(ISBLANK(I12),"◯ Not attempted",IF(NOT(_xlfn.ISFORMULA(I12)),"✎ Use a formula",IF(ISNUMBER(I12),IF(ABS(I12-$L$12)<0.005,"✓ Correct","✗ Check again"),"✗ Not a number"))) -> ◯ Not attempted | K12: Total rows minus different invoices. | L12: =5 -> 5 | M12: =COUNTIF($A$9:$A$33,A12) -> 2 | N12: =IF(COUNTIF($A$9:A12,A12)=1,"Keep","Duplicate") -> Keep
A13: INV-2104 | B13: Vaibhav Textiles | C13: 45000 | G13: 5 | H13: Total value counting each invoice only ONCE. | J13: =IF(ISBLANK(I13),"◯ Not attempted",IF(NOT(_xlfn.ISFORMULA(I13)),"✎ Use a formula",IF(ISNUMBER(I13),IF(ABS(I13-$L$13)<0.005,"✓ Correct","✗ Check again"),"✗ Not a number"))) -> ◯ Not attempted | K13: SUMIF on the Keep label. | L13: =2991000 -> 2991000 | M13: =COUNTIF($A$9:$A$33,A13) -> 1 | N13: =IF(COUNTIF($A$9:A13,A13)=1,"Keep","Duplicate") -> Keep
A14: INV-2109 | B14: Shree Enterprises | C14: 181500 | M14: =COUNTIF($A$9:$A$33,A14) -> 3 | N14: =IF(COUNTIF($A$9:A14,A14)=1,"Keep","Duplicate") -> Keep
A15: INV-2109 | B15: Shree Enterprises | C15: 181500 | M15: =COUNTIF($A$9:$A$33,A15) -> 3 | N15: =IF(COUNTIF($A$9:A15,A15)=1,"Keep","Duplicate") -> Duplicate
A16: INV-2114 | B16: Vaibhav Textiles | C16: 40500 | M16: =COUNTIF($A$9:$A$33,A16) -> 1 | N16: =IF(COUNTIF($A$9:A16,A16)=1,"Keep","Duplicate") -> Keep
A17: INV-2107 | B17: Patel & Co | C17: 87500 | M17: =COUNTIF($A$9:$A$33,A17) -> 1 | N17: =IF(COUNTIF($A$9:A17,A17)=1,"Keep","Duplicate") -> Keep
A18: INV-2106 | B18: Shree Enterprises | C18: 275000 | M18: =COUNTIF($A$9:$A$33,A18) -> 1 | N18: =IF(COUNTIF($A$9:A18,A18)=1,"Keep","Duplicate") -> Keep
A19: INV-2108 | B19: ABC Traders | C19: 173500 | M19: =COUNTIF($A$9:$A$33,A19) -> 1 | N19: =IF(COUNTIF($A$9:A19,A19)=1,"Keep","Duplicate") -> Keep
A20: INV-2105 | B20: Kiran Agencies | C20: 190500 | M20: =COUNTIF($A$9:$A$33,A20) -> 1 | N20: =IF(COUNTIF($A$9:A20,A20)=1,"Keep","Duplicate") -> Keep
A21: INV-2110 | B21: Shree Enterprises | C21: 19500 | M21: =COUNTIF($A$9:$A$33,A21) -> 1 | N21: =IF(COUNTIF($A$9:A21,A21)=1,"Keep","Duplicate") -> Keep
A22: INV-2111 | B22: Nandini Foods | C22: 13000 | M22: =COUNTIF($A$9:$A$33,A22) -> 1 | N22: =IF(COUNTIF($A$9:A22,A22)=1,"Keep","Duplicate") -> Keep
A23: INV-2118 | B23: Shree Enterprises | C23: 107000 | M23: =COUNTIF($A$9:$A$33,A23) -> 1 | N23: =IF(COUNTIF($A$9:A23,A23)=1,"Keep","Duplicate") -> Keep
A24: INV-2109 | B24: Shree Enterprises | C24: 181500 | M24: =COUNTIF($A$9:$A$33,A24) -> 3 | N24: =IF(COUNTIF($A$9:A24,A24)=1,"Keep","Duplicate") -> Duplicate
A25: INV-2101 | B25: Vaibhav Textiles | C25: 101500 | M25: =COUNTIF($A$9:$A$33,A25) -> 1 | N25: =IF(COUNTIF($A$9:A25,A25)=1,"Keep","Duplicate") -> Keep
... A33: INV-2102 | B33: Patel & Co | C33: 277500 | M33: =COUNTIF($A$9:$A$33,A33) -> 1 | N33: =IF(COUNTIF($A$9:A33,A33)=1,"Keep","Duplicate") -> Keep

Sheet L5 Joining text and building ke
A1: LESSON 5 · JOINING TEXT AND BUILDING KEYS
A2: ★★★★☆ Make a key that matches across two systems that agree on nothing.
A3: CONCEPT · The & operator glues text together: A9&" "&B9. CONCAT does the same for a whole range; TEXTJOIN adds a separator and can skip blanks — TEXTJOIN(", ", TRUE, range). The real skill is designing a MATCH KEY: clean it, force one case, and join the parts with a character that cannot appear in the data, like a pipe. Two systems will then agree even when their spelling does not.
A8: First | B8: Last | C8: City | D8: Full Name | E8: Match Key | G8: # | H8: Task | I8: Your answer | J8: Check | K8: Hint
A9: Rahul | B9: KULKARNI | C9: Mumbai | G9: 1 | H9: Fill Full Name: first and last name, cleaned and properly capitalised, with one space between them. | I9: → fill column D | J9: =IF(COUNTA($D$9:$D$32)=0,"◯ Not attempted",IF(NOT(_xlfn.ISFORMULA(D9)),"✎ Use a formula",IFERROR(IF(SUMPRODUCT(--(UPPER(TRIM($D$9:$D$32&""))=UPPER(TRIM($M$9:$M$32&""))))=ROWS($D$9:$D$32),"✓ Correct","✗ "&(ROWS($D$9:$D$32)-SUMPRODUCT(--(UPPER(TRIM($D$9:$D$32&""))=UPPER(TRIM($M$9:$M$32&"")))))&" rows differ"),"✗ Check the column"))) -> ◯ Not attempted | K9: =PROPER(TRIM(A9))&" "&PROPER(TRIM(B9)) | M9: =PROPER(TRIM(A9))&" "&PROPER(TRIM(B9)) -> Rahul Kulkarni | N9: =UPPER(LEFT(TRIM(A9),1)&TRIM(B9)&"|"&TRIM(C9)) -> RKULKARNI|MUMBAI
A10: PRIYA | B10: Gupta | C10: Ahmedabad | G10: 2 | H10: Fill Match Key: first initial + last name + "|" + city, all in CAPITALS, no spaces around anything. | I10: → fill column E | J10: =IF(COUNTA($E$9:$E$32)=0,"◯ Not attempted",IF(NOT(_xlfn.ISFORMULA(E9)),"✎ Use a formula",IFERROR(IF(SUMPRODUCT(--(UPPER(TRIM($E$9:$E$32&""))=UPPER(TRIM($N$9:$N$32&""))))=ROWS($E$9:$E$32),"✓ Correct","✗ "&(ROWS($E$9:$E$32)-SUMPRODUCT(--(UPPER(TRIM($E$9:$E$32&""))=UPPER(TRIM($N$9:$N$32&"")))))&" rows differ"),"✗ Check the column"))) -> ◯ Not attempted | K10: =UPPER(LEFT(TRIM(A9),1)&TRIM(B9)&"|"&TRIM(C9)) | M10: =PROPER(TRIM(A10))&" "&PROPER(TRIM(B10)) -> Priya Gupta | N10: =UPPER(LEFT(TRIM(A10),1)&TRIM(B10)&"|"&TRIM(C10)) -> PGUPTA|AHMEDABAD
A11: AMIT | B11: Naik | C11: Delhi | G11: 3 | H11: How many match keys are unique (appear only once)? | J11: =IF(ISBLANK(I11),"◯ Not attempted",IF(NOT(_xlfn.ISFORMULA(I11)),"✎ Use a formula",IF(ISNUMBER(I11),IF(ABS(I11-$L$11)<0.005,"✓ Correct","✗ Check again"),"✗ Not a number"))) -> ◯ Not attempted | K11: COUNTIF a column against itself, then count the 1s. | L11: =16 -> 16 | M11: =PROPER(TRIM(A11))&" "&PROPER(TRIM(B11)) -> Amit Naik | N11: =UPPER(LEFT(TRIM(A11),1)&TRIM(B11)&"|"&TRIM(C11)) -> ANAIK|DELHI
A12: Sneha | B12: rao | C12: Pune | G12: 4 | H12: Join the first three full names into one cell, separated by a comma and a space. | J12: =IF(ISBLANK(I12),"◯ Not attempted",IF(NOT(_xlfn.ISFORMULA(I12)),"✎ Use a formula",IF(UPPER(TRIM(I12&""))=UPPER(TRIM($L$12&"")),"✓ Correct","✗ Check again"))) -> ◯ Not attempted | K12: =TEXTJOIN(", ",TRUE,D9:D11) | L12: ="Rahul Kulkarni, Priya Gupta, Amit Naik" -> Rahul Kulkarni, Priya Gupta, Amit Naik | M12: =PROPER(TRIM(A12))&" "&PROPER(TRIM(B12)) -> Sneha Rao | N12: =UPPER(LEFT(TRIM(A12),1)&TRIM(B12)&"|"&TRIM(C12)) -> SRAO|PUNE
A13: VIKRAM | B13: REDDY | C13: Surat | G13: 5 | H13: How many people are in Pune? | J13: =IF(ISBLANK(I13),"◯ Not attempted",IF(NOT(_xlfn.ISFORMULA(I13)),"✎ Use a formula",IF(ISNUMBER(I13),IF(ABS(I13-$L$13)<0.005,"✓ Correct","✗ Check again"),"✗ Not a number"))) -> ◯ Not attempted | K13: COUNTIF on the City column. | L13: =3 -> 3 | M13: =PROPER(TRIM(A13))&" "&PROPER(TRIM(B13)) -> Vikram Reddy | N13: =UPPER(LEFT(TRIM(A13),1)&TRIM(B13)&"|"&TRIM(C13)) -> VREDDY|SURAT
A14: NEHA | B14: VERMA | C14: Chennai | M14: =PROPER(TRIM(A14))&" "&PROPER(TRIM(B14)) -> Neha Verma | N14: =UPPER(LEFT(TRIM(A14),1)&TRIM(B14)&"|"&TRIM(C14)) -> NVERMA|CHENNAI
A15: Arjun | B15: Joshi | C15: Kochi | M15: =PROPER(TRIM(A15))&" "&PROPER(TRIM(B15)) -> Arjun Joshi | N15: =UPPER(LEFT(TRIM(A15),1)&TRIM(B15)&"|"&TRIM(C15)) -> AJOSHI|KOCHI
A16: kavya | B16: Chopra | C16: Nagpur | M16: =PROPER(TRIM(A16))&" "&PROPER(TRIM(B16)) -> Kavya Chopra | N16: =UPPER(LEFT(TRIM(A16),1)&TRIM(B16)&"|"&TRIM(C16)) -> KCHOPRA|NAGPUR
A17: ROHIT | B17: Ghosh | C17: Bengaluru | M17: =PROPER(TRIM(A17))&" "&PROPER(TRIM(B17)) -> Rohit Ghosh | N17: =UPPER(LEFT(TRIM(A17),1)&TRIM(B17)&"|"&TRIM(C17)) -> RGHOSH|BENGALURU
A18: ananya | B18: nair | C18: Indore | M18: =PROPER(TRIM(A18))&" "&PROPER(TRIM(B18)) -> Ananya Nair | N18: =UPPER(LEFT(TRIM(A18),1)&TRIM(B18)&"|"&TRIM(C18)) -> ANAIR|INDORE
A19: siddharth | B19: PILLAI | C19: Mumbai | M19: =PROPER(TRIM(A19))&" "&PROPER(TRIM(B19)) -> Siddharth Pillai | N19: =UPPER(LEFT(TRIM(A19),1)&TRIM(B19)&"|"&TRIM(C19)) -> SPILLAI|MUMBAI
A20: ishita | B20: Sharma | C20: Ahmedabad | M20: =PROPER(TRIM(A20))&" "&PROPER(TRIM(B20)) -> Ishita Sharma | N20: =UPPER(LEFT(TRIM(A20),1)&TRIM(B20)&"|"&TRIM(C20)) -> ISHARMA|AHMEDABAD
A21: Manish | B21: Desai | C21: Delhi | M21: =PROPER(TRIM(A21))&" "&PROPER(TRIM(B21)) -> Manish Desai | N21: =UPPER(LEFT(TRIM(A21),1)&TRIM(B21)&"|"&TRIM(C21)) -> MDESAI|DELHI
A22: Pooja | B22: Shetty | C22: Pune | M22: =PROPER(TRIM(A22))&" "&PROPER(TRIM(B22)) -> Pooja Shetty | N22: =UPPER(LEFT(TRIM(A22),1)&TRIM(B22)&"|"&TRIM(C22)) -> PSHETTY|PUNE
A23: Karan | B23: IYER | C23: Surat | M23: =PROPER(TRIM(A23))&" "&PROPER(TRIM(B23)) -> Karan Iyer | N23: =UPPER(LEFT(TRIM(A23),1)&TRIM(B23)&"|"&TRIM(C23)) -> KIYER|SURAT
A24: DIVYA | B24: MEHTA | C24: Chennai | M24: =PROPER(TRIM(A24))&" "&PROPER(TRIM(B24)) -> Divya Mehta | N24: =UPPER(LEFT(TRIM(A24),1)&TRIM(B24)&"|"&TRIM(C24)) -> DMEHTA|CHENNAI
A25: nikhil | B25: Malhotra | C25: Kochi | M25: =PROPER(TRIM(A25))&" "&PROPER(TRIM(B25)) -> Nikhil Malhotra | N25: =UPPER(LEFT(TRIM(A25),1)&TRIM(B25)&"|"&TRIM(C25)) -> NMALHOTRA|KOCHI
... A32: Sneha | B32: Rao | C32: Pune | M32: =PROPER(TRIM(A32))&" "&PROPER(TRIM(B32)) -> Sneha Rao | N32: =UPPER(LEFT(TRIM(A32),1)&TRIM(B32)&"|"&TRIM(C32)) -> SRAO|PUNE

Sheet L6 Boss round — validate the im
A1: LESSON 6 · BOSS ROUND — VALIDATE THE IMPORT
A2: ★★★★★ One formula that audits every row before it reaches the accounting system.
A3: CONCEPT · Validation is a ladder of tests, most serious first. ISERROR(FIND("@", email)) is TRUE when there is no @ at all — that is how you test for "contains" without a #VALUE! crashing the row. LEN(TRIM(x)) = 0 catches cells that look empty but hold spaces. IFS stops at the first TRUE, so a row with two problems reports the most important one and stops.
A8: Name | B8: Email | C8: Phone | D8: GSTIN | E8: Status | G8: # | H8: Task | I8: Your answer | J8: Check | K8: Hint
A9: Rahul Kulkarni | B9: rahul.kulkarni@gmail.com | C9: 9542595605 | D9: 27AABCA1000A1ZV | G9: 1 | H9: Fill Status: "Name missing" if the name is blank or only spaces; else "Bad email" if there is no @; else "Bad phone" if the phone is not 10 characters; else "Bad GSTIN" if the GSTIN is not 15 characters; else "OK". | I9: → fill column E | J9: =IF(COUNTA($E$9:$E$34)=0,"◯ Not attempted",IF(NOT(_xlfn.ISFORMULA(E9)),"✎ Use a formula",IFERROR(IF(SUMPRODUCT(--(UPPER(TRIM($E$9:$E$34&""))=UPPER(TRIM($M$9:$M$34&""))))=ROWS($E$9:$E$34),"✓ Correct","✗ "&(ROWS($E$9:$E$34)-SUMPRODUCT(--(UPPER(TRIM($E$9:$E$34&""))=UPPER(TRIM($M$9:$M$34&"")))))&" rows differ"),"✗ Check the column"))) -> ◯ Not attempted | K9: IFS(test,result,test,result,…,TRUE,"OK"). Use ISERROR(FIND("@",B9)) for the missing @. | M9: =_xlfn.IFS(LEN(TRIM(A9))=0,"Name missing",ISERROR(FIND("@",B9)),"Bad email",LEN(TRIM(C9))<>10,"Bad phone",LEN(TRIM(D9))<>15,"Bad GSTIN",TRUE(),"OK") -> OK
A10: Priya Gupta | B10: priya.gupta@outlook.com | C10: 9481238749 | D10: 27AABCB1037D1ZV | G10: 2 | H10: How many rows are clean? | J10: =IF(ISBLANK(I10),"◯ Not attempted",IF(NOT(_xlfn.ISFORMULA(I10)),"✎ Use a formula",IF(ISNUMBER(I10),IF(ABS(I10-$L$10)<0.005,"✓ Correct","✗ Check again"),"✗ Not a number"))) -> ◯ Not attempted | K10: COUNTIF for OK. | L10: =15 -> 15 | M10: =_xlfn.IFS(LEN(TRIM(A10))=0,"Name missing",ISERROR(FIND("@",B10)),"Bad email",LEN(TRIM(C10))<>10,"Bad phone",LEN(TRIM(D10))<>15,"Bad GSTIN",TRUE(),"OK") -> OK
A11: Amit Naik | B11: amit.naik.gmail.com | C11: 9704677648 | D11: 27AABCC1074G1ZV | G11: 3 | H11: How many rows have a bad phone number? | J11: =IF(ISBLANK(I11),"◯ Not attempted",IF(NOT(_xlfn.ISFORMULA(I11)),"✎ Use a formula",IF(ISNUMBER(I11),IF(ABS(I11-$L$11)<0.005,"✓ Correct","✗ Check again"),"✗ Not a number"))) -> ◯ Not attempted | K11: COUNTIF for that exact label. | L11: =3 -> 3 | M11: =_xlfn.IFS(LEN(TRIM(A11))=0,"Name missing",ISERROR(FIND("@",B11)),"Bad email",LEN(TRIM(C11))<>10,"Bad phone",LEN(TRIM(D11))<>15,"Bad GSTIN",TRUE(),"OK") -> Bad email
A12: Sneha Rao | B12: sneha.rao@company.co.in | C12: 9533333875 | D12: 27AABCD1111J1ZV | G12: 4 | H12: How many rows need a fix of any kind? | J12: =IF(ISBLANK(I12),"◯ Not attempted",IF(NOT(_xlfn.ISFORMULA(I12)),"✎ Use a formula",IF(ISNUMBER(I12),IF(ABS(I12-$L$12)<0.005,"✓ Correct","✗ Check again"),"✗ Not a number"))) -> ◯ Not attempted | K12: "<>OK" means "not equal to OK". | L12: =11 -> 11 | M12: =_xlfn.IFS(LEN(TRIM(A12))=0,"Name missing",ISERROR(FIND("@",B12)),"Bad email",LEN(TRIM(C12))<>10,"Bad phone",LEN(TRIM(D12))<>15,"Bad GSTIN",TRUE(),"OK") -> OK
A13: Vikram Reddy | B13: vikram.reddy@gmail.com | C13: 93477743 | D13: 27AABCE1148M1ZV | G13: 5 | H13: The email address on the FIRST row flagged "Bad email". | J13: =IF(ISBLANK(I13),"◯ Not attempted",IF(NOT(_xlfn.ISFORMULA(I13)),"✎ Use a formula",IF(UPPER(TRIM(I13&""))=UPPER(TRIM($L$13&"")),"✓ Correct","✗ Check again"))) -> ◯ Not attempted | K13: MATCH finds the position of the first "Bad email"; INDEX pulls the email from that position. | L13: ="amit.naik.gmail.com" -> amit.naik.gmail.com | M13: =_xlfn.IFS(LEN(TRIM(A13))=0,"Name missing",ISERROR(FIND("@",B13)),"Bad email",LEN(TRIM(C13))<>10,"Bad phone",LEN(TRIM(D13))<>15,"Bad GSTIN",TRUE(),"OK") -> Bad phone
A14: Neha Verma | B14: neha.verma@yahoo.in | C14: 9172552997 | D14: 27AABCF1185P1ZV | G14: 6 | H14: What share of the file is clean? | J14: =IF(ISBLANK(I14),"◯ Not attempted",IF(NOT(_xlfn.ISFORMULA(I14)),"✎ Use a formula",IF(ISNUMBER(I14),IF(ABS(I14-$L$14)<0.0005,"✓ Correct","✗ Check again"),"✗ Not a number"))) -> ◯ Not attempted | K14: Clean rows ÷ total rows. Format as a percentage. | L14: =0.576923 -> 0.576923 | M14: =_xlfn.IFS(LEN(TRIM(A14))=0,"Name missing",ISERROR(FIND("@",B14)),"Bad email",LEN(TRIM(C14))<>10,"Bad phone",LEN(TRIM(D14))<>15,"Bad GSTIN",TRUE(),"OK") -> OK
B15: arjun.joshi@gmail.com | C15: 9665850459 | D15: 27AABCG1222S1ZV | M15: =_xlfn.IFS(LEN(TRIM(A15))=0,"Name missing",ISERROR(FIND("@",B15)),"Bad email",LEN(TRIM(C15))<>10,"Bad phone",LEN(TRIM(D15))<>15,"Bad GSTIN",TRUE(),"OK") -> Name missing
A16: Kavya Chopra | B16: kavya.chopra@outlook.com | C16: 9448751693 | D16: 27AABCH1259V1ZV | M16: =_xlfn.IFS(LEN(TRIM(A16))=0,"Name missing",ISERROR(FIND("@",B16)),"Bad email",LEN(TRIM(C16))<>10,"Bad phone",LEN(TRIM(D16))<>15,"Bad GSTIN",TRUE(),"OK") -> OK
A17: Rohit Ghosh | B17: rohit.ghosh@gmail.com | C17: 9470794056 | D17: 27AABCI1296Y1 | M17: =_xlfn.IFS(LEN(TRIM(A17))=0,"Name missing",ISERROR(FIND("@",B17)),"Bad email",LEN(TRIM(C17))<>10,"Bad phone",LEN(TRIM(D17))<>15,"Bad GSTIN",TRUE(),"OK") -> Bad GSTIN
A18: Ananya Nair | B18: ananya.nair@company.co.in | C18: 9607138806 | D18: 27AABCJ1333B1ZV | M18: =_xlfn.IFS(LEN(TRIM(A18))=0,"Name missing",ISERROR(FIND("@",B18)),"Bad email",LEN(TRIM(C18))<>10,"Bad phone",LEN(TRIM(D18))<>15,"Bad GSTIN",TRUE(),"OK") -> OK
A19: Siddharth Pillai | B19: siddharth.pillai@gmail.com | C19: 9867895199 | D19: 27AABCK1370E1ZV | M19: =_xlfn.IFS(LEN(TRIM(A19))=0,"Name missing",ISERROR(FIND("@",B19)),"Bad email",LEN(TRIM(C19))<>10,"Bad phone",LEN(TRIM(D19))<>15,"Bad GSTIN",TRUE(),"OK") -> OK
A20: Ishita Sharma | B20: ishita.sharma.yahoo.in | C20: 9606402635 | D20: 27AABCL1407H1ZV | M20: =_xlfn.IFS(LEN(TRIM(A20))=0,"Name missing",ISERROR(FIND("@",B20)),"Bad email",LEN(TRIM(C20))<>10,"Bad phone",LEN(TRIM(D20))<>15,"Bad GSTIN",TRUE(),"OK") -> Bad email
A21: Manish Desai | B21: manish.desai@gmail.com | C21: 9145470175 | D21: 27AABCM1444K1ZV | M21: =_xlfn.IFS(LEN(TRIM(A21))=0,"Name missing",ISERROR(FIND("@",B21)),"Bad email",LEN(TRIM(C21))<>10,"Bad phone",LEN(TRIM(D21))<>15,"Bad GSTIN",TRUE(),"OK") -> OK
A22: Pooja Shetty | B22: pooja.shetty@outlook.com | C22: 94418318 | D22: 27AABCN1481N1ZV | M22: =_xlfn.IFS(LEN(TRIM(A22))=0,"Name missing",ISERROR(FIND("@",B22)),"Bad email",LEN(TRIM(C22))<>10,"Bad phone",LEN(TRIM(D22))<>15,"Bad GSTIN",TRUE(),"OK") -> Bad phone
A23: Karan Iyer | B23: karan.iyer@gmail.com | C23: 9229864595 | D23: 27AABCO1518Q1ZV | M23: =_xlfn.IFS(LEN(TRIM(A23))=0,"Name missing",ISERROR(FIND("@",B23)),"Bad email",LEN(TRIM(C23))<>10,"Bad phone",LEN(TRIM(D23))<>15,"Bad GSTIN",TRUE(),"OK") -> OK
B24: divya.mehta@company.co.in | C24: 9616520761 | D24: 27AABCP1555T1ZV | M24: =_xlfn.IFS(LEN(TRIM(A24))=0,"Name missing",ISERROR(FIND("@",B24)),"Bad email",LEN(TRIM(C24))<>10,"Bad phone",LEN(TRIM(D24))<>15,"Bad GSTIN",TRUE(),"OK") -> Name missing
A25: Nikhil Malhotra | B25: nikhil.malhotra@gmail.com | C25: 9553786685 | D25: 27AABCQ1592W1ZV | M25: =_xlfn.IFS(LEN(TRIM(A25))=0,"Name missing",ISERROR(FIND("@",B25)),"Bad email",LEN(TRIM(C25))<>10,"Bad phone",LEN(TRIM(D25))<>15,"Bad GSTIN",TRUE(),"OK") -> OK
A26: Meghna Patel | B26: meghna.patel@yahoo.in | C26: 9644709928 | D26: 27AABCR1629Z1 | M26: =_xlfn.IFS(LEN(TRIM(A26))=0,"Name missing",ISERROR(FIND("@",B26)),"Bad email",LEN(TRIM(C26))<>10,"Bad phone",LEN(TRIM(D26))<>15,"Bad GSTIN",TRUE(),"OK") -> Bad GSTIN
A27: Aditya Banerjee | B27: aditya.banerjee@gmail.com | C27: 9764930981 | D27: 27AABCS1666C1ZV | M27: =_xlfn.IFS(LEN(TRIM(A27))=0,"Name missing",ISERROR(FIND("@",B27)),"Bad email",LEN(TRIM(C27))<>10,"Bad phone",LEN(TRIM(D27))<>15,"Bad GSTIN",TRUE(),"OK") -> OK
A28: Shreya Bose | B28: shreya.bose@outlook.com | C28: 9697054488 | D28: 27AABCT1703F1ZV | M28: =_xlfn.IFS(LEN(TRIM(A28))=0,"Name missing",ISERROR(FIND("@",B28)),"Bad email",LEN(TRIM(C28))<>10,"Bad phone",LEN(TRIM(D28))<>15,"Bad GSTIN",TRUE(),"OK") -> OK
A29: Rahul Kulkarni | B29: rahul.kulkarni.gmail.com | C29: 9693749282 | D29: 27AABCU1740I1ZV | M29: =_xlfn.IFS(LEN(TRIM(A29))=0,"Name missing",ISERROR(FIND("@",B29)),"Bad email",LEN(TRIM(C29))<>10,"Bad phone",LEN(TRIM(D29))<>15,"Bad GSTIN",TRUE(),"OK") -> Bad email
A30: Priya Gupta | B30: priya.gupta@company.co.in | C30: 9690295037 | D30: 27AABCV1777L1ZV | M30: =_xlfn.IFS(LEN(TRIM(A30))=0,"Name missing",ISERROR(FIND("@",B30)),"Bad email",LEN(TRIM(C30))<>10,"Bad phone",LEN(TRIM(D30))<>15,"Bad GSTIN",TRUE(),"OK") -> OK
A31: Amit Naik | B31: amit.naik@gmail.com | C31: 97740271 | D31: 27AABCW1814O1ZV | M31: =_xlfn.IFS(LEN(TRIM(A31))=0,"Name missing",ISERROR(FIND("@",B31)),"Bad email",LEN(TRIM(C31))<>10,"Bad phone",LEN(TRIM(D31))<>15,"Bad GSTIN",TRUE(),"OK") -> Bad phone
A32: Sneha Rao | B32: sneha.rao@yahoo.in | C32: 9883504178 | D32: 27AABCX1851R1ZV | M32: =_xlfn.IFS(LEN(TRIM(A32))=0,"Name missing",ISERROR(FIND("@",B32)),"Bad email",LEN(TRIM(C32))<>10,"Bad phone",LEN(TRIM(D32))<>15,"Bad GSTIN",TRUE(),"OK") -> OK
B33: vikram.reddy@gmail.com | C33: 9139914355 | D33: 27AABCY1888U1ZV | M33: =_xlfn.IFS(LEN(TRIM(A33))=0,"Name missing",ISERROR(FIND("@",B33)),"Bad email",LEN(TRIM(C33))<>10,"Bad phone",LEN(TRIM(D33))<>15,"Bad GSTIN",TRUE(),"OK") -> Name missing
A34: Neha Verma | B34: neha.verma@outlook.com | C34: 9296441697 | D34: 27AABCZ1925X1ZV | M34: =_xlfn.IFS(LEN(TRIM(A34))=0,"Name missing",ISERROR(FIND("@",B34)),"Bad email",LEN(TRIM(C34))<>10,"Bad phone",LEN(TRIM(D34))<>15,"Bad GSTIN",TRUE(),"OK") -> OK

Sheet Solutions
A1: SOLUTIONS & OTHER WAYS — open only after you have tried
A2: Model answers are shapes, not the only answer. If your formula gives the same result, it is right — compare the logic.
A4: L1 Spaces and capitals ★
A5: # | B5: Task | C5: Answer cell | D5: Model formula | E5: Other ways | F5: Why it works
A6: 1 | B6: Fill Clean Name: no stray spaces, each word capitalised. | C6: column B | D6: =PROPER(TRIM(A9)) (row 9, then fill down) | E6: =TRIM(PROPER(A9)) — same result here, but TRIM first is the habit to keep =PROPER(TRIM(CLEAN(A9))) — CLEAN also strips invisible control characters from system exports | F6: Two names that look identical but differ by one space will never match in a VLOOKUP.
A7: 2 | B7: Fill Chars removed: how many characters TRIM took out of each raw name. | C7: column C | D7: =LEN(A9)-LEN(TRIM(A9)) (row 9, then fill down)
A8: 3 | B8: How many names needed cleaning at all? | C8: G11 | D8: =COUNTIF($C$9:$C$36,">0") | E8: =SUMPRODUCT(--(LEN(raw)<>LEN(TRIM(raw))))
A9: 4 | B9: Total characters removed across the whole list. | C9: G12 | D9: =SUM($C$9:$C$36) | E9: =SUMPRODUCT(LEN(raw)-LEN(TRIM(raw))) — no helper column needed
A10: 5 | B10: How many cleaned names are longer than 12 characters? | C10: G13 | D10: =SUMPRODUCT(--(LEN($B$9:$B$36)>12)) | F10: COUNTIF cannot test a calculated property like length — SUMPRODUCT can.
A12: L2 Cutting text apart ★★
A13: # | B13: Task | C13: Answer cell | D13: Model formula | E13: Other ways | F13: Why it works
A14: 1 | B14: Fill State: the two letters before the first dash. | C14: column C | D14: =LEFT(A9,2) (row 9, then fill down) | E14: =LEFT(A9,FIND("-",A9)-1) — works even if the prefix length changes =MID(A9,1,2) | F14: Hard-coding 2 breaks the day someone adds a three-letter code. FIND never does.
A15: 2 | B15: Fill Serial: the number between the two dashes, as a real number. | C15: column D | D15: =VALUE(MID(A9,FIND("-",A9)+1,5)) (row 9, then fill down) | E15: =VALUE(MID(A9,4,5)) — fine while every prefix is 2 letters =VALUE(MID(A9,FIND("-",A9)+1,FIND("-",A9,FIND("-",A9)+1)-FIND("-",A9)-1)) — finds both dashes, any length | F15: Without VALUE it stays text, and text never sums.
A16: 3 | B16: Fill Domain: everything after the @, in lower case. | C16: column E | D16: =LOWER(MID(B9,FIND("@",B9)+1,99)) (row 9, then fill down) | E16: =RIGHT(B9,LEN(B9)-FIND("@",B9)) =TEXTAFTER(B9,"@") in Microsoft 365
A17: 4 | B17: How many contacts use gmail.com? | C17: I12 | D17: =COUNTIF($E$9:$E$34,"gmail.com") | E17: =COUNTIF(emails,"*@gmail.com") — * is a wildcard for any characters
A18: 5 | B18: The highest serial number in the list. | C18: I13 | D18: =MAX($D$9:$D$34)
A19: 6 | B19: How many codes are from Maharashtra (MH)? | C19: I14 | D19: =COUNTIF($C$9:$C$34,"MH")
A21: L3 Numbers and dates trapped in ★★★
A22: # | B22: Task | C22: Answer cell | D22: Model formula | E22: Other ways | F22: Why it works
A23: 1 | B23: Fill Amount: a real number, from the text in column A. | C23: column C | D23: =VALUE(SUBSTITUTE(SUBSTITUTE(A9,",",""),"₹","")) (row 9, then fill down) | E23: =NUMBERVALUE(SUBSTITUTE(A9,"₹","")) in newer Excel =SUMPRODUCT(VALUE(SUBSTITUTE(SUBSTITUTE(A9,",",""),"₹",""))) | F23: Text that looks like a number is the single most common reason a total comes out as zero.
A24: 2 | B24: Fill Date: a real date, built from the dd-mm-yyyy text in column B. | C24: column D | D24: =DATE(VALUE(MID(B9,7,4)),VALUE(MID(B9,4,2)),VALUE(MID(B9,1,2))) (row 9, then fill down) | E24: =DATEVALUE(B9) — shorter, but it breaks on a computer set to US date format =--TEXT(B9,"@") does NOT work; there is no shortcut worth trusting here | F24: MID + DATE is regional-settings-proof. That matters the moment someone else opens your file.
A25: 3 | B25: Fill Month as a label like "Jul-25". | C25: column E | D25: =TEXT(D9,"mmm-yy") (row 9, then fill down) | E25: =TEXT(D9,"mmm")&"-"&TEXT(YEAR(D9),"00") | F25: TEXT turns a date into a label you can group on. Do not use it for anything you still need to sort chronologically.
A26: 4 | B26: Total of all the amounts. | C26: I12 | D26: =SUM($C$9:$C$32)
A27: 5 | B27: How many transactions fall in May 2025? | C27: I13 | D27: =COUNTIF($E$9:$E$32,"May-25") | E27: =SUMPRODUCT((YEAR(dates)=2025)*(MONTH(dates)=5)) =COUNTIFS(dates,">="&DATE(2025,5,1),dates,"<="&DATE(2025,5,31))
A28: 6 | B28: Largest single amount. | C28: I14 | D28: =MAX($C$9:$C$32)
A30: L4 Duplicates ★★★
A31: # | B31: Task | C31: Answer cell | D31: Model formula | E31: Other ways | F31: Why it works
A32: 1 | B32: Fill Times seen: how many times this invoice number appears in the whole column. | C32: column D | D32: =COUNTIF($A$9:$A$33,A9) (row 9, then fill down)
A33: 2 | B33: Fill Keep?: "Keep" for the first time an invoice appears, "Duplicate" for every later copy. | C33: column E | D33: =IF(COUNTIF($A$9:A9,A9)=1,"Keep","Duplicate") (row 9, then fill down) | E33: =IF(COUNTIFS($A$9:A9,A9)=1,"Keep","Duplicate") Data ▸ Remove Duplicates deletes them, but then you cannot see what was removed | F33: An expanding range grows as you fill down: row 10 sees $A$9:A10, row 11 sees $A$9:A11.
A34: 3 | B34: How many DIFFERENT invoice numbers are there? | C34: I11 | D34: =COUNTIF($E$9:$E$33,"Keep") | E34: =SUMPRODUCT(1/COUNTIF(A9:A33,A9:A33)) — the classic one-cell unique count =ROWS(UNIQUE(A9:A33)) in Microsoft 365 | F34: SUMPRODUCT(1/COUNTIF(range,range)) works because a value seen 3 times contributes 1/3 three times.
A35: 4 | B35: How many rows are duplicates? | C35: I12 | D35: =COUNTIF($E$9:$E$33,"Duplicate") | E35: =COUNTA(A9:A33)-SUMPRODUCT(1/COUNTIF(A9:A33,A9:A33))
A36: 5 | B36: Total value counting each invoice only ONCE. | C36: I13 | D36: =SUMIF($E$9:$E$33,"Keep",$C$9:$C$33) | E36: =SUMPRODUCT(C9:C33/COUNTIF(A9:A33,A9:A33)) — no helper column: each copy contributes its share | F36: Double-counted revenue is how a month's numbers get restated.
A38: L5 Joining text and building ke ★★★★
A39: # | B39: Task | C39: Answer cell | D39: Model formula | E39: Other ways | F39: Why it works
A40: 1 | B40: Fill Full Name: first and last name, cleaned and properly capitalised, with one space between them. | C40: column D | D40: =PROPER(TRIM(A9))&" "&PROPER(TRIM(B9)) (row 9, then fill down) | E40: =TEXTJOIN(" ",TRUE,PROPER(TRIM(A9)),PROPER(TRIM(B9))) =CONCAT(PROPER(TRIM(A9))," ",PROPER(TRIM(B9)))
A41: 2 | B41: Fill Match Key: first initial + last name + "|" + city, all in CAPITALS, no spaces around anything. | C41: column E | D41: =UPPER(LEFT(TRIM(A9),1)&TRIM(B9)&"|"&TRIM(C9)) (row 9, then fill down) | E41: =UPPER(TEXTJOIN("|",TRUE,LEFT(TRIM(A9),1)&TRIM(B9),TRIM(C9))) | F41: A pipe is safe because no real name or city contains one. A space or a dash is not safe.
A42: 3 | B42: How many match keys are unique (appear only once)? | C42: I11 | D42: =SUMPRODUCT(--(COUNTIF($E$9:$E$32,$E$9:$E$32)=1)) | F42: If your key is not unique, every lookup built on it is a coin toss.
A43: 4 | B43: Join the first three full names into one cell, separated by a comma and a space. | C43: I12 | D43: =TEXTJOIN(", ",TRUE,D9:D11) | E43: =D9&", "&D10&", "&D11 =CONCAT(D9,", ",D10,", ",D11) | F43: TEXTJOIN with TRUE skips blanks, so a gap in the range does not leave a dangling comma.
A44: 5 | B44: How many people are in Pune? | C44: I13 | D44: =COUNTIF($C$9:$C$32,"Pune")
A46: L6 Boss round — validate the im ★★★★★
...
