Workbook

Sheet Start Here
A1: EXCEL LAB · 05 BANK RECONCILIATION
A2: A real month of cash book and bank statement side by side: match by reference, find timing differences, catch wrong amounts, and build a reconciliation statement that proves itself to zero.
A4: HOW TO USE THIS WORKBOOK
A5: 1 | B5: Work through the lessons in order — each one is harder than the last (★ to ★★★★★).
A6: 2 | B6: Read the Concept box at the top of each lesson, then look at the data.
A7: 3 | B7: Type a FORMULA in each yellow cell. The Check column marks it ✓ or ✗ instantly.
A8: 4 | B8: Blue cells are inputs. Change them and watch every answer update — that is how you know your formula is really right.
A9: 5 | B9: Stuck? Read the Hint. Still stuck? The Solutions sheet shows the model answer and other ways to do it.
A11: COLOUR CODE
B12: Yellow — your answer goes here (always a formula)
B13: Blue — an input you can change
B14: ✓ Correct — marked automatically
B15: ✗ Check again — the result does not match
B16: ✎ You typed a value — replace it with a formula
A18: # | B18: Lesson | C18: Difficulty | D18: Tasks | E18: Solved | F18: Progress
A19: 1 | B19: L1 Two books, two balances | C19: ★★☆☆☆ | D19: 7 | E19: =COUNTIF('L1 Two books, two balances'!N9:N15,"✓*") -> 0 | F19: =IFERROR(E19/D19,0) -> 0
A20: 2 | B20: L2 Match by reference | C20: ★★★☆☆ | D20: 6 | E20: =COUNTIF('L2 Match by reference'!O9:O14,"✓*") -> 0 | F20: =IFERROR(E20/D20,0) -> 0
A21: 3 | B21: L3 The bank's own entries | C21: ★★★☆☆ | D21: 6 | E21: =COUNTIF('L3 The bank''s own entries'!O9:O14,"✓*") -> 0 | F21: =IFERROR(E21/D21,0) -> 0
A22: 4 | B22: L4 Amounts that don't agree | C22: ★★★★☆ | D22: 5 | E22: =COUNTIF('L4 Amounts that don''t agree'!P9:P13,"✓*") -> 0 | F22: =IFERROR(E22/D22,0) -> 0
A23: 5 | B23: L5 The reconciliation statement | C23: ★★★★☆ | D23: 7 | E23: =COUNTIF('L5 The reconciliation statement'!N9:N15,"✓*") -> 0 | F23: =IFERROR(E23/D23,0) -> 0
A24: 6 | B24: L6 Boss round — automatic recon | C24: ★★★★★ | D24: 5 | E24: =COUNTIF('L6 Boss round — automatic recon'!O9:O13,"✓*") -> 0 | F24: =IFERROR(E24/D24,0) -> 0
B25: OVERALL | D25: =SUM(D19:D24) -> 36 | E25: =SUM(E19:E24) -> 0 | F25: =IFERROR(E25/D25,0) -> 0
A27: Excel Lab — created by Pranay · excel-lab-by-pranay.vercel.app · free for every student

Sheet L1 Two books, two balances
A1: LESSON 1 · TWO BOOKS, TWO BALANCES
A2: ★★☆☆☆ Total both books and see the gap you are about to explain.
A3: CONCEPT · Your cash book and the bank statement almost never agree on the last day of the month — and that is normal. Amounts are signed: money in is positive, money out is negative, so SUM gives the net movement. Closing balance = opening balance + net movement. Find both closing balances first; the difference is what the reconciliation has to explain.
A6: Opening balance | B6: 842500
A8: Ref | B8: Date | C8: Particulars | D8: Amount | F8: Ref | G8: Date | H8: Particulars | I8: Amount | K8: # | L8: Task | M8: Your answer | N8: Check | O8: Hint
A9: DEP-7163 | B9: 46112 | C9: Received from ABC Traders | D9: 29800 | F9: DEP-7122 | G9: 46105 | H9: Deposit - Shree Enterprises | I9: 25000 | K9: 1 | L9: Net movement as per the cash book (SUM the cash book Amount column). | N9: =IF(ISBLANK(M9),"◯ Not attempted",IF(NOT(_xlfn.ISFORMULA(M9)),"✎ Use a formula",IF(ISNUMBER(M9),IF(ABS(M9-$P$9)<0.005,"✓ Correct","✗ Check again"),"✗ Not a number"))) -> ◯ Not attempted | O9: One SUM over the whole Amount column of the left table. | P9: =SUM($D$9:$D$42) -> -26450
A10: CHQ-4151 | B10: 46107 | C10: Cheque issued to Sagar Metals | D10: -96500 | F10: DEP-7110 | G10: 46108 | H10: Deposit - Nandini Foods | I10: 189000 | K10: 2 | L10: Closing balance as per the cash book = opening balance (B6) + net movement. | N10: =IF(ISBLANK(M10),"◯ Not attempted",IF(NOT(_xlfn.ISFORMULA(M10)),"✎ Use a formula",IF(ISNUMBER(M10),IF(ABS(M10-$P$10)<0.005,"✓ Correct","✗ Check again"),"✗ Not a number"))) -> ◯ Not attempted | O10: =$B$6+SUM(D9:D44) | P10: =$B$6+SUM($D$9:$D$42) -> 816050
A11: CHQ-4152 | B11: 46108 | C11: Cheque issued to Patel & Co | D11: -41200 | F11: DEP-7108 | G11: 46086 | H11: Deposit - Kiran Agencies | I11: 75500 | K11: 3 | L11: Net movement as per the bank statement. | N11: =IF(ISBLANK(M11),"◯ Not attempted",IF(NOT(_xlfn.ISFORMULA(M11)),"✎ Use a formula",IF(ISNUMBER(M11),IF(ABS(M11-$P$11)<0.005,"✓ Correct","✗ Check again"),"✗ Not a number"))) -> ◯ Not attempted | O11: SUM the Amount column of the right-hand table. | P11: =SUM($I$9:$I$40) -> 143304
A12: DEP-7114 | B12: 46095 | C12: Received from Patel & Co | D12: 225500 | F12: DEP-7114 | G12: 46097 | H12: Deposit - Patel & Co | I12: 225500 | K12: 4 | L12: Closing balance as per the bank statement. | N12: =IF(ISBLANK(M12),"◯ Not attempted",IF(NOT(_xlfn.ISFORMULA(M12)),"✎ Use a formula",IF(ISNUMBER(M12),IF(ABS(M12-$P$12)<0.005,"✓ Correct","✗ Check again"),"✗ Not a number"))) -> ◯ Not attempted | O12: Same shape as the cash book closing balance. | P12: =$B$6+SUM($I$9:$I$40) -> 985804
A13: CHQ-4154 | B13: 46111 | C13: Cheque issued to Kiran Agencies | D13: -23750 | F13: DEP-7112 | G13: 46087 | H13: Deposit - Bharat Electricals | I13: 97500 | K13: 5 | L13: The difference: bank closing balance minus cash book closing balance. | N13: =IF(ISBLANK(M13),"◯ Not attempted",IF(NOT(_xlfn.ISFORMULA(M13)),"✎ Use a formula",IF(ISNUMBER(M13),IF(ABS(M13-$P$13)<0.005,"✓ Correct","✗ Check again"),"✗ Not a number"))) -> ◯ Not attempted | O13: The opening balances cancel out, so it is just one net movement minus the other. | P13: =SUM($I$9:$I$40)-SUM($D$9:$D$42) -> 169754
A14: DEP-7118 | B14: 46106 | C14: Received from Vaibhav Textiles | D14: 226500 | F14: CHQ-4105 | G14: 46099 | H14: Cheque paid - Shree Enterprises | I14: -155500 | K14: 6 | L14: How many entries are in the cash book? | N14: =IF(ISBLANK(M14),"◯ Not attempted",IF(NOT(_xlfn.ISFORMULA(M14)),"✎ Use a formula",IF(ISNUMBER(M14),IF(ABS(M14-$P$14)<0.005,"✓ Correct","✗ Check again"),"✗ Not a number"))) -> ◯ Not attempted | O14: COUNTA counts filled cells. | P14: =COUNTA($A$9:$A$42) -> 34
A15: DEP-7110 | B15: 46105 | C15: Received from Nandini Foods | D15: 189000 | F15: DEP-7102 | G15: 46106 | H15: Deposit - Nova Industries | I15: 90500 | K15: 7 | L15: How many entries are on the bank statement? | N15: =IF(ISBLANK(M15),"◯ Not attempted",IF(NOT(_xlfn.ISFORMULA(M15)),"✎ Use a formula",IF(ISNUMBER(M15),IF(ABS(M15-$P$15)<0.005,"✓ Correct","✗ Check again"),"✗ Not a number"))) -> ◯ Not attempted | O15: Same idea on the other table. | P15: =COUNTA($F$9:$F$40) -> 32
A16: CHQ-4105 | B16: 46099 | C16: Cheque issued to Shree Enterprises | D16: -155500 | F16: BNK-004 | G16: 46103 | H16: NEFT direct credit - Zenith Software | I16: 68000
A17: CHQ-4119 | B17: 46091 | C17: Cheque issued to Shree Enterprises | D17: -162500 | F17: DEP-7142 | G17: 46101 | H17: Deposit - Orbit Systems | I17: 117410
A18: DEP-7124 | B18: 46099 | C18: Received from Sagar Metals | D18: 146000 | F18: CHQ-4119 | G18: 46091 | H18: Cheque paid - Shree Enterprises | I18: -162500
A19: DEP-7102 | B19: 46104 | C19: Received from Nova Industries | D19: 90500 | F19: BNK-001 | G19: 46112 | H19: Bank charges - quarterly | I19: -1180
A20: DEP-7112 | B20: 46087 | C20: Received from Bharat Electricals | D20: 97500 | F20: CHQ-4109 | G20: 46097 | H20: Cheque paid - Bharat Electricals | I20: -199000
A21: DEP-7120 | B21: 46094 | C21: Received from Bharat Electricals | D21: 88000 | F21: DEP-7120 | G21: 46098 | H21: Deposit - Bharat Electricals | I21: 88000
A22: CHQ-4155 | B22: 46112 | C22: Cheque issued to Meera Pharma | D22: -67400 | F22: CHQ-4111 | G22: 46092 | H22: Cheque paid - Deccan Supplies | I22: -80500
A23: CHQ-4123 | B23: 46090 | C23: Cheque issued to Nova Industries | D23: -90500 | F23: DEP-7124 | G23: 46102 | H23: Deposit - Sagar Metals | I23: 146000
A24: DEP-7122 | B24: 46102 | C24: Received from Shree Enterprises | D24: 25000 | F24: BNK-006 | G24: 46101 | H24: Cheque returned - insufficient funds | I24: -25000
A25: CHQ-4107 | B25: 46085 | C25: Cheque issued to Nandini Foods | D25: -67500 | F25: DEP-7104 | G25: 46098 | H25: Deposit - Vaibhav Textiles | I25: 19000
A26: CHQ-4121 | B26: 46085 | C26: Cheque issued to Bharat Electricals | D26: -149500 | F26: CHQ-4131 | G26: 46092 | H26: Cheque paid - Meera Pharma | I26: -49500
A27: CHQ-4115 | B27: 46082 | C27: Cheque issued to Sagar Metals | D27: -75000 | F27: BNK-005 | G27: 46096 | H27: ECS debit - insurance premium | I27: -12500
... A40: CHQ-4117 | B40: 46102 | C40: Cheque issued to Nandini Foods | D40: -233000 | F40: DEP-7106 | G40: 46095 | H40: Deposit - Bharat Electricals | I40: 195000
A41: DEP-7108 | B41: 46086 | C41: Received from Kiran Agencies | D41: 75500
A42: DEP-7162 | B42: 46112 | C42: Received from Nandini Foods | D42: 132500

Sheet L2 Match by reference
A1: LESSON 2 · MATCH BY REFERENCE
A2: ★★★☆☆ Tick off every cash book entry that has reached the bank.
A3: CONCEPT · COUNTIF(bank reference column, this reference) returns how many times your reference appears on the statement. Zero means it has not reached the bank yet. Wrap it in IF to turn the count into a readable label, and lock the bank range with $ so it does not slide as you fill down.
A8: Ref | B8: Date | C8: Particulars | D8: Amount | E8: In bank? | G8: Ref | H8: Date | I8: Particulars | J8: Amount | L8: # | M8: Task | N8: Your answer | O8: Check | P8: Hint
A9: DEP-7163 | B9: 46112 | C9: Received from ABC Traders | D9: 29800 | G9: DEP-7122 | H9: 46105 | I9: Deposit - Shree Enterprises | J9: 25000 | L9: 1 | M9: Fill "In bank?": "Yes" if the reference appears on the bank statement, otherwise "No". | N9: → fill column E | O9: =IF(COUNTA($E$9:$E$42)=0,"◯ Not attempted",IF(NOT(_xlfn.ISFORMULA(E9)),"✎ Use a formula",IFERROR(IF(SUMPRODUCT(--(UPPER(TRIM($E$9:$E$42&""))=UPPER(TRIM($R$9:$R$42&""))))=ROWS($E$9:$E$42),"✓ Correct","✗ "&(ROWS($E$9:$E$42)-SUMPRODUCT(--(UPPER(TRIM($E$9:$E$42&""))=UPPER(TRIM($R$9:$R$42&"")))))&" rows differ"),"✗ Check the column"))) -> ◯ Not attempted | P9: =IF(COUNTIF($G$9:$G$40,A9)>0,"Yes","No") — then fill down. | R9: =IF(COUNTIF($G$9:$G$40,A9)>0,"Yes","No") -> No
A10: CHQ-4151 | B10: 46107 | C10: Cheque issued to Sagar Metals | D10: -96500 | G10: DEP-7110 | H10: 46108 | I10: Deposit - Nandini Foods | J10: 189000 | L10: 2 | M10: How many cash book entries have NOT reached the bank? | O10: =IF(ISBLANK(N10),"◯ Not attempted",IF(NOT(_xlfn.ISFORMULA(N10)),"✎ Use a formula",IF(ISNUMBER(N10),IF(ABS(N10-$Q$10)<0.005,"✓ Correct","✗ Check again"),"✗ Not a number"))) -> ◯ Not attempted | P10: COUNTIF your new column for "No". | Q10: =SUMPRODUCT(--(COUNTIF($G$9:$G$40,$A$9:$A$42)=0)) -> 8 | R10: =IF(COUNTIF($G$9:$G$40,A10)>0,"Yes","No") -> No
A11: CHQ-4152 | B11: 46108 | C11: Cheque issued to Patel & Co | D11: -41200 | G11: DEP-7108 | H11: 46086 | I11: Deposit - Kiran Agencies | J11: 75500 | L11: 3 | M11: Net value of those unmatched entries. | O11: =IF(ISBLANK(N11),"◯ Not attempted",IF(NOT(_xlfn.ISFORMULA(N11)),"✎ Use a formula",IF(ISNUMBER(N11),IF(ABS(N11-$Q$11)<0.005,"✓ Correct","✗ Check again"),"✗ Not a number"))) -> ◯ Not attempted | P11: SUMIF on the label you just created. | Q11: =SUMPRODUCT((COUNTIF($G$9:$G$40,$A$9:$A$42)=0)*$D$9:$D$42) -> -140550 | R11: =IF(COUNTIF($G$9:$G$40,A11)>0,"Yes","No") -> No
A12: DEP-7114 | B12: 46095 | C12: Received from Patel & Co | D12: 225500 | G12: DEP-7114 | H12: 46097 | I12: Deposit - Patel & Co | J12: 225500 | L12: 4 | M12: Total of cheques issued but not yet presented (unmatched entries with a negative amount). | O12: =IF(ISBLANK(N12),"◯ Not attempted",IF(NOT(_xlfn.ISFORMULA(N12)),"✎ Use a formula",IF(ISNUMBER(N12),IF(ABS(N12-$Q$12)<0.005,"✓ Correct","✗ Check again"),"✗ Not a number"))) -> ◯ Not attempted | P12: SUMIFS with two conditions: In bank? = "No" AND Amount < 0. | Q12: =-386850 -> -386850 | R12: =IF(COUNTIF($G$9:$G$40,A12)>0,"Yes","No") -> Yes
A13: CHQ-4154 | B13: 46111 | C13: Cheque issued to Kiran Agencies | D13: -23750 | G13: DEP-7112 | H13: 46087 | I13: Deposit - Bharat Electricals | J13: 97500 | L13: 5 | M13: Total of deposits in transit (unmatched entries with a positive amount). | O13: =IF(ISBLANK(N13),"◯ Not attempted",IF(NOT(_xlfn.ISFORMULA(N13)),"✎ Use a formula",IF(ISNUMBER(N13),IF(ABS(N13-$Q$13)<0.005,"✓ Correct","✗ Check again"),"✗ Not a number"))) -> ◯ Not attempted | P13: Same SUMIFS with the sign flipped. | Q13: =246300 -> 246300 | R13: =IF(COUNTIF($G$9:$G$40,A13)>0,"Yes","No") -> No
A14: DEP-7118 | B14: 46106 | C14: Received from Vaibhav Textiles | D14: 226500 | G14: CHQ-4105 | H14: 46099 | I14: Cheque paid - Shree Enterprises | J14: -155500 | L14: 6 | M14: Check: unpresented cheques + deposits in transit must equal the net value of unmatched entries. | O14: =IF(ISBLANK(N14),"◯ Not attempted",IF(NOT(_xlfn.ISFORMULA(N14)),"✎ Use a formula",IF(ISNUMBER(N14),IF(ABS(N14-$Q$14)<0.5,"✓ Correct","✗ Check again"),"✗ Not a number"))) -> ◯ Not attempted | P14: Add your last two answers and subtract the one before them. It must be zero. | Q14: =0 -> 0 | R14: =IF(COUNTIF($G$9:$G$40,A14)>0,"Yes","No") -> Yes
A15: DEP-7110 | B15: 46105 | C15: Received from Nandini Foods | D15: 189000 | G15: DEP-7102 | H15: 46106 | I15: Deposit - Nova Industries | J15: 90500 | R15: =IF(COUNTIF($G$9:$G$40,A15)>0,"Yes","No") -> Yes
A16: CHQ-4105 | B16: 46099 | C16: Cheque issued to Shree Enterprises | D16: -155500 | G16: BNK-004 | H16: 46103 | I16: NEFT direct credit - Zenith Software | J16: 68000 | R16: =IF(COUNTIF($G$9:$G$40,A16)>0,"Yes","No") -> Yes
A17: CHQ-4119 | B17: 46091 | C17: Cheque issued to Shree Enterprises | D17: -162500 | G17: DEP-7142 | H17: 46101 | I17: Deposit - Orbit Systems | J17: 117410 | R17: =IF(COUNTIF($G$9:$G$40,A17)>0,"Yes","No") -> Yes
A18: DEP-7124 | B18: 46099 | C18: Received from Sagar Metals | D18: 146000 | G18: CHQ-4119 | H18: 46091 | I18: Cheque paid - Shree Enterprises | J18: -162500 | R18: =IF(COUNTIF($G$9:$G$40,A18)>0,"Yes","No") -> Yes
A19: DEP-7102 | B19: 46104 | C19: Received from Nova Industries | D19: 90500 | G19: BNK-001 | H19: 46112 | I19: Bank charges - quarterly | J19: -1180 | R19: =IF(COUNTIF($G$9:$G$40,A19)>0,"Yes","No") -> Yes
A20: DEP-7112 | B20: 46087 | C20: Received from Bharat Electricals | D20: 97500 | G20: CHQ-4109 | H20: 46097 | I20: Cheque paid - Bharat Electricals | J20: -199000 | R20: =IF(COUNTIF($G$9:$G$40,A20)>0,"Yes","No") -> Yes
A21: DEP-7120 | B21: 46094 | C21: Received from Bharat Electricals | D21: 88000 | G21: DEP-7120 | H21: 46098 | I21: Deposit - Bharat Electricals | J21: 88000 | R21: =IF(COUNTIF($G$9:$G$40,A21)>0,"Yes","No") -> Yes
A22: CHQ-4155 | B22: 46112 | C22: Cheque issued to Meera Pharma | D22: -67400 | G22: CHQ-4111 | H22: 46092 | I22: Cheque paid - Deccan Supplies | J22: -80500 | R22: =IF(COUNTIF($G$9:$G$40,A22)>0,"Yes","No") -> No
A23: CHQ-4123 | B23: 46090 | C23: Cheque issued to Nova Industries | D23: -90500 | G23: DEP-7124 | H23: 46102 | I23: Deposit - Sagar Metals | J23: 146000 | R23: =IF(COUNTIF($G$9:$G$40,A23)>0,"Yes","No") -> Yes
A24: DEP-7122 | B24: 46102 | C24: Received from Shree Enterprises | D24: 25000 | G24: BNK-006 | H24: 46101 | I24: Cheque returned - insufficient funds | J24: -25000 | R24: =IF(COUNTIF($G$9:$G$40,A24)>0,"Yes","No") -> Yes
A25: CHQ-4107 | B25: 46085 | C25: Cheque issued to Nandini Foods | D25: -67500 | G25: DEP-7104 | H25: 46098 | I25: Deposit - Vaibhav Textiles | J25: 19000 | R25: =IF(COUNTIF($G$9:$G$40,A25)>0,"Yes","No") -> Yes
A26: CHQ-4121 | B26: 46085 | C26: Cheque issued to Bharat Electricals | D26: -149500 | G26: CHQ-4131 | H26: 46092 | I26: Cheque paid - Meera Pharma | J26: -49500 | R26: =IF(COUNTIF($G$9:$G$40,A26)>0,"Yes","No") -> Yes
... A40: CHQ-4117 | B40: 46102 | C40: Cheque issued to Nandini Foods | D40: -233000 | G40: DEP-7106 | H40: 46095 | I40: Deposit - Bharat Electricals | J40: 195000 | R40: =IF(COUNTIF($G$9:$G$40,A40)>0,"Yes","No") -> Yes
A41: DEP-7108 | B41: 46086 | C41: Received from Kiran Agencies | D41: 75500 | R41: =IF(COUNTIF($G$9:$G$40,A41)>0,"Yes","No") -> Yes
A42: DEP-7162 | B42: 46112 | C42: Received from Nandini Foods | D42: 132500 | R42: =IF(COUNTIF($G$9:$G$40,A42)>0,"Yes","No") -> No

Sheet L3 The bank's own entries
A1: LESSON 3 · THE BANK'S OWN ENTRIES
A2: ★★★☆☆ Find what the bank did that you never recorded.
A3: CONCEPT · Now run the match the other way. Bank charges, interest, ECS debits and direct credits appear on the statement first — you only learn about them when the statement arrives. These are not timing differences: they are entries missing from YOUR book, and they have to be posted before the balances can ever agree.
A8: Ref | B8: Date | C8: Particulars | D8: Amount | F8: Ref | G8: Date | H8: Particulars | I8: Amount | J8: In cash book? | L8: # | M8: Task | N8: Your answer | O8: Check | P8: Hint
A9: DEP-7163 | B9: 46112 | C9: Received from ABC Traders | D9: 29800 | F9: DEP-7122 | G9: 46105 | H9: Deposit - Shree Enterprises | I9: 25000 | L9: 1 | M9: Fill "In cash book?" on the bank statement: "Yes" or "No". | N9: → fill column J | O9: =IF(COUNTA($J$9:$J$40)=0,"◯ Not attempted",IF(NOT(_xlfn.ISFORMULA(J9)),"✎ Use a formula",IFERROR(IF(SUMPRODUCT(--(UPPER(TRIM($J$9:$J$40&""))=UPPER(TRIM($R$9:$R$40&""))))=ROWS($J$9:$J$40),"✓ Correct","✗ "&(ROWS($J$9:$J$40)-SUMPRODUCT(--(UPPER(TRIM($J$9:$J$40&""))=UPPER(TRIM($R$9:$R$40&"")))))&" rows differ"),"✗ Check the column"))) -> ◯ Not attempted | P9: Same formula as before, but COUNTIF now looks at the cash book references. | R9: =IF(COUNTIF($A$9:$A$42,F9)>0,"Yes","No") -> Yes
A10: CHQ-4151 | B10: 46107 | C10: Cheque issued to Sagar Metals | D10: -96500 | F10: DEP-7110 | G10: 46108 | H10: Deposit - Nandini Foods | I10: 189000 | L10: 2 | M10: How many bank entries are missing from your cash book? | O10: =IF(ISBLANK(N10),"◯ Not attempted",IF(NOT(_xlfn.ISFORMULA(N10)),"✎ Use a formula",IF(ISNUMBER(N10),IF(ABS(N10-$Q$10)<0.005,"✓ Correct","✗ Check again"),"✗ Not a number"))) -> ◯ Not attempted | P10: COUNTIF for "No". | Q10: =SUMPRODUCT(--(COUNTIF($A$9:$A$42,$F$9:$F$40)=0)) -> 6 | R10: =IF(COUNTIF($A$9:$A$42,F10)>0,"Yes","No") -> Yes
A11: CHQ-4152 | B11: 46108 | C11: Cheque issued to Patel & Co | D11: -41200 | F11: DEP-7108 | G11: 46086 | H11: Deposit - Kiran Agencies | I11: 75500 | L11: 3 | M11: Net value of those bank-only entries. | O11: =IF(ISBLANK(N11),"◯ Not attempted",IF(NOT(_xlfn.ISFORMULA(N11)),"✎ Use a formula",IF(ISNUMBER(N11),IF(ABS(N11-$Q$11)<0.005,"✓ Correct","✗ Check again"),"✗ Not a number"))) -> ◯ Not attempted | P11: SUMIF the label. | Q11: =33394 -> 33394 | R11: =IF(COUNTIF($A$9:$A$42,F11)>0,"Yes","No") -> Yes
A12: DEP-7114 | B12: 46095 | C12: Received from Patel & Co | D12: 225500 | F12: DEP-7114 | G12: 46097 | H12: Deposit - Patel & Co | I12: 225500 | L12: 4 | M12: Total of bank-only DEBITS (charges, ECS, returned cheque — the negative ones). | O12: =IF(ISBLANK(N12),"◯ Not attempted",IF(NOT(_xlfn.ISFORMULA(N12)),"✎ Use a formula",IF(ISNUMBER(N12),IF(ABS(N12-$Q$12)<0.005,"✓ Correct","✗ Check again"),"✗ Not a number"))) -> ◯ Not attempted | P12: SUMIFS: label = No AND amount < 0. | Q12: =-38916 -> -38916 | R12: =IF(COUNTIF($A$9:$A$42,F12)>0,"Yes","No") -> Yes
A13: CHQ-4154 | B13: 46111 | C13: Cheque issued to Kiran Agencies | D13: -23750 | F13: DEP-7112 | G13: 46087 | H13: Deposit - Bharat Electricals | I13: 97500 | L13: 5 | M13: Total of bank-only CREDITS (interest and direct receipts). | O13: =IF(ISBLANK(N13),"◯ Not attempted",IF(NOT(_xlfn.ISFORMULA(N13)),"✎ Use a formula",IF(ISNUMBER(N13),IF(ABS(N13-$Q$13)<0.005,"✓ Correct","✗ Check again"),"✗ Not a number"))) -> ◯ Not attempted | P13: Same, amount > 0. | Q13: =72310 -> 72310 | R13: =IF(COUNTIF($A$9:$A$42,F13)>0,"Yes","No") -> Yes
A14: DEP-7118 | B14: 46106 | C14: Received from Vaibhav Textiles | D14: 226500 | F14: CHQ-4105 | G14: 46099 | H14: Cheque paid - Shree Enterprises | I14: -155500 | L14: 6 | M14: Which bank-only entry is the largest debit? Return its Particulars. | O14: =IF(ISBLANK(N14),"◯ Not attempted",IF(NOT(_xlfn.ISFORMULA(N14)),"✎ Use a formula",IF(UPPER(TRIM(N14&""))=UPPER(TRIM($Q$14&"")),"✓ Correct","✗ Check again"))) -> ◯ Not attempted | P14: MINIFS finds the most negative amount among the No rows; MATCH then finds its position. | Q14: ="Cheque returned - insufficient funds" -> Cheque returned - insufficient funds | R14: =IF(COUNTIF($A$9:$A$42,F14)>0,"Yes","No") -> Yes
A15: DEP-7110 | B15: 46105 | C15: Received from Nandini Foods | D15: 189000 | F15: DEP-7102 | G15: 46106 | H15: Deposit - Nova Industries | I15: 90500 | R15: =IF(COUNTIF($A$9:$A$42,F15)>0,"Yes","No") -> Yes
A16: CHQ-4105 | B16: 46099 | C16: Cheque issued to Shree Enterprises | D16: -155500 | F16: BNK-004 | G16: 46103 | H16: NEFT direct credit - Zenith Software | I16: 68000 | R16: =IF(COUNTIF($A$9:$A$42,F16)>0,"Yes","No") -> No
A17: CHQ-4119 | B17: 46091 | C17: Cheque issued to Shree Enterprises | D17: -162500 | F17: DEP-7142 | G17: 46101 | H17: Deposit - Orbit Systems | I17: 117410 | R17: =IF(COUNTIF($A$9:$A$42,F17)>0,"Yes","No") -> Yes
A18: DEP-7124 | B18: 46099 | C18: Received from Sagar Metals | D18: 146000 | F18: CHQ-4119 | G18: 46091 | H18: Cheque paid - Shree Enterprises | I18: -162500 | R18: =IF(COUNTIF($A$9:$A$42,F18)>0,"Yes","No") -> Yes
A19: DEP-7102 | B19: 46104 | C19: Received from Nova Industries | D19: 90500 | F19: BNK-001 | G19: 46112 | H19: Bank charges - quarterly | I19: -1180 | R19: =IF(COUNTIF($A$9:$A$42,F19)>0,"Yes","No") -> No
A20: DEP-7112 | B20: 46087 | C20: Received from Bharat Electricals | D20: 97500 | F20: CHQ-4109 | G20: 46097 | H20: Cheque paid - Bharat Electricals | I20: -199000 | R20: =IF(COUNTIF($A$9:$A$42,F20)>0,"Yes","No") -> Yes
A21: DEP-7120 | B21: 46094 | C21: Received from Bharat Electricals | D21: 88000 | F21: DEP-7120 | G21: 46098 | H21: Deposit - Bharat Electricals | I21: 88000 | R21: =IF(COUNTIF($A$9:$A$42,F21)>0,"Yes","No") -> Yes
A22: CHQ-4155 | B22: 46112 | C22: Cheque issued to Meera Pharma | D22: -67400 | F22: CHQ-4111 | G22: 46092 | H22: Cheque paid - Deccan Supplies | I22: -80500 | R22: =IF(COUNTIF($A$9:$A$42,F22)>0,"Yes","No") -> Yes
A23: CHQ-4123 | B23: 46090 | C23: Cheque issued to Nova Industries | D23: -90500 | F23: DEP-7124 | G23: 46102 | H23: Deposit - Sagar Metals | I23: 146000 | R23: =IF(COUNTIF($A$9:$A$42,F23)>0,"Yes","No") -> Yes
A24: DEP-7122 | B24: 46102 | C24: Received from Shree Enterprises | D24: 25000 | F24: BNK-006 | G24: 46101 | H24: Cheque returned - insufficient funds | I24: -25000 | R24: =IF(COUNTIF($A$9:$A$42,F24)>0,"Yes","No") -> No
A25: CHQ-4107 | B25: 46085 | C25: Cheque issued to Nandini Foods | D25: -67500 | F25: DEP-7104 | G25: 46098 | H25: Deposit - Vaibhav Textiles | I25: 19000 | R25: =IF(COUNTIF($A$9:$A$42,F25)>0,"Yes","No") -> Yes
A26: CHQ-4121 | B26: 46085 | C26: Cheque issued to Bharat Electricals | D26: -149500 | F26: CHQ-4131 | G26: 46092 | H26: Cheque paid - Meera Pharma | I26: -49500 | R26: =IF(COUNTIF($A$9:$A$42,F26)>0,"Yes","No") -> Yes
... A40: CHQ-4117 | B40: 46102 | C40: Cheque issued to Nandini Foods | D40: -233000 | F40: DEP-7106 | G40: 46095 | H40: Deposit - Bharat Electricals | I40: 195000 | R40: =IF(COUNTIF($A$9:$A$42,F40)>0,"Yes","No") -> Yes
A41: DEP-7108 | B41: 46086 | C41: Received from Kiran Agencies | D41: 75500
A42: DEP-7162 | B42: 46112 | C42: Received from Nandini Foods | D42: 132500

Sheet L4 Amounts that don't agree
A1: LESSON 4 · AMOUNTS THAT DON'T AGREE
A2: ★★★★☆ Two references match but the money doesn't. Find them without reading 36 rows.
A3: CONCEPT · The nastiest reconciling item is an entry that IS on both sides with the wrong amount — a transposed figure, or a collection charge the bank deducted. Pull the bank amount next to the book amount with a lookup, subtract, and look for non-zero rows. IFNA(...,0) keeps the unmatched rows from turning into #N/A.
A8: Ref | B8: Date | C8: Particulars | D8: Amount | E8: Bank amount | F8: Difference | H8: Ref | I8: Date | J8: Particulars | K8: Amount | M8: # | N8: Task | O8: Your answer | P8: Check | Q8: Hint
A9: DEP-7163 | B9: 46112 | C9: Received from ABC Traders | D9: 29800 | H9: DEP-7122 | I9: 46105 | J9: Deposit - Shree Enterprises | K9: 25000 | M9: 1 | N9: Fill Bank amount: the amount the bank shows for this reference, or 0 if the bank has no such entry. | O9: → fill column E | P9: =IF(COUNTA($E$9:$E$42)=0,"◯ Not attempted",IF(NOT(_xlfn.ISFORMULA(E9)),"✎ Use a formula",IFERROR(IF(SUMPRODUCT(--(ABS($E$9:$E$42-$S$9:$S$42)<0.01))=ROWS($E$9:$E$42),"✓ Correct","✗ "&(ROWS($E$9:$E$42)-SUMPRODUCT(--(ABS($E$9:$E$42-$S$9:$S$42)<0.01)))&" rows differ"),"✗ Check the column"))) -> ◯ Not attempted | Q9: =IFNA(VLOOKUP(A9,$H$9:$K$40,4,0),0) — column 4 of the bank table is Amount. | S9: =_xlfn.IFNA(VLOOKUP(A9,$H$9:$K$40,4,0),0) -> 0 | T9: =D9-_xlfn.IFNA(VLOOKUP(A9,$H$9:$K$40,4,0),0) -> 29800
A10: CHQ-4151 | B10: 46107 | C10: Cheque issued to Sagar Metals | D10: -96500 | H10: DEP-7110 | I10: 46108 | J10: Deposit - Nandini Foods | K10: 189000 | M10: 2 | N10: Fill Difference = cash book Amount minus Bank amount. | O10: → fill column F | P10: =IF(COUNTA($F$9:$F$42)=0,"◯ Not attempted",IF(NOT(_xlfn.ISFORMULA(F9)),"✎ Use a formula",IFERROR(IF(SUMPRODUCT(--(ABS($F$9:$F$42-$T$9:$T$42)<0.01))=ROWS($F$9:$F$42),"✓ Correct","✗ "&(ROWS($F$9:$F$42)-SUMPRODUCT(--(ABS($F$9:$F$42-$T$9:$T$42)<0.01)))&" rows differ"),"✗ Check the column"))) -> ◯ Not attempted | Q10: =D9-E9 | S10: =_xlfn.IFNA(VLOOKUP(A10,$H$9:$K$40,4,0),0) -> 0 | T10: =D10-_xlfn.IFNA(VLOOKUP(A10,$H$9:$K$40,4,0),0) -> -96500
A11: CHQ-4152 | B11: 46108 | C11: Cheque issued to Patel & Co | D11: -41200 | H11: DEP-7108 | I11: 46086 | J11: Deposit - Kiran Agencies | K11: 75500 | M11: 3 | N11: How many references are on BOTH sides but with different amounts? | P11: =IF(ISBLANK(O11),"◯ Not attempted",IF(NOT(_xlfn.ISFORMULA(O11)),"✎ Use a formula",IF(ISNUMBER(O11),IF(ABS(O11-$R$11)<0.005,"✓ Correct","✗ Check again"),"✗ Not a number"))) -> ◯ Not attempted | Q11: Count rows where Bank amount is not zero and the difference is not zero. | R11: =2 -> 2 | S11: =_xlfn.IFNA(VLOOKUP(A11,$H$9:$K$40,4,0),0) -> 0 | T11: =D11-_xlfn.IFNA(VLOOKUP(A11,$H$9:$K$40,4,0),0) -> -41200
A12: DEP-7114 | B12: 46095 | C12: Received from Patel & Co | D12: 225500 | H12: DEP-7114 | I12: 46097 | J12: Deposit - Patel & Co | K12: 225500 | M12: 4 | N12: Net effect of those amount differences (bank minus book, for matched references only). | P12: =IF(ISBLANK(O12),"◯ Not attempted",IF(NOT(_xlfn.ISFORMULA(O12)),"✎ Use a formula",IF(ISNUMBER(O12),IF(ABS(O12-$R$12)<0.005,"✓ Correct","✗ Check again"),"✗ Not a number"))) -> ◯ Not attempted | Q12: Your Difference column is book − bank, so flip the sign and only count rows where a bank amount exists. | R12: =-4190 -> -4190 | S12: =_xlfn.IFNA(VLOOKUP(A12,$H$9:$K$40,4,0),0) -> 225500 | T12: =D12-_xlfn.IFNA(VLOOKUP(A12,$H$9:$K$40,4,0),0) -> 0
A13: CHQ-4154 | B13: 46111 | C13: Cheque issued to Kiran Agencies | D13: -23750 | H13: DEP-7112 | I13: 46087 | J13: Deposit - Bharat Electricals | K13: 97500 | M13: 5 | N13: Total of the cash book entries that matched the bank EXACTLY. | P13: =IF(ISBLANK(O13),"◯ Not attempted",IF(NOT(_xlfn.ISFORMULA(O13)),"✎ Use a formula",IF(ISNUMBER(O13),IF(ABS(O13-$R$13)<0.005,"✓ Correct","✗ Check again"),"✗ Not a number"))) -> ◯ Not attempted | Q13: Bank amount not zero AND Difference exactly 0. | R13: =42000 -> 42000 | S13: =_xlfn.IFNA(VLOOKUP(A13,$H$9:$K$40,4,0),0) -> 0 | T13: =D13-_xlfn.IFNA(VLOOKUP(A13,$H$9:$K$40,4,0),0) -> -23750
A14: DEP-7118 | B14: 46106 | C14: Received from Vaibhav Textiles | D14: 226500 | H14: CHQ-4105 | I14: 46099 | J14: Cheque paid - Shree Enterprises | K14: -155500 | S14: =_xlfn.IFNA(VLOOKUP(A14,$H$9:$K$40,4,0),0) -> 226500 | T14: =D14-_xlfn.IFNA(VLOOKUP(A14,$H$9:$K$40,4,0),0) -> 0
A15: DEP-7110 | B15: 46105 | C15: Received from Nandini Foods | D15: 189000 | H15: DEP-7102 | I15: 46106 | J15: Deposit - Nova Industries | K15: 90500 | S15: =_xlfn.IFNA(VLOOKUP(A15,$H$9:$K$40,4,0),0) -> 189000 | T15: =D15-_xlfn.IFNA(VLOOKUP(A15,$H$9:$K$40,4,0),0) -> 0
A16: CHQ-4105 | B16: 46099 | C16: Cheque issued to Shree Enterprises | D16: -155500 | H16: BNK-004 | I16: 46103 | J16: NEFT direct credit - Zenith Software | K16: 68000 | S16: =_xlfn.IFNA(VLOOKUP(A16,$H$9:$K$40,4,0),0) -> -155500 | T16: =D16-_xlfn.IFNA(VLOOKUP(A16,$H$9:$K$40,4,0),0) -> 0
A17: CHQ-4119 | B17: 46091 | C17: Cheque issued to Shree Enterprises | D17: -162500 | H17: DEP-7142 | I17: 46101 | J17: Deposit - Orbit Systems | K17: 117410 | S17: =_xlfn.IFNA(VLOOKUP(A17,$H$9:$K$40,4,0),0) -> -162500 | T17: =D17-_xlfn.IFNA(VLOOKUP(A17,$H$9:$K$40,4,0),0) -> 0
A18: DEP-7124 | B18: 46099 | C18: Received from Sagar Metals | D18: 146000 | H18: CHQ-4119 | I18: 46091 | J18: Cheque paid - Shree Enterprises | K18: -162500 | S18: =_xlfn.IFNA(VLOOKUP(A18,$H$9:$K$40,4,0),0) -> 146000 | T18: =D18-_xlfn.IFNA(VLOOKUP(A18,$H$9:$K$40,4,0),0) -> 0
A19: DEP-7102 | B19: 46104 | C19: Received from Nova Industries | D19: 90500 | H19: BNK-001 | I19: 46112 | J19: Bank charges - quarterly | K19: -1180 | S19: =_xlfn.IFNA(VLOOKUP(A19,$H$9:$K$40,4,0),0) -> 90500 | T19: =D19-_xlfn.IFNA(VLOOKUP(A19,$H$9:$K$40,4,0),0) -> 0
A20: DEP-7112 | B20: 46087 | C20: Received from Bharat Electricals | D20: 97500 | H20: CHQ-4109 | I20: 46097 | J20: Cheque paid - Bharat Electricals | K20: -199000 | S20: =_xlfn.IFNA(VLOOKUP(A20,$H$9:$K$40,4,0),0) -> 97500 | T20: =D20-_xlfn.IFNA(VLOOKUP(A20,$H$9:$K$40,4,0),0) -> 0
A21: DEP-7120 | B21: 46094 | C21: Received from Bharat Electricals | D21: 88000 | H21: DEP-7120 | I21: 46098 | J21: Deposit - Bharat Electricals | K21: 88000 | S21: =_xlfn.IFNA(VLOOKUP(A21,$H$9:$K$40,4,0),0) -> 88000 | T21: =D21-_xlfn.IFNA(VLOOKUP(A21,$H$9:$K$40,4,0),0) -> 0
A22: CHQ-4155 | B22: 46112 | C22: Cheque issued to Meera Pharma | D22: -67400 | H22: CHQ-4111 | I22: 46092 | J22: Cheque paid - Deccan Supplies | K22: -80500 | S22: =_xlfn.IFNA(VLOOKUP(A22,$H$9:$K$40,4,0),0) -> 0 | T22: =D22-_xlfn.IFNA(VLOOKUP(A22,$H$9:$K$40,4,0),0) -> -67400
A23: CHQ-4123 | B23: 46090 | C23: Cheque issued to Nova Industries | D23: -90500 | H23: DEP-7124 | I23: 46102 | J23: Deposit - Sagar Metals | K23: 146000 | S23: =_xlfn.IFNA(VLOOKUP(A23,$H$9:$K$40,4,0),0) -> -90500 | T23: =D23-_xlfn.IFNA(VLOOKUP(A23,$H$9:$K$40,4,0),0) -> 0
A24: DEP-7122 | B24: 46102 | C24: Received from Shree Enterprises | D24: 25000 | H24: BNK-006 | I24: 46101 | J24: Cheque returned - insufficient funds | K24: -25000 | S24: =_xlfn.IFNA(VLOOKUP(A24,$H$9:$K$40,4,0),0) -> 25000 | T24: =D24-_xlfn.IFNA(VLOOKUP(A24,$H$9:$K$40,4,0),0) -> 0
A25: CHQ-4107 | B25: 46085 | C25: Cheque issued to Nandini Foods | D25: -67500 | H25: DEP-7104 | I25: 46098 | J25: Deposit - Vaibhav Textiles | K25: 19000 | S25: =_xlfn.IFNA(VLOOKUP(A25,$H$9:$K$40,4,0),0) -> -67500 | T25: =D25-_xlfn.IFNA(VLOOKUP(A25,$H$9:$K$40,4,0),0) -> 0
... A40: CHQ-4117 | B40: 46102 | C40: Cheque issued to Nandini Foods | D40: -233000 | H40: DEP-7106 | I40: 46095 | J40: Deposit - Bharat Electricals | K40: 195000 | S40: =_xlfn.IFNA(VLOOKUP(A40,$H$9:$K$40,4,0),0) -> -233000 | T40: =D40-_xlfn.IFNA(VLOOKUP(A40,$H$9:$K$40,4,0),0) -> 0
A41: DEP-7108 | B41: 46086 | C41: Received from Kiran Agencies | D41: 75500 | S41: =_xlfn.IFNA(VLOOKUP(A41,$H$9:$K$40,4,0),0) -> 75500 | T41: =D41-_xlfn.IFNA(VLOOKUP(A41,$H$9:$K$40,4,0),0) -> 0
A42: DEP-7162 | B42: 46112 | C42: Received from Nandini Foods | D42: 132500 | S42: =_xlfn.IFNA(VLOOKUP(A42,$H$9:$K$40,4,0),0) -> 0 | T42: =D42-_xlfn.IFNA(VLOOKUP(A42,$H$9:$K$40,4,0),0) -> 132500

Sheet L5 The reconciliation statement
A1: LESSON 5 · THE RECONCILIATION STATEMENT
A2: ★★★★☆ Walk from the cash book balance to the bank balance, one adjustment at a time.
A3: CONCEPT · A bank reconciliation statement is a bridge. Start at your cash book closing balance and apply four adjustments: add deposits in transit back out, add back unpresented cheques, post the bank's own entries, and correct the amount differences. If the bridge is right you land exactly on the bank statement balance — not near it, ON it. Build each line from the raw data, not from the row above, so one wrong step cannot poison the rest.
A6: Opening balance | B6: 842500
A8: Ref | B8: Date | C8: Particulars | D8: Amount | F8: Ref | G8: Date | H8: Particulars | I8: Amount | K8: # | L8: Task | M8: Your answer | N8: Check | O8: Hint
A9: DEP-7163 | B9: 46112 | C9: Received from ABC Traders | D9: 29800 | F9: DEP-7122 | G9: 46105 | H9: Deposit - Shree Enterprises | I9: 25000 | K9: 1 | L9: Line 1 — Balance as per cash book. | N9: =IF(ISBLANK(M9),"◯ Not attempted",IF(NOT(_xlfn.ISFORMULA(M9)),"✎ Use a formula",IF(ISNUMBER(M9),IF(ABS(M9-$P$9)<0.005,"✓ Correct","✗ Check again"),"✗ Not a number"))) -> ◯ Not attempted | O9: Opening balance + net movement, as in lesson 1. | P9: =$B$6+SUM($D$9:$D$42) -> 816050
A10: CHQ-4151 | B10: 46107 | C10: Cheque issued to Sagar Metals | D10: -96500 | F10: DEP-7110 | G10: 46108 | H10: Deposit - Nandini Foods | I10: 189000 | K10: 2 | L10: Line 2 — Less: deposits in transit (recorded by you, not yet credited by the bank). Enter as a NEGATIVE number. | N10: =IF(ISBLANK(M10),"◯ Not attempted",IF(NOT(_xlfn.ISFORMULA(M10)),"✎ Use a formula",IF(ISNUMBER(M10),IF(ABS(M10-$P$10)<0.005,"✓ Correct","✗ Check again"),"✗ Not a number"))) -> ◯ Not attempted | O10: Take the deposits-in-transit total from lesson 2 and put a minus sign in front. | P10: =-246300 -> -246300
A11: CHQ-4152 | B11: 46108 | C11: Cheque issued to Patel & Co | D11: -41200 | F11: DEP-7108 | G11: 46086 | H11: Deposit - Kiran Agencies | I11: 75500 | K11: 3 | L11: Line 3 — Add: cheques issued but not presented. Enter as a POSITIVE number. | N11: =IF(ISBLANK(M11),"◯ Not attempted",IF(NOT(_xlfn.ISFORMULA(M11)),"✎ Use a formula",IF(ISNUMBER(M11),IF(ABS(M11-$P$11)<0.005,"✓ Correct","✗ Check again"),"✗ Not a number"))) -> ◯ Not attempted | O11: The unpresented total is negative, so the minus sign makes it positive. | P11: =386850 -> 386850
A12: DEP-7114 | B12: 46095 | C12: Received from Patel & Co | D12: 225500 | F12: DEP-7114 | G12: 46097 | H12: Deposit - Patel & Co | I12: 225500 | K12: 4 | L12: Line 4 — Add: the bank's own entries not yet in your book (net — charges are negative, interest positive). | N12: =IF(ISBLANK(M12),"◯ Not attempted",IF(NOT(_xlfn.ISFORMULA(M12)),"✎ Use a formula",IF(ISNUMBER(M12),IF(ABS(M12-$P$12)<0.005,"✓ Correct","✗ Check again"),"✗ Not a number"))) -> ◯ Not attempted | O12: The bank-only total from lesson 3, signed. | P12: =33394 -> 33394
A13: CHQ-4154 | B13: 46111 | C13: Cheque issued to Kiran Agencies | D13: -23750 | F13: DEP-7112 | G13: 46087 | H13: Deposit - Bharat Electricals | I13: 97500 | K13: 5 | L13: Line 5 — Add: net amount differences (bank amount minus book amount on matched references). | N13: =IF(ISBLANK(M13),"◯ Not attempted",IF(NOT(_xlfn.ISFORMULA(M13)),"✎ Use a formula",IF(ISNUMBER(M13),IF(ABS(M13-$P$13)<0.005,"✓ Correct","✗ Check again"),"✗ Not a number"))) -> ◯ Not attempted | O13: SUMIF with a whole column as the criteria returns one matched amount per row — subtract the book amount and add it all up. | P13: =-4190 -> -4190
A14: DEP-7118 | B14: 46106 | C14: Received from Vaibhav Textiles | D14: 226500 | F14: CHQ-4105 | G14: 46099 | H14: Cheque paid - Shree Enterprises | I14: -155500 | K14: 6 | L14: Line 6 — Reconciled balance: add lines 1 to 5. | N14: =IF(ISBLANK(M14),"◯ Not attempted",IF(NOT(_xlfn.ISFORMULA(M14)),"✎ Use a formula",IF(ISNUMBER(M14),IF(ABS(M14-$P$14)<0.005,"✓ Correct","✗ Check again"),"✗ Not a number"))) -> ◯ Not attempted | O14: =SUM(M9:M13) | P14: =985804 -> 985804
A15: DEP-7110 | B15: 46105 | C15: Received from Nandini Foods | D15: 189000 | F15: DEP-7102 | G15: 46106 | H15: Deposit - Nova Industries | I15: 90500 | K15: 7 | L15: Line 7 — Proof: your reconciled balance minus the bank statement closing balance. It must be exactly 0. | N15: =IF(ISBLANK(M15),"◯ Not attempted",IF(NOT(_xlfn.ISFORMULA(M15)),"✎ Use a formula",IF(ISNUMBER(M15),IF(ABS(M15-$P$15)<0.5,"✓ Correct","✗ Check again"),"✗ Not a number"))) -> ◯ Not attempted | O15: Line 6 minus (opening balance + SUM of the bank Amount column). | P15: =0 -> 0
A16: CHQ-4105 | B16: 46099 | C16: Cheque issued to Shree Enterprises | D16: -155500 | F16: BNK-004 | G16: 46103 | H16: NEFT direct credit - Zenith Software | I16: 68000
A17: CHQ-4119 | B17: 46091 | C17: Cheque issued to Shree Enterprises | D17: -162500 | F17: DEP-7142 | G17: 46101 | H17: Deposit - Orbit Systems | I17: 117410
A18: DEP-7124 | B18: 46099 | C18: Received from Sagar Metals | D18: 146000 | F18: CHQ-4119 | G18: 46091 | H18: Cheque paid - Shree Enterprises | I18: -162500
A19: DEP-7102 | B19: 46104 | C19: Received from Nova Industries | D19: 90500 | F19: BNK-001 | G19: 46112 | H19: Bank charges - quarterly | I19: -1180
A20: DEP-7112 | B20: 46087 | C20: Received from Bharat Electricals | D20: 97500 | F20: CHQ-4109 | G20: 46097 | H20: Cheque paid - Bharat Electricals | I20: -199000
A21: DEP-7120 | B21: 46094 | C21: Received from Bharat Electricals | D21: 88000 | F21: DEP-7120 | G21: 46098 | H21: Deposit - Bharat Electricals | I21: 88000
A22: CHQ-4155 | B22: 46112 | C22: Cheque issued to Meera Pharma | D22: -67400 | F22: CHQ-4111 | G22: 46092 | H22: Cheque paid - Deccan Supplies | I22: -80500
A23: CHQ-4123 | B23: 46090 | C23: Cheque issued to Nova Industries | D23: -90500 | F23: DEP-7124 | G23: 46102 | H23: Deposit - Sagar Metals | I23: 146000
A24: DEP-7122 | B24: 46102 | C24: Received from Shree Enterprises | D24: 25000 | F24: BNK-006 | G24: 46101 | H24: Cheque returned - insufficient funds | I24: -25000
A25: CHQ-4107 | B25: 46085 | C25: Cheque issued to Nandini Foods | D25: -67500 | F25: DEP-7104 | G25: 46098 | H25: Deposit - Vaibhav Textiles | I25: 19000
A26: CHQ-4121 | B26: 46085 | C26: Cheque issued to Bharat Electricals | D26: -149500 | F26: CHQ-4131 | G26: 46092 | H26: Cheque paid - Meera Pharma | I26: -49500
A27: CHQ-4115 | B27: 46082 | C27: Cheque issued to Sagar Metals | D27: -75000 | F27: BNK-005 | G27: 46096 | H27: ECS debit - insurance premium | I27: -12500
... A40: CHQ-4117 | B40: 46102 | C40: Cheque issued to Nandini Foods | D40: -233000 | F40: DEP-7106 | G40: 46095 | H40: Deposit - Bharat Electricals | I40: 195000
A41: DEP-7108 | B41: 46086 | C41: Received from Kiran Agencies | D41: 75500
A42: DEP-7162 | B42: 46112 | C42: Received from Nandini Foods | D42: 132500

Sheet L6 Boss round — automatic recon
A1: LESSON 6 · BOSS ROUND — AUTOMATIC RECONCILIATION
A2: ★★★★★ One formula that classifies every line. This is the version you actually use at work.
A3: CONCEPT · Three outcomes in one nested test: not on the statement at all, on it with a different amount, or a clean match. IFS reads top to bottom and stops at the first TRUE, so order the tests from most specific to most general. SUMIF(bankRefs, thisRef, bankAmounts) fetches the bank amount without any error handling — a missing reference simply sums to zero.
A6: Opening balance | B6: 842500
A8: Ref | B8: Date | C8: Particulars | D8: Amount | E8: Status | G8: Ref | H8: Date | I8: Particulars | J8: Amount | L8: # | M8: Task | N8: Your answer | O8: Check | P8: Hint
A9: DEP-7163 | B9: 46112 | C9: Received from ABC Traders | D9: 29800 | G9: DEP-7122 | H9: 46105 | I9: Deposit - Shree Enterprises | J9: 25000 | L9: 1 | M9: Fill Status: "Not in bank" if the reference is absent, "Amount differs" if it is present with a different amount, otherwise "Matched". | N9: → fill column E | O9: =IF(COUNTA($E$9:$E$42)=0,"◯ Not attempted",IF(NOT(_xlfn.ISFORMULA(E9)),"✎ Use a formula",IFERROR(IF(SUMPRODUCT(--(UPPER(TRIM($E$9:$E$42&""))=UPPER(TRIM($R$9:$R$42&""))))=ROWS($E$9:$E$42),"✓ Correct","✗ "&(ROWS($E$9:$E$42)-SUMPRODUCT(--(UPPER(TRIM($E$9:$E$42&""))=UPPER(TRIM($R$9:$R$42&"")))))&" rows differ"),"✗ Check the column"))) -> ◯ Not attempted | P9: IFS(test1,result1,test2,result2,TRUE,fallback). Test "missing" first — you cannot compare an amount that is not there. | R9: =_xlfn.IFS(COUNTIF($G$9:$G$40,A9)=0,"Not in bank",ABS(D9-SUMIF($G$9:$G$40,A9,$J$9:$J$40))>0.5,"Amount differs",TRUE(),"Matched") -> Not in bank
A10: CHQ-4151 | B10: 46107 | C10: Cheque issued to Sagar Metals | D10: -96500 | G10: DEP-7110 | H10: 46108 | I10: Deposit - Nandini Foods | J10: 189000 | L10: 2 | M10: How many lines are "Amount differs"? | O10: =IF(ISBLANK(N10),"◯ Not attempted",IF(NOT(_xlfn.ISFORMULA(N10)),"✎ Use a formula",IF(ISNUMBER(N10),IF(ABS(N10-$Q$10)<0.005,"✓ Correct","✗ Check again"),"✗ Not a number"))) -> ◯ Not attempted | P10: COUNTIF on your Status column. | Q10: =2 -> 2 | R10: =_xlfn.IFS(COUNTIF($G$9:$G$40,A10)=0,"Not in bank",ABS(D10-SUMIF($G$9:$G$40,A10,$J$9:$J$40))>0.5,"Amount differs",TRUE(),"Matched") -> Not in bank
A11: CHQ-4152 | B11: 46108 | C11: Cheque issued to Patel & Co | D11: -41200 | G11: DEP-7108 | H11: 46086 | I11: Deposit - Kiran Agencies | J11: 75500 | L11: 3 | M11: Net value of every line that is "Not in bank". | O11: =IF(ISBLANK(N11),"◯ Not attempted",IF(NOT(_xlfn.ISFORMULA(N11)),"✎ Use a formula",IF(ISNUMBER(N11),IF(ABS(N11-$Q$11)<0.005,"✓ Correct","✗ Check again"),"✗ Not a number"))) -> ◯ Not attempted | P11: SUMIF on the label. | Q11: =-140550 -> -140550 | R11: =_xlfn.IFS(COUNTIF($G$9:$G$40,A11)=0,"Not in bank",ABS(D11-SUMIF($G$9:$G$40,A11,$J$9:$J$40))>0.5,"Amount differs",TRUE(),"Matched") -> Not in bank
A12: DEP-7114 | B12: 46095 | C12: Received from Patel & Co | D12: 225500 | G12: DEP-7114 | H12: 46097 | I12: Deposit - Patel & Co | J12: 225500 | L12: 4 | M12: The reference of the largest unpresented cheque (the most negative "Not in bank" line). | O12: =IF(ISBLANK(N12),"◯ Not attempted",IF(NOT(_xlfn.ISFORMULA(N12)),"✎ Use a formula",IF(UPPER(TRIM(N12&""))=UPPER(TRIM($Q$12&"")),"✓ Correct","✗ Check again"))) -> ◯ Not attempted | P12: MINIFS, then MATCH, then INDEX. | Q12: ="CHQ-4153" -> CHQ-4153 | R12: =_xlfn.IFS(COUNTIF($G$9:$G$40,A12)=0,"Not in bank",ABS(D12-SUMIF($G$9:$G$40,A12,$J$9:$J$40))>0.5,"Amount differs",TRUE(),"Matched") -> Matched
A13: CHQ-4154 | B13: 46111 | C13: Cheque issued to Kiran Agencies | D13: -23750 | G13: DEP-7112 | H13: 46087 | I13: Deposit - Bharat Electricals | J13: 97500 | L13: 5 | M13: Final proof: cash book closing + unmatched reversal + bank-only entries + amount differences − bank closing. Must be 0. | O13: =IF(ISBLANK(N13),"◯ Not attempted",IF(NOT(_xlfn.ISFORMULA(N13)),"✎ Use a formula",IF(ISNUMBER(N13),IF(ABS(N13-$Q$13)<0.5,"✓ Correct","✗ Check again"),"✗ Not a number"))) -> ◯ Not attempted | P13: Every piece is something you have already built. Chain them in one cell and watch it collapse to zero. | Q13: =0 -> 0 | R13: =_xlfn.IFS(COUNTIF($G$9:$G$40,A13)=0,"Not in bank",ABS(D13-SUMIF($G$9:$G$40,A13,$J$9:$J$40))>0.5,"Amount differs",TRUE(),"Matched") -> Not in bank
A14: DEP-7118 | B14: 46106 | C14: Received from Vaibhav Textiles | D14: 226500 | G14: CHQ-4105 | H14: 46099 | I14: Cheque paid - Shree Enterprises | J14: -155500 | R14: =_xlfn.IFS(COUNTIF($G$9:$G$40,A14)=0,"Not in bank",ABS(D14-SUMIF($G$9:$G$40,A14,$J$9:$J$40))>0.5,"Amount differs",TRUE(),"Matched") -> Matched
A15: DEP-7110 | B15: 46105 | C15: Received from Nandini Foods | D15: 189000 | G15: DEP-7102 | H15: 46106 | I15: Deposit - Nova Industries | J15: 90500 | R15: =_xlfn.IFS(COUNTIF($G$9:$G$40,A15)=0,"Not in bank",ABS(D15-SUMIF($G$9:$G$40,A15,$J$9:$J$40))>0.5,"Amount differs",TRUE(),"Matched") -> Matched
A16: CHQ-4105 | B16: 46099 | C16: Cheque issued to Shree Enterprises | D16: -155500 | G16: BNK-004 | H16: 46103 | I16: NEFT direct credit - Zenith Software | J16: 68000 | R16: =_xlfn.IFS(COUNTIF($G$9:$G$40,A16)=0,"Not in bank",ABS(D16-SUMIF($G$9:$G$40,A16,$J$9:$J$40))>0.5,"Amount differs",TRUE(),"Matched") -> Matched
A17: CHQ-4119 | B17: 46091 | C17: Cheque issued to Shree Enterprises | D17: -162500 | G17: DEP-7142 | H17: 46101 | I17: Deposit - Orbit Systems | J17: 117410 | R17: =_xlfn.IFS(COUNTIF($G$9:$G$40,A17)=0,"Not in bank",ABS(D17-SUMIF($G$9:$G$40,A17,$J$9:$J$40))>0.5,"Amount differs",TRUE(),"Matched") -> Matched
A18: DEP-7124 | B18: 46099 | C18: Received from Sagar Metals | D18: 146000 | G18: CHQ-4119 | H18: 46091 | I18: Cheque paid - Shree Enterprises | J18: -162500 | R18: =_xlfn.IFS(COUNTIF($G$9:$G$40,A18)=0,"Not in bank",ABS(D18-SUMIF($G$9:$G$40,A18,$J$9:$J$40))>0.5,"Amount differs",TRUE(),"Matched") -> Matched
A19: DEP-7102 | B19: 46104 | C19: Received from Nova Industries | D19: 90500 | G19: BNK-001 | H19: 46112 | I19: Bank charges - quarterly | J19: -1180 | R19: =_xlfn.IFS(COUNTIF($G$9:$G$40,A19)=0,"Not in bank",ABS(D19-SUMIF($G$9:$G$40,A19,$J$9:$J$40))>0.5,"Amount differs",TRUE(),"Matched") -> Matched
A20: DEP-7112 | B20: 46087 | C20: Received from Bharat Electricals | D20: 97500 | G20: CHQ-4109 | H20: 46097 | I20: Cheque paid - Bharat Electricals | J20: -199000 | R20: =_xlfn.IFS(COUNTIF($G$9:$G$40,A20)=0,"Not in bank",ABS(D20-SUMIF($G$9:$G$40,A20,$J$9:$J$40))>0.5,"Amount differs",TRUE(),"Matched") -> Matched
A21: DEP-7120 | B21: 46094 | C21: Received from Bharat Electricals | D21: 88000 | G21: DEP-7120 | H21: 46098 | I21: Deposit - Bharat Electricals | J21: 88000 | R21: =_xlfn.IFS(COUNTIF($G$9:$G$40,A21)=0,"Not in bank",ABS(D21-SUMIF($G$9:$G$40,A21,$J$9:$J$40))>0.5,"Amount differs",TRUE(),"Matched") -> Matched
A22: CHQ-4155 | B22: 46112 | C22: Cheque issued to Meera Pharma | D22: -67400 | G22: CHQ-4111 | H22: 46092 | I22: Cheque paid - Deccan Supplies | J22: -80500 | R22: =_xlfn.IFS(COUNTIF($G$9:$G$40,A22)=0,"Not in bank",ABS(D22-SUMIF($G$9:$G$40,A22,$J$9:$J$40))>0.5,"Amount differs",TRUE(),"Matched") -> Not in bank
A23: CHQ-4123 | B23: 46090 | C23: Cheque issued to Nova Industries | D23: -90500 | G23: DEP-7124 | H23: 46102 | I23: Deposit - Sagar Metals | J23: 146000 | R23: =_xlfn.IFS(COUNTIF($G$9:$G$40,A23)=0,"Not in bank",ABS(D23-SUMIF($G$9:$G$40,A23,$J$9:$J$40))>0.5,"Amount differs",TRUE(),"Matched") -> Matched
A24: DEP-7122 | B24: 46102 | C24: Received from Shree Enterprises | D24: 25000 | G24: BNK-006 | H24: 46101 | I24: Cheque returned - insufficient funds | J24: -25000 | R24: =_xlfn.IFS(COUNTIF($G$9:$G$40,A24)=0,"Not in bank",ABS(D24-SUMIF($G$9:$G$40,A24,$J$9:$J$40))>0.5,"Amount differs",TRUE(),"Matched") -> Matched
A25: CHQ-4107 | B25: 46085 | C25: Cheque issued to Nandini Foods | D25: -67500 | G25: DEP-7104 | H25: 46098 | I25: Deposit - Vaibhav Textiles | J25: 19000 | R25: =_xlfn.IFS(COUNTIF($G$9:$G$40,A25)=0,"Not in bank",ABS(D25-SUMIF($G$9:$G$40,A25,$J$9:$J$40))>0.5,"Amount differs",TRUE(),"Matched") -> Matched
... A40: CHQ-4117 | B40: 46102 | C40: Cheque issued to Nandini Foods | D40: -233000 | G40: DEP-7106 | H40: 46095 | I40: Deposit - Bharat Electricals | J40: 195000 | R40: =_xlfn.IFS(COUNTIF($G$9:$G$40,A40)=0,"Not in bank",ABS(D40-SUMIF($G$9:$G$40,A40,$J$9:$J$40))>0.5,"Amount differs",TRUE(),"Matched") -> Matched
A41: DEP-7108 | B41: 46086 | C41: Received from Kiran Agencies | D41: 75500 | R41: =_xlfn.IFS(COUNTIF($G$9:$G$40,A41)=0,"Not in bank",ABS(D41-SUMIF($G$9:$G$40,A41,$J$9:$J$40))>0.5,"Amount differs",TRUE(),"Matched") -> Matched
A42: DEP-7162 | B42: 46112 | C42: Received from Nandini Foods | D42: 132500 | R42: =_xlfn.IFS(COUNTIF($G$9:$G$40,A42)=0,"Not in bank",ABS(D42-SUMIF($G$9:$G$40,A42,$J$9:$J$40))>0.5,"Amount differs",TRUE(),"Matched") -> Not in bank

Sheet Solutions
A1: SOLUTIONS & OTHER WAYS — open only after you have tried
A2: Model answers are shapes, not the only answer. If your formula gives the same result, it is right — compare the logic.
A4: L1 Two books, two balances ★★
A5: # | B5: Task | C5: Answer cell | D5: Model formula | E5: Other ways | F5: Why it works
A6: 1 | B6: Net movement as per the cash book (SUM the cash book Amount column). | C6: M9 | D6: =SUM($D$9:$D$42) | E6: =SUMPRODUCT(D9:D44) | F6: Because payments are already negative, one SUM gives receipts minus payments.
A7: 2 | B7: Closing balance as per the cash book = opening balance (B6) + net movement. | C7: M10 | D7: =$B$6+SUM($D$9:$D$42) | F7: The opening balance is an input — change it and every answer below must move.
A8: 3 | B8: Net movement as per the bank statement. | C8: M11 | D8: =SUM($I$9:$I$40)
A9: 4 | B9: Closing balance as per the bank statement. | C9: M12 | D9: =$B$6+SUM($I$9:$I$40)
A10: 5 | B10: The difference: bank closing balance minus cash book closing balance. | C10: M13 | D10: =SUM($I$9:$I$40)-SUM($D$9:$D$42) | F10: This is the number the whole reconciliation has to explain, rupee for rupee.
A11: 6 | B11: How many entries are in the cash book? | C11: M14 | D11: =COUNTA($A$9:$A$42) | E11: =ROWS(A9:A44)
A12: 7 | B12: How many entries are on the bank statement? | C12: M15 | D12: =COUNTA($F$9:$F$40)
A14: L2 Match by reference ★★★
A15: # | B15: Task | C15: Answer cell | D15: Model formula | E15: Other ways | F15: Why it works
A16: 1 | B16: Fill "In bank?": "Yes" if the reference appears on the bank statement, otherwise "No". | C16: column E | D16: =IF(COUNTIF($G$9:$G$40,A9)>0,"Yes","No") (row 9, then fill down) | E16: =IF(ISNA(MATCH(A9,bankRefs,0)),"No","Yes") =IF(COUNTIF(bankRefs,A9),"Yes","No") — a non-zero count is already TRUE | F16: COUNTIF is the safest matcher: it never throws #N/A, it just returns 0.
A17: 2 | B17: How many cash book entries have NOT reached the bank? | C17: N10 | D17: =COUNTIF($E$9:$E$42,"No") | E17: =SUMPRODUCT(--(COUNTIF(bankRefs,cbRefs)=0)) — no helper column at all
A18: 3 | B18: Net value of those unmatched entries. | C18: N11 | D18: =SUMIF($E$9:$E$42,"No",$D$9:$D$42)
A19: 4 | B19: Total of cheques issued but not yet presented (unmatched entries with a negative amount). | C19: N12 | D19: =SUMIFS($D$9:$D$42,$E$9:$E$42,"No",$D$9:$D$42,"<0") | E19: =SUMPRODUCT((COUNTIF(bankRefs,cbRefs)=0)*(amt<0)*amt) | F19: These are cheques you have written that the payee has not banked yet.
A20: 5 | B20: Total of deposits in transit (unmatched entries with a positive amount). | C20: N13 | D20: =SUMIFS($D$9:$D$42,$E$9:$E$42,"No",$D$9:$D$42,">0") | F20: Money you have received and recorded, but the bank has not credited yet.
A21: 6 | B21: Check: unpresented cheques + deposits in transit must equal the net value of unmatched entries. | C21: N14 | D21: =SUMIFS($D$9:$D$42,$E$9:$E$42,"No",$D$9:$D$42,"<0")+SUMIFS($D$9:$D$42,$E$9:$E$42,"No",$D$9:$D$42,">0")-SUMIF($E$9:$E$42,"No",$D$9:$D$42) | F21: Splitting a total two ways and adding it back is the cheapest audit you will ever run.
A23: L3 The bank's own entries ★★★
A24: # | B24: Task | C24: Answer cell | D24: Model formula | E24: Other ways | F24: Why it works
A25: 1 | B25: Fill "In cash book?" on the bank statement: "Yes" or "No". | C25: column J | D25: =IF(COUNTIF($A$9:$A$42,F9)>0,"Yes","No") (row 9, then fill down)
A26: 2 | B26: How many bank entries are missing from your cash book? | C26: N10 | D26: =COUNTIF($J$9:$J$40,"No")
A27: 3 | B27: Net value of those bank-only entries. | C27: N11 | D27: =SUMIF($J$9:$J$40,"No",$I$9:$I$40) | F27: Post these into the cash book and your book balance changes — the bank's does not.
A28: 4 | B28: Total of bank-only DEBITS (charges, ECS, returned cheque — the negative ones). | C28: N12 | D28: =SUMIFS($I$9:$I$40,$J$9:$J$40,"No",$I$9:$I$40,"<0")
A29: 5 | B29: Total of bank-only CREDITS (interest and direct receipts). | C29: N13 | D29: =SUMIFS($I$9:$I$40,$J$9:$J$40,"No",$I$9:$I$40,">0")
A30: 6 | B30: Which bank-only entry is the largest debit? Return its Particulars. | C30: N14 | D30: =INDEX($H$9:$H$40,MATCH(MINIFS($I$9:$I$40,$J$9:$J$40,"No"),$I$9:$I$40,0)) | E30: =INDEX(Particulars,MATCH(MIN(IF(flag="No",Amount)),Amount,0)) entered with Ctrl+Shift+Enter
A32: L4 Amounts that don't agree ★★★★
A33: # | B33: Task | C33: Answer cell | D33: Model formula | E33: Other ways | F33: Why it works
A34: 1 | B34: Fill Bank amount: the amount the bank shows for this reference, or 0 if the bank has no such entry. | C34: column E | D34: =IFNA(VLOOKUP(A9,$H$9:$K$40,4,0),0) (row 9, then fill down) | E34: =IFERROR(VLOOKUP(A9,bankTable,4,0),0) =SUMIF(bankRefs,A9,bankAmts) — returns 0 when nothing matches, no error handling needed =IFNA(XLOOKUP(A9,bankRefs,bankAmts),0) | F34: SUMIF as a lookup is a favourite trick: unique keys make the sum equal the value, and a miss is simply 0.
A35: 2 | B35: Fill Difference = cash book Amount minus Bank amount. | C35: column F | D35: =D9-E9 (row 9, then fill down)
A36: 3 | B36: How many references are on BOTH sides but with different amounts? | C36: O11 | D36: =SUMPRODUCT(($E$9:$E$42<>0)*(ABS($F$9:$F$42)>0.5)) | E36: =SUMPRODUCT((COUNTIF(bankRefs,cbRefs)>0)*(ABS(cbAmt-SUMIF(bankRefs,cbRefs,bankAmts))>0.5)) — no helper columns | F36: A reference that exists on both sides is not a timing difference; somebody keyed a wrong number.
A37: 4 | B37: Net effect of those amount differences (bank minus book, for matched references only). | C37: O12 | D37: =-SUMIFS($F$9:$F$42,$E$9:$E$42,"<>0") | E37: =SUMPRODUCT((COUNTIF(bankRefs,cbRefs)>0)*(SUMIF(bankRefs,cbRefs,bankAmts)-cbAmt))
A38: 5 | B38: Total of the cash book entries that matched the bank EXACTLY. | C38: O13 | D38: =SUMIFS($D$9:$D$42,$E$9:$E$42,"<>0",$F$9:$F$42,0)
A40: L5 The reconciliation statement ★★★★
A41: # | B41: Task | C41: Answer cell | D41: Model formula | E41: Other ways | F41: Why it works
A42: 1 | B42: Line 1 — Balance as per cash book. | C42: M9 | D42: =$B$6+SUM($D$9:$D$42)
A43: 2 | B43: Line 2 — Less: deposits in transit (recorded by you, not yet credited by the bank). Enter as a NEGATIVE number. | C43: M10 | D43: =-SUMPRODUCT((COUNTIF($F$9:$F$40,$A$9:$A$42)=0)*($D$9:$D$42>0)*$D$9:$D$42) | F43: The bank does not know about them yet, so remove them on the way to the bank's view.
A44: 3 | B44: Line 3 — Add: cheques issued but not presented. Enter as a POSITIVE number. | C44: M11 | D44: =-SUMPRODUCT((COUNTIF($F$9:$F$40,$A$9:$A$42)=0)*($D$9:$D$42<0)*$D$9:$D$42) | F44: You have already deducted them; the bank has not.
A45: 4 | B45: Line 4 — Add: the bank's own entries not yet in your book (net — charges are negative, interest positive). | C45: M12 | D45: =SUMPRODUCT((COUNTIF($A$9:$A$42,$F$9:$F$40)=0)*$I$9:$I$40)
...
