Workbook

Sheet Start Here
A1: EXCEL LAB · 08 SALES ANALYTICS
A2: A full year of orders turned into a dashboard: revenue by segment, a month-by-region matrix built with one formula, a rep scorecard, product contribution and Pareto, growth and running totals, and a nine-question KPI boss round.
A4: HOW TO USE THIS WORKBOOK
A5: 1 | B5: Work through the lessons in order — each one is harder than the last (★ to ★★★★★).
A6: 2 | B6: Read the Concept box at the top of each lesson, then look at the data.
A7: 3 | B7: Type a FORMULA in each yellow cell. The Check column marks it ✓ or ✗ instantly.
A8: 4 | B8: Blue cells are inputs. Change them and watch every answer update — that is how you know your formula is really right.
A9: 5 | B9: Stuck? Read the Hint. Still stuck? The Solutions sheet shows the model answer and other ways to do it.
A11: COLOUR CODE
B12: Yellow — your answer goes here (always a formula)
B13: Blue — an input you can change
B14: ✓ Correct — marked automatically
B15: ✗ Check again — the result does not match
B16: ✎ You typed a value — replace it with a formula
A18: # | B18: Lesson | C18: Difficulty | D18: Tasks | E18: Solved | F18: Progress
A19: 1 | B19: L1 Revenue and segments | C19: ★★☆☆☆ | D19: 7 | E19: =COUNTIF('L1 Revenue and segments'!L9:L15,"✓*") -> 0 | F19: =IFERROR(E19/D19,0) -> 0
A20: 2 | B20: L2 The month by region matrix | C20: ★★★☆☆ | D20: 6 | E20: =COUNTIF('L2 The month by region matrix'!M9:M14,"✓*") -> 0 | F20: =IFERROR(E20/D20,0) -> 0
A21: 3 | B21: L3 Ranking the sales team | C21: ★★★☆☆ | D21: 7 | E21: =COUNTIF('L3 Ranking the sales team'!L9:L15,"✓*") -> 0 | F21: =IFERROR(E21/D21,0) -> 0
A22: 4 | B22: L4 Contribution and the 80-20 r | C22: ★★★★☆ | D22: 7 | E22: =COUNTIF('L4 Contribution and the 80-20 r'!L9:L15,"✓*") -> 0 | F22: =IFERROR(E22/D22,0) -> 0
A23: 5 | B23: L5 Growth, running totals and i | C23: ★★★★☆ | D23: 8 | E23: =COUNTIF('L5 Growth, running totals and i'!J9:J16,"✓*") -> 0 | F23: =IFERROR(E23/D23,0) -> 0
A24: 6 | B24: L6 Boss round — the KPI panel | C24: ★★★★★ | D24: 9 | E24: =COUNTIF('L6 Boss round — the KPI panel'!L9:L17,"✓*") -> 0 | F24: =IFERROR(E24/D24,0) -> 0
B25: OVERALL | D25: =SUM(D19:D24) -> 44 | E25: =SUM(E19:E24) -> 0 | F25: =IFERROR(E25/D25,0) -> 0
A27: Excel Lab — created by Pranay · excel-lab-by-pranay.vercel.app · free for every student

Sheet L1 Revenue and segments
A1: LESSON 1 · REVENUE AND SEGMENTS
A2: ★★☆☆☆ 180 orders, no revenue column. Build it, then slice it five ways.
A3: CONCEPT · Analysis starts by creating the measure you actually care about. Revenue is Units × Price — one formula, filled down 180 rows. After that, SUMIF and COUNTIF answer every 'how much from…' and 'how many…' question you will be asked in a review meeting.
A8: Date | B8: Region | C8: Product | D8: Rep | E8: Units | F8: Price | G8: Revenue | I8: # | J8: Task | K8: Your answer | L8: Check | M8: Hint
A9: 45749 | B9: East | C9: Printer | D9: Aditya Verma | E9: 12 | F9: 9800 | I9: 1 | J9: Fill Revenue = Units × Price. | K9: → fill column G | L9: =IF(COUNTA($G$9:$G$188)=0,"◯ Not attempted",IF(NOT(_xlfn.ISFORMULA(G9)),"✎ Use a formula",IFERROR(IF(SUMPRODUCT(--(ABS($G$9:$G$188-$O$9:$O$188)<0.01))=ROWS($G$9:$G$188),"✓ Correct","✗ "&(ROWS($G$9:$G$188)-SUMPRODUCT(--(ABS($G$9:$G$188-$O$9:$O$188)<0.01)))&" rows differ"),"✗ Check the column"))) -> ◯ Not attempted | M9: =E9*F9, then double-click the fill handle to copy it all the way down. | O9: =E9*F9 -> 117600
A10: 45749 | B10: South | C10: Monitor | D10: Ananya Bose | E10: 21 | F10: 15200 | I10: 2 | J10: Total revenue for the year. | L10: =IF(ISBLANK(K10),"◯ Not attempted",IF(NOT(_xlfn.ISFORMULA(K10)),"✎ Use a formula",IF(ISNUMBER(K10),IF(ABS(K10-$N$10)<0.005,"✓ Correct","✗ Check again"),"✗ Not a number"))) -> ◯ Not attempted | M10: SUM your new column. | N10: =SUMPRODUCT($E$9:$E$188,$F$9:$F$188) -> 164874500 | O10: =E10*F10 -> 319200
A11: 45750 | B11: East | C11: Router | D11: Aditya Verma | E11: 8 | F11: 5700 | I11: 3 | J11: Total units sold. | L11: =IF(ISBLANK(K11),"◯ Not attempted",IF(NOT(_xlfn.ISFORMULA(K11)),"✎ Use a formula",IF(ISNUMBER(K11),IF(ABS(K11-$N$11)<0.005,"✓ Correct","✗ Check again"),"✗ Not a number"))) -> ◯ Not attempted | M11: SUM the Units column. | N11: =SUM($E$9:$E$188) -> 3450 | O11: =E11*F11 -> 45600
A12: 45751 | B12: South | C12: Monitor | D12: Rohit Nair | E12: 24 | F12: 15300 | I12: 4 | J12: Average order value. | L12: =IF(ISBLANK(K12),"◯ Not attempted",IF(NOT(_xlfn.ISFORMULA(K12)),"✎ Use a formula",IF(ISNUMBER(K12),IF(ABS(K12-$N$12)<0.05,"✓ Correct","✗ Check again"),"✗ Not a number"))) -> ◯ Not attempted | M12: AVERAGE over Revenue. | N12: =SUMPRODUCT($E$9:$E$188,$F$9:$F$188)/COUNTA($A$9:$A$188) -> 915969.44 | O12: =E12*F12 -> 367200
A13: 45752 | B13: Central | C13: Server | D13: Karan Mehta | E13: 16 | F13: 138700 | I13: 5 | J13: Revenue from the West region. | L13: =IF(ISBLANK(K13),"◯ Not attempted",IF(NOT(_xlfn.ISFORMULA(K13)),"✎ Use a formula",IF(ISNUMBER(K13),IF(ABS(K13-$N$13)<0.005,"✓ Correct","✗ Check again"),"✗ Not a number"))) -> ◯ Not attempted | M13: SUMIF: test range, criteria, sum range. | N13: =SUMPRODUCT(($B$9:$B$188="West")*$E$9:$E$188*$F$9:$F$188) -> 37229600 | O13: =E13*F13 -> 2219200
A14: 45753 | B14: South | C14: Printer | D14: Rohit Nair | E14: 38 | F14: 9000 | I14: 6 | J14: How many orders are worth more than ₹5,00,000? | L14: =IF(ISBLANK(K14),"◯ Not attempted",IF(NOT(_xlfn.ISFORMULA(K14)),"✎ Use a formula",IF(ISNUMBER(K14),IF(ABS(K14-$N$14)<0.005,"✓ Correct","✗ Check again"),"✗ Not a number"))) -> ◯ Not attempted | M14: COUNTIF(range,">500000"). | N14: =SUMPRODUCT(--($E$9:$E$188*$F$9:$F$188>500000)) -> 72 | O14: =E14*F14 -> 342000
A15: 45755 | B15: Central | C15: Printer | D15: Shreya Naik | E15: 8 | F15: 9800 | I15: 7 | J15: Revenue per unit across the whole file. | L15: =IF(ISBLANK(K15),"◯ Not attempted",IF(NOT(_xlfn.ISFORMULA(K15)),"✎ Use a formula",IF(ISNUMBER(K15),IF(ABS(K15-$N$15)<0.05,"✓ Correct","✗ Check again"),"✗ Not a number"))) -> ◯ Not attempted | M15: Total revenue ÷ total units. | N15: =47789.710145 -> 47789.71 | O15: =E15*F15 -> 78400
A16: 45759 | B16: East | C16: Monitor | D16: Shreya Naik | E16: 28 | F16: 13900 | O16: =E16*F16 -> 389200
A17: 45761 | B17: West | C17: Laptop | D17: Pooja Chopra | E17: 27 | F17: 58500 | O17: =E17*F17 -> 1579500
A18: 45764 | B18: East | C18: Tablet | D18: Karan Mehta | E18: 15 | F18: 26900 | O18: =E18*F18 -> 403500
A19: 45767 | B19: Central | C19: Server | D19: Divya Pillai | E19: 37 | F19: 160300 | O19: =E19*F19 -> 5931100
A20: 45769 | B20: Central | C20: Printer | D20: Karan Mehta | E20: 13 | F20: 10400 | O20: =E20*F20 -> 135200
A21: 45772 | B21: North | C21: Monitor | D21: Manish Reddy | E21: 21 | F21: 15700 | O21: =E21*F21 -> 329700
A22: 45773 | B22: East | C22: Monitor | D22: Aditya Verma | E22: 2 | F22: 15400 | O22: =E22*F22 -> 30800
A23: 45776 | B23: West | C23: Tablet | D23: Shreya Naik | E23: 11 | F23: 22700 | O23: =E23*F23 -> 249700
A24: 45782 | B24: Central | C24: Laptop | D24: Aditya Verma | E24: 21 | F24: 66900 | O24: =E24*F24 -> 1404900
A25: 45782 | B25: Central | C25: Printer | D25: Pooja Chopra | E25: 13 | F25: 10300 | O25: =E25*F25 -> 133900
A26: 45782 | B26: West | C26: Laptop | D26: Karan Mehta | E26: 29 | F26: 67400 | O26: =E26*F26 -> 1954600
A27: 45786 | B27: South | C27: Monitor | D27: Nikhil Shetty | E27: 24 | F27: 13400 | O27: =E27*F27 -> 321600
... A188: 46112 | B188: South | C188: Server | D188: Pooja Chopra | E188: 25 | F188: 161400 | O188: =E188*F188 -> 4035000

Sheet L2 The month by region matrix
A1: LESSON 2 · THE MONTH BY REGION MATRIX
A2: ★★★☆☆ Sixty cells, one formula. Lock the right half of each reference and you are done.
A3: CONCEPT · TEXT(date,"mmm-yy") collapses a date into a month label you can group on. In the grid below, the month labels run down the left and the regions run across the top. The formula in the top-left cell must point at the month with its COLUMN locked ($K12) and at the region with its ROW locked (L$11). Get those two dollar signs right and one fill handles all sixty cells.
A8: Date | B8: Region | C8: Product | D8: Rep | E8: Units | F8: Price | G8: Revenue | H8: Month | J8: # | K8: Task | L8: Your answer | M8: Check | N8: Hint
A9: 45749 | B9: East | C9: Printer | D9: Aditya Verma | E9: 12 | F9: 9800 | G9: 117600 | J9: 1 | K9: Fill Month as a label like "Jul-25". | L9: → fill column H | M9: =IF(COUNTA($H$9:$H$188)=0,"◯ Not attempted",IF(NOT(_xlfn.ISFORMULA(H9)),"✎ Use a formula",IFERROR(IF(SUMPRODUCT(--(UPPER(TRIM($H$9:$H$188&""))=UPPER(TRIM($R$9:$R$188&""))))=ROWS($H$9:$H$188),"✓ Correct","✗ "&(ROWS($H$9:$H$188)-SUMPRODUCT(--(UPPER(TRIM($H$9:$H$188&""))=UPPER(TRIM($R$9:$R$188&"")))))&" rows differ"),"✗ Check the column"))) -> ◯ Not attempted | N9: =TEXT(A9,"mmm-yy") | R9: =TEXT(A9,"mmm-yy") -> Apr-25
A10: 45749 | B10: South | C10: Monitor | D10: Ananya Bose | E10: 21 | F10: 15200 | G10: 319200 | J10: 2 | K10: Fill the whole grid: revenue for each month (rows) and region (columns). | L10: → fill the grid below | M10: =IF(COUNT($L$18:$P$29)=0,"◯ Not attempted",IF(NOT(_xlfn.ISFORMULA(L18)),"✎ Use a formula",IFERROR(IF(SUMPRODUCT(--(ABS($L$18:$P$29-$S$18:$W$29)<0.01))=60,"✓ Correct","✗ "&(60-SUMPRODUCT(--(ABS($L$18:$P$29-$S$18:$W$29)<0.01)))&" cells differ"),"✗ Check the grid"))) -> ◯ Not attempted | N10: =SUMIFS($G$9:$G$188,$H$9:$H$188,$K18,$B$9:$B$188,L$17) in the top-left cell, then fill right and down. | R10: =TEXT(A10,"mmm-yy") -> Apr-25
A11: 45750 | B11: East | C11: Router | D11: Aditya Verma | E11: 8 | F11: 5700 | G11: 45600 | J11: 3 | K11: Grand total of the grid. It must equal total revenue. | M11: =IF(ISBLANK(L11),"◯ Not attempted",IF(NOT(_xlfn.ISFORMULA(L11)),"✎ Use a formula",IF(ISNUMBER(L11),IF(ABS(L11-$Q$11)<0.005,"✓ Correct","✗ Check again"),"✗ Not a number"))) -> ◯ Not attempted | N11: SUM the whole grid. | Q11: =164874500 -> 164874500 | R11: =TEXT(A11,"mmm-yy") -> Apr-25
A12: 45751 | B12: South | C12: Monitor | D12: Rohit Nair | E12: 24 | F12: 15300 | G12: 367200 | J12: 4 | K12: The best single month in the West column of your grid. | M12: =IF(ISBLANK(L12),"◯ Not attempted",IF(NOT(_xlfn.ISFORMULA(L12)),"✎ Use a formula",IF(ISNUMBER(L12),IF(ABS(L12-$Q$12)<0.005,"✓ Correct","✗ Check again"),"✗ Not a number"))) -> ◯ Not attempted | N12: MAX down the West column of the grid. | Q12: =9140000 -> 9140000 | R12: =TEXT(A12,"mmm-yy") -> Apr-25
A13: 45752 | B13: Central | C13: Server | D13: Karan Mehta | E13: 16 | F13: 138700 | G13: 2219200 | J13: 5 | K13: Which month was that? Return the month label. | M13: =IF(ISBLANK(L13),"◯ Not attempted",IF(NOT(_xlfn.ISFORMULA(L13)),"✎ Use a formula",IF(UPPER(TRIM(L13&""))=UPPER(TRIM($Q$13&"")),"✓ Correct","✗ Check again"))) -> ◯ Not attempted | N13: MAX down the West column, MATCH to find its position, INDEX to read the month label beside it. | Q13: ="Aug-25" -> Aug-25 | R13: =TEXT(A13,"mmm-yy") -> Apr-25
A14: 45753 | B14: South | C14: Printer | D14: Rohit Nair | E14: 38 | F14: 9000 | G14: 342000 | J14: 6 | K14: How many of the 60 grid cells are above ₹20,00,000? | M14: =IF(ISBLANK(L14),"◯ Not attempted",IF(NOT(_xlfn.ISFORMULA(L14)),"✎ Use a formula",IF(ISNUMBER(L14),IF(ABS(L14-$Q$14)<0.005,"✓ Correct","✗ Check again"),"✗ Not a number"))) -> ◯ Not attempted | N14: COUNTIF works on a two-dimensional range just as happily as on a column. | Q14: =28 -> 28 | R14: =TEXT(A14,"mmm-yy") -> Apr-25
A15: 45755 | B15: Central | C15: Printer | D15: Shreya Naik | E15: 8 | F15: 9800 | G15: 78400 | R15: =TEXT(A15,"mmm-yy") -> Apr-25
A16: 45759 | B16: East | C16: Monitor | D16: Shreya Naik | E16: 28 | F16: 13900 | G16: 389200 | K16: Month × Region revenue — ONE formula, filled right and down | R16: =TEXT(A16,"mmm-yy") -> Apr-25
A17: 45761 | B17: West | C17: Laptop | D17: Pooja Chopra | E17: 27 | F17: 58500 | G17: 1579500 | L17: West | M17: North | N17: South | O17: East | P17: Central | R17: =TEXT(A17,"mmm-yy") -> Apr-25
A18: 45764 | B18: East | C18: Tablet | D18: Karan Mehta | E18: 15 | F18: 26900 | G18: 403500 | K18: Apr-25 | R18: =TEXT(A18,"mmm-yy") -> Apr-25 | S18: =SUMPRODUCT((TEXT($A$9:$A$188,"mmm-yy")=$K18)*($B$9:$B$188=L$17)*$G$9:$G$188) -> 1829200 | T18: =SUMPRODUCT((TEXT($A$9:$A$188,"mmm-yy")=$K18)*($B$9:$B$188=M$17)*$G$9:$G$188) -> 329700 | U18: =SUMPRODUCT((TEXT($A$9:$A$188,"mmm-yy")=$K18)*($B$9:$B$188=N$17)*$G$9:$G$188) -> 1028400 | V18: =SUMPRODUCT((TEXT($A$9:$A$188,"mmm-yy")=$K18)*($B$9:$B$188=O$17)*$G$9:$G$188) -> 986700 | W18: =SUMPRODUCT((TEXT($A$9:$A$188,"mmm-yy")=$K18)*($B$9:$B$188=P$17)*$G$9:$G$188) -> 8363900
A19: 45767 | B19: Central | C19: Server | D19: Divya Pillai | E19: 37 | F19: 160300 | G19: 5931100 | K19: May-25 | R19: =TEXT(A19,"mmm-yy") -> Apr-25 | S19: =SUMPRODUCT((TEXT($A$9:$A$188,"mmm-yy")=$K19)*($B$9:$B$188=L$17)*$G$9:$G$188) -> 2944400 | T19: =SUMPRODUCT((TEXT($A$9:$A$188,"mmm-yy")=$K19)*($B$9:$B$188=M$17)*$G$9:$G$188) -> 3346800 | U19: =SUMPRODUCT((TEXT($A$9:$A$188,"mmm-yy")=$K19)*($B$9:$B$188=N$17)*$G$9:$G$188) -> 3797000 | V19: =SUMPRODUCT((TEXT($A$9:$A$188,"mmm-yy")=$K19)*($B$9:$B$188=O$17)*$G$9:$G$188) -> 408000 | W19: =SUMPRODUCT((TEXT($A$9:$A$188,"mmm-yy")=$K19)*($B$9:$B$188=P$17)*$G$9:$G$188) -> 8049400
A20: 45769 | B20: Central | C20: Printer | D20: Karan Mehta | E20: 13 | F20: 10400 | G20: 135200 | K20: Jun-25 | R20: =TEXT(A20,"mmm-yy") -> Apr-25 | S20: =SUMPRODUCT((TEXT($A$9:$A$188,"mmm-yy")=$K20)*($B$9:$B$188=L$17)*$G$9:$G$188) -> 1840200 | T20: =SUMPRODUCT((TEXT($A$9:$A$188,"mmm-yy")=$K20)*($B$9:$B$188=M$17)*$G$9:$G$188) -> 2822300 | U20: =SUMPRODUCT((TEXT($A$9:$A$188,"mmm-yy")=$K20)*($B$9:$B$188=N$17)*$G$9:$G$188) -> 480700 | V20: =SUMPRODUCT((TEXT($A$9:$A$188,"mmm-yy")=$K20)*($B$9:$B$188=O$17)*$G$9:$G$188) -> 0 | W20: =SUMPRODUCT((TEXT($A$9:$A$188,"mmm-yy")=$K20)*($B$9:$B$188=P$17)*$G$9:$G$188) -> 3218400
A21: 45772 | B21: North | C21: Monitor | D21: Manish Reddy | E21: 21 | F21: 15700 | G21: 329700 | K21: Jul-25 | R21: =TEXT(A21,"mmm-yy") -> Apr-25 | S21: =SUMPRODUCT((TEXT($A$9:$A$188,"mmm-yy")=$K21)*($B$9:$B$188=L$17)*$G$9:$G$188) -> 9027200 | T21: =SUMPRODUCT((TEXT($A$9:$A$188,"mmm-yy")=$K21)*($B$9:$B$188=M$17)*$G$9:$G$188) -> 58400 | U21: =SUMPRODUCT((TEXT($A$9:$A$188,"mmm-yy")=$K21)*($B$9:$B$188=N$17)*$G$9:$G$188) -> 122400 | V21: =SUMPRODUCT((TEXT($A$9:$A$188,"mmm-yy")=$K21)*($B$9:$B$188=O$17)*$G$9:$G$188) -> 12891200 | W21: =SUMPRODUCT((TEXT($A$9:$A$188,"mmm-yy")=$K21)*($B$9:$B$188=P$17)*$G$9:$G$188) -> 4738200
A22: 45773 | B22: East | C22: Monitor | D22: Aditya Verma | E22: 2 | F22: 15400 | G22: 30800 | K22: Aug-25 | R22: =TEXT(A22,"mmm-yy") -> Apr-25 | S22: =SUMPRODUCT((TEXT($A$9:$A$188,"mmm-yy")=$K22)*($B$9:$B$188=L$17)*$G$9:$G$188) -> 9140000 | T22: =SUMPRODUCT((TEXT($A$9:$A$188,"mmm-yy")=$K22)*($B$9:$B$188=M$17)*$G$9:$G$188) -> 3971600 | U22: =SUMPRODUCT((TEXT($A$9:$A$188,"mmm-yy")=$K22)*($B$9:$B$188=N$17)*$G$9:$G$188) -> 11924900 | V22: =SUMPRODUCT((TEXT($A$9:$A$188,"mmm-yy")=$K22)*($B$9:$B$188=O$17)*$G$9:$G$188) -> 493200 | W22: =SUMPRODUCT((TEXT($A$9:$A$188,"mmm-yy")=$K22)*($B$9:$B$188=P$17)*$G$9:$G$188) -> 197600
A23: 45776 | B23: West | C23: Tablet | D23: Shreya Naik | E23: 11 | F23: 22700 | G23: 249700 | K23: Sep-25 | R23: =TEXT(A23,"mmm-yy") -> Apr-25 | S23: =SUMPRODUCT((TEXT($A$9:$A$188,"mmm-yy")=$K23)*($B$9:$B$188=L$17)*$G$9:$G$188) -> 2528100 | T23: =SUMPRODUCT((TEXT($A$9:$A$188,"mmm-yy")=$K23)*($B$9:$B$188=M$17)*$G$9:$G$188) -> 1468200 | U23: =SUMPRODUCT((TEXT($A$9:$A$188,"mmm-yy")=$K23)*($B$9:$B$188=N$17)*$G$9:$G$188) -> 5245500 | V23: =SUMPRODUCT((TEXT($A$9:$A$188,"mmm-yy")=$K23)*($B$9:$B$188=O$17)*$G$9:$G$188) -> 2335600 | W23: =SUMPRODUCT((TEXT($A$9:$A$188,"mmm-yy")=$K23)*($B$9:$B$188=P$17)*$G$9:$G$188) -> 2184300
A24: 45782 | B24: Central | C24: Laptop | D24: Aditya Verma | E24: 21 | F24: 66900 | G24: 1404900 | K24: Oct-25 | R24: =TEXT(A24,"mmm-yy") -> May-25 | S24: =SUMPRODUCT((TEXT($A$9:$A$188,"mmm-yy")=$K24)*($B$9:$B$188=L$17)*$G$9:$G$188) -> 0 | T24: =SUMPRODUCT((TEXT($A$9:$A$188,"mmm-yy")=$K24)*($B$9:$B$188=M$17)*$G$9:$G$188) -> 6067600 | U24: =SUMPRODUCT((TEXT($A$9:$A$188,"mmm-yy")=$K24)*($B$9:$B$188=N$17)*$G$9:$G$188) -> 543900 | V24: =SUMPRODUCT((TEXT($A$9:$A$188,"mmm-yy")=$K24)*($B$9:$B$188=O$17)*$G$9:$G$188) -> 328200 | W24: =SUMPRODUCT((TEXT($A$9:$A$188,"mmm-yy")=$K24)*($B$9:$B$188=P$17)*$G$9:$G$188) -> 5520900
A25: 45782 | B25: Central | C25: Printer | D25: Pooja Chopra | E25: 13 | F25: 10300 | G25: 133900 | K25: Nov-25 | R25: =TEXT(A25,"mmm-yy") -> May-25 | S25: =SUMPRODUCT((TEXT($A$9:$A$188,"mmm-yy")=$K25)*($B$9:$B$188=L$17)*$G$9:$G$188) -> 499500 | T25: =SUMPRODUCT((TEXT($A$9:$A$188,"mmm-yy")=$K25)*($B$9:$B$188=M$17)*$G$9:$G$188) -> 347700 | U25: =SUMPRODUCT((TEXT($A$9:$A$188,"mmm-yy")=$K25)*($B$9:$B$188=N$17)*$G$9:$G$188) -> 195600 | V25: =SUMPRODUCT((TEXT($A$9:$A$188,"mmm-yy")=$K25)*($B$9:$B$188=O$17)*$G$9:$G$188) -> 2805800 | W25: =SUMPRODUCT((TEXT($A$9:$A$188,"mmm-yy")=$K25)*($B$9:$B$188=P$17)*$G$9:$G$188) -> 0
A26: 45782 | B26: West | C26: Laptop | D26: Karan Mehta | E26: 29 | F26: 67400 | G26: 1954600 | K26: Dec-25 | R26: =TEXT(A26,"mmm-yy") -> May-25 | S26: =SUMPRODUCT((TEXT($A$9:$A$188,"mmm-yy")=$K26)*($B$9:$B$188=L$17)*$G$9:$G$188) -> 933000 | T26: =SUMPRODUCT((TEXT($A$9:$A$188,"mmm-yy")=$K26)*($B$9:$B$188=M$17)*$G$9:$G$188) -> 906000 | U26: =SUMPRODUCT((TEXT($A$9:$A$188,"mmm-yy")=$K26)*($B$9:$B$188=N$17)*$G$9:$G$188) -> 1176500 | V26: =SUMPRODUCT((TEXT($A$9:$A$188,"mmm-yy")=$K26)*($B$9:$B$188=O$17)*$G$9:$G$188) -> 3899300 | W26: =SUMPRODUCT((TEXT($A$9:$A$188,"mmm-yy")=$K26)*($B$9:$B$188=P$17)*$G$9:$G$188) -> 6279800
A27: 45786 | B27: South | C27: Monitor | D27: Nikhil Shetty | E27: 24 | F27: 13400 | G27: 321600 | K27: Jan-26 | R27: =TEXT(A27,"mmm-yy") -> May-25 | S27: =SUMPRODUCT((TEXT($A$9:$A$188,"mmm-yy")=$K27)*($B$9:$B$188=L$17)*$G$9:$G$188) -> 4358800 | T27: =SUMPRODUCT((TEXT($A$9:$A$188,"mmm-yy")=$K27)*($B$9:$B$188=M$17)*$G$9:$G$188) -> 846000 | U27: =SUMPRODUCT((TEXT($A$9:$A$188,"mmm-yy")=$K27)*($B$9:$B$188=N$17)*$G$9:$G$188) -> 4785000 | V27: =SUMPRODUCT((TEXT($A$9:$A$188,"mmm-yy")=$K27)*($B$9:$B$188=O$17)*$G$9:$G$188) -> 346300 | W27: =SUMPRODUCT((TEXT($A$9:$A$188,"mmm-yy")=$K27)*($B$9:$B$188=P$17)*$G$9:$G$188) -> 715900
A28: 45787 | B28: East | C28: Printer | D28: Karan Mehta | E28: 21 | F28: 9900 | G28: 207900 | K28: Feb-26 | R28: =TEXT(A28,"mmm-yy") -> May-25 | S28: =SUMPRODUCT((TEXT($A$9:$A$188,"mmm-yy")=$K28)*($B$9:$B$188=L$17)*$G$9:$G$188) -> 3999200 | T28: =SUMPRODUCT((TEXT($A$9:$A$188,"mmm-yy")=$K28)*($B$9:$B$188=M$17)*$G$9:$G$188) -> 1008800 | U28: =SUMPRODUCT((TEXT($A$9:$A$188,"mmm-yy")=$K28)*($B$9:$B$188=N$17)*$G$9:$G$188) -> 543400 | V28: =SUMPRODUCT((TEXT($A$9:$A$188,"mmm-yy")=$K28)*($B$9:$B$188=O$17)*$G$9:$G$188) -> 2502000 | W28: =SUMPRODUCT((TEXT($A$9:$A$188,"mmm-yy")=$K28)*($B$9:$B$188=P$17)*$G$9:$G$188) -> 4105100
A29: 45791 | B29: North | C29: Monitor | D29: Nikhil Shetty | E29: 21 | F29: 15200 | G29: 319200 | K29: Mar-26 | R29: =TEXT(A29,"mmm-yy") -> May-25 | S29: =SUMPRODUCT((TEXT($A$9:$A$188,"mmm-yy")=$K29)*($B$9:$B$188=L$17)*$G$9:$G$188) -> 130000 | T29: =SUMPRODUCT((TEXT($A$9:$A$188,"mmm-yy")=$K29)*($B$9:$B$188=M$17)*$G$9:$G$188) -> 386500 | U29: =SUMPRODUCT((TEXT($A$9:$A$188,"mmm-yy")=$K29)*($B$9:$B$188=N$17)*$G$9:$G$188) -> 5410800 | V29: =SUMPRODUCT((TEXT($A$9:$A$188,"mmm-yy")=$K29)*($B$9:$B$188=O$17)*$G$9:$G$188) -> 461400 | W29: =SUMPRODUCT((TEXT($A$9:$A$188,"mmm-yy")=$K29)*($B$9:$B$188=P$17)*$G$9:$G$188) -> 0
A30: 45794 | B30: East | C30: Printer | D30: Rohit Nair | E30: 17 | F30: 10200 | G30: 173400 | R30: =TEXT(A30,"mmm-yy") -> May-25
A31: 45797 | B31: Central | C31: Server | D31: Aditya Verma | E31: 8 | F31: 136000 | G31: 1088000 | R31: =TEXT(A31,"mmm-yy") -> May-25
A32: 45797 | B32: South | C32: Monitor | D32: Nikhil Shetty | E32: 37 | F32: 14000 | G32: 518000 | R32: =TEXT(A32,"mmm-yy") -> May-25
A33: 45798 | B33: Central | C33: Router | D33: Shreya Naik | E33: 19 | F33: 5000 | G33: 95000 | R33: =TEXT(A33,"mmm-yy") -> May-25
A34: 45798 | B34: South | C34: Server | D34: Ananya Bose | E34: 18 | F34: 164300 | G34: 2957400 | R34: =TEXT(A34,"mmm-yy") -> May-25
A35: 45800 | B35: East | C35: Printer | D35: Ananya Bose | E35: 3 | F35: 8900 | G35: 26700 | R35: =TEXT(A35,"mmm-yy") -> May-25
A36: 45800 | B36: Central | C36: Server | D36: Shreya Naik | E36: 38 | F36: 140200 | G36: 5327600 | R36: =TEXT(A36,"mmm-yy") -> May-25
A37: 45802 | B37: North | C37: Server | D37: Manish Reddy | E37: 18 | F37: 168200 | G37: 3027600 | R37: =TEXT(A37,"mmm-yy") -> May-25
A38: 45803 | B38: West | C38: Laptop | D38: Karan Mehta | E38: 14 | F38: 70700 | G38: 989800 | R38: =TEXT(A38,"mmm-yy") -> May-25
A39: 45810 | B39: North | C39: Laptop | D39: Rohit Nair | E39: 28 | F39: 62700 | G39: 1755600 | R39: =TEXT(A39,"mmm-yy") -> Jun-25
A40: 45813 | B40: North | C40: Tablet | D40: Rohit Nair | E40: 15 | F40: 25700 | G40: 385500 | R40: =TEXT(A40,"mmm-yy") -> Jun-25
A41: 45815 | B41: Central | C41: Laptop | D41: Divya Pillai | E41: 24 | F41: 68000 | G41: 1632000 | R41: =TEXT(A41,"mmm-yy") -> Jun-25
... A188: 46112 | B188: South | C188: Server | D188: Pooja Chopra | E188: 25 | F188: 161400 | G188: 4035000 | R188: =TEXT(A188,"mmm-yy") -> Mar-26

Sheet L3 Ranking the sales team
A1: LESSON 3 · RANKING THE SALES TEAM
A2: ★★★☆☆ Three different questions about the same ten people — revenue, volume and quality.
A3: CONCEPT · A scorecard needs three measures side by side: SUMIF for the money, COUNTIF for the activity, AVERAGEIF for the quality of each deal. All three take the same rep name from the left of the row, so lock the column of the name with $ and fill right — then fill down for all ten reps. LARGE(range, k) then pulls the k-th biggest value out of a column without sorting anything.
A8: Date | B8: Region | C8: Product | D8: Rep | E8: Units | F8: Price | G8: Revenue | I8: # | J8: Task | K8: Your answer | L8: Check | M8: Hint
A9: 45749 | B9: East | C9: Printer | D9: Aditya Verma | E9: 12 | F9: 9800 | G9: 117600 | I9: 1 | J9: Fill the scorecard: revenue, number of orders and average order value for each rep. | K9: → fill the grid below | L9: =IF(COUNT($K$19:$M$28)=0,"◯ Not attempted",IF(NOT(_xlfn.ISFORMULA(K19)),"✎ Use a formula",IFERROR(IF(SUMPRODUCT(--(ABS($K$19:$M$28-$O$19:$Q$28)<0.01))=30,"✓ Correct","✗ "&(30-SUMPRODUCT(--(ABS($K$19:$M$28-$O$19:$Q$28)<0.01)))&" cells differ"),"✗ Check the grid"))) -> ◯ Not attempted | M9: Revenue: =SUMIF($D$9:$D$188,$J19,$G$9:$G$188). Orders: COUNTIF. Avg order: AVERAGEIF.
A10: 45749 | B10: South | C10: Monitor | D10: Ananya Bose | E10: 21 | F10: 15200 | G10: 319200 | I10: 2 | J10: The top rep's revenue. | L10: =IF(ISBLANK(K10),"◯ Not attempted",IF(NOT(_xlfn.ISFORMULA(K10)),"✎ Use a formula",IF(ISNUMBER(K10),IF(ABS(K10-$N$10)<0.005,"✓ Correct","✗ Check again"),"✗ Not a number"))) -> ◯ Not attempted | M10: MAX on the Revenue column of the scorecard. | N10: =35708900 -> 35708900
A11: 45750 | B11: East | C11: Router | D11: Aditya Verma | E11: 8 | F11: 5700 | G11: 45600 | I11: 3 | J11: Which rep is that? | L11: =IF(ISBLANK(K11),"◯ Not attempted",IF(NOT(_xlfn.ISFORMULA(K11)),"✎ Use a formula",IF(UPPER(TRIM(K11&""))=UPPER(TRIM($N$11&"")),"✓ Correct","✗ Check again"))) -> ◯ Not attempted | M11: MAX, MATCH, INDEX on the scorecard. | N11: ="Divya Pillai" -> Divya Pillai
A12: 45751 | B12: South | C12: Monitor | D12: Rohit Nair | E12: 24 | F12: 15300 | G12: 367200 | I12: 4 | J12: Revenue of the SECOND best rep. | L12: =IF(ISBLANK(K12),"◯ Not attempted",IF(NOT(_xlfn.ISFORMULA(K12)),"✎ Use a formula",IF(ISNUMBER(K12),IF(ABS(K12-$N$12)<0.005,"✓ Correct","✗ Check again"),"✗ Not a number"))) -> ◯ Not attempted | M12: LARGE(range,2). MAX only ever gives you the first. | N12: =26820000 -> 26820000
A13: 45752 | B13: Central | C13: Server | D13: Karan Mehta | E13: 16 | F13: 138700 | G13: 2219200 | I13: 5 | J13: Combined revenue of the top 3 reps. | L13: =IF(ISBLANK(K13),"◯ Not attempted",IF(NOT(_xlfn.ISFORMULA(K13)),"✎ Use a formula",IF(ISNUMBER(K13),IF(ABS(K13-$N$13)<0.005,"✓ Correct","✗ Check again"),"✗ Not a number"))) -> ◯ Not attempted | M13: =SUM(LARGE(range,{1,2,3})) — the braces hold a list of ranks, so LARGE returns three values at once. | N13: =81287700 -> 81287700
A14: 45753 | B14: South | C14: Printer | D14: Rohit Nair | E14: 38 | F14: 9000 | G14: 342000 | I14: 6 | J14: What share of total revenue do the top 3 reps bring in? | L14: =IF(ISBLANK(K14),"◯ Not attempted",IF(NOT(_xlfn.ISFORMULA(K14)),"✎ Use a formula",IF(ISNUMBER(K14),IF(ABS(K14-$N$14)<0.0002,"✓ Correct","✗ Check again"),"✗ Not a number"))) -> ◯ Not attempted | M14: Top 3 ÷ total revenue. | N14: =0.493028 -> 0.493028
A15: 45755 | B15: Central | C15: Printer | D15: Shreya Naik | E15: 8 | F15: 9800 | G15: 78400 | I15: 7 | J15: How many reps are ABOVE the team's average revenue? | L15: =IF(ISBLANK(K15),"◯ Not attempted",IF(NOT(_xlfn.ISFORMULA(K15)),"✎ Use a formula",IF(ISNUMBER(K15),IF(ABS(K15-$N$15)<0.005,"✓ Correct","✗ Check again"),"✗ Not a number"))) -> ◯ Not attempted | M15: COUNTIF(range,">"&AVERAGE(range)) — the & glues the operator onto the calculated number. | N15: =4 -> 4
A16: 45759 | B16: East | C16: Monitor | D16: Shreya Naik | E16: 28 | F16: 13900 | G16: 389200
A17: 45761 | B17: West | C17: Laptop | D17: Pooja Chopra | E17: 27 | F17: 58500 | G17: 1579500 | J17: Sales rep scorecard
A18: 45764 | B18: East | C18: Tablet | D18: Karan Mehta | E18: 15 | F18: 26900 | G18: 403500 | K18: Revenue | L18: Orders | M18: Avg order
A19: 45767 | B19: Central | C19: Server | D19: Divya Pillai | E19: 37 | F19: 160300 | G19: 5931100 | J19: Rohit Nair | O19: =SUMIF($D$9:$D$188,$J19,$G$9:$G$188) -> 9685100 | P19: =COUNTIF($D$9:$D$188,$J19) -> 20 | Q19: =AVERAGEIF($D$9:$D$188,$J19,$G$9:$G$188) -> 484255
A20: 45769 | B20: Central | C20: Printer | D20: Karan Mehta | E20: 13 | F20: 10400 | G20: 135200 | J20: Ananya Bose | O20: =SUMIF($D$9:$D$188,$J20,$G$9:$G$188) -> 11474600 | P20: =COUNTIF($D$9:$D$188,$J20) -> 15 | Q20: =AVERAGEIF($D$9:$D$188,$J20,$G$9:$G$188) -> 764973.33
A21: 45772 | B21: North | C21: Monitor | D21: Manish Reddy | E21: 21 | F21: 15700 | G21: 329700 | J21: Karan Mehta | O21: =SUMIF($D$9:$D$188,$J21,$G$9:$G$188) -> 26820000 | P21: =COUNTIF($D$9:$D$188,$J21) -> 26 | Q21: =AVERAGEIF($D$9:$D$188,$J21,$G$9:$G$188) -> 1031538.5
A22: 45773 | B22: East | C22: Monitor | D22: Aditya Verma | E22: 2 | F22: 15400 | G22: 30800 | J22: Divya Pillai | O22: =SUMIF($D$9:$D$188,$J22,$G$9:$G$188) -> 35708900 | P22: =COUNTIF($D$9:$D$188,$J22) -> 22 | Q22: =AVERAGEIF($D$9:$D$188,$J22,$G$9:$G$188) -> 1623131.8
A23: 45776 | B23: West | C23: Tablet | D23: Shreya Naik | E23: 11 | F23: 22700 | G23: 249700 | J23: Nikhil Shetty | O23: =SUMIF($D$9:$D$188,$J23,$G$9:$G$188) -> 9396700 | P23: =COUNTIF($D$9:$D$188,$J23) -> 15 | Q23: =AVERAGEIF($D$9:$D$188,$J23,$G$9:$G$188) -> 626446.67
A24: 45782 | B24: Central | C24: Laptop | D24: Aditya Verma | E24: 21 | F24: 66900 | G24: 1404900 | J24: Meghna Ghosh | O24: =SUMIF($D$9:$D$188,$J24,$G$9:$G$188) -> 18758800 | P24: =COUNTIF($D$9:$D$188,$J24) -> 17 | Q24: =AVERAGEIF($D$9:$D$188,$J24,$G$9:$G$188) -> 1103458.8
A25: 45782 | B25: Central | C25: Printer | D25: Pooja Chopra | E25: 13 | F25: 10300 | G25: 133900 | J25: Aditya Verma | O25: =SUMIF($D$9:$D$188,$J25,$G$9:$G$188) -> 9993700 | P25: =COUNTIF($D$9:$D$188,$J25) -> 13 | Q25: =AVERAGEIF($D$9:$D$188,$J25,$G$9:$G$188) -> 768746.15
A26: 45782 | B26: West | C26: Laptop | D26: Karan Mehta | E26: 29 | F26: 67400 | G26: 1954600 | J26: Shreya Naik | O26: =SUMIF($D$9:$D$188,$J26,$G$9:$G$188) -> 15333400 | P26: =COUNTIF($D$9:$D$188,$J26) -> 19 | Q26: =AVERAGEIF($D$9:$D$188,$J26,$G$9:$G$188) -> 807021.05
A27: 45786 | B27: South | C27: Monitor | D27: Nikhil Shetty | E27: 24 | F27: 13400 | G27: 321600 | J27: Manish Reddy | O27: =SUMIF($D$9:$D$188,$J27,$G$9:$G$188) -> 11097500 | P27: =COUNTIF($D$9:$D$188,$J27) -> 14 | Q27: =AVERAGEIF($D$9:$D$188,$J27,$G$9:$G$188) -> 792678.57
A28: 45787 | B28: East | C28: Printer | D28: Karan Mehta | E28: 21 | F28: 9900 | G28: 207900 | J28: Pooja Chopra | O28: =SUMIF($D$9:$D$188,$J28,$G$9:$G$188) -> 16605800 | P28: =COUNTIF($D$9:$D$188,$J28) -> 19 | Q28: =AVERAGEIF($D$9:$D$188,$J28,$G$9:$G$188) -> 873989.47
A29: 45791 | B29: North | C29: Monitor | D29: Nikhil Shetty | E29: 21 | F29: 15200 | G29: 319200
A30: 45794 | B30: East | C30: Printer | D30: Rohit Nair | E30: 17 | F30: 10200 | G30: 173400
A31: 45797 | B31: Central | C31: Server | D31: Aditya Verma | E31: 8 | F31: 136000 | G31: 1088000
A32: 45797 | B32: South | C32: Monitor | D32: Nikhil Shetty | E32: 37 | F32: 14000 | G32: 518000
A33: 45798 | B33: Central | C33: Router | D33: Shreya Naik | E33: 19 | F33: 5000 | G33: 95000
A34: 45798 | B34: South | C34: Server | D34: Ananya Bose | E34: 18 | F34: 164300 | G34: 2957400
A35: 45800 | B35: East | C35: Printer | D35: Ananya Bose | E35: 3 | F35: 8900 | G35: 26700
A36: 45800 | B36: Central | C36: Server | D36: Shreya Naik | E36: 38 | F36: 140200 | G36: 5327600
A37: 45802 | B37: North | C37: Server | D37: Manish Reddy | E37: 18 | F37: 168200 | G37: 3027600
A38: 45803 | B38: West | C38: Laptop | D38: Karan Mehta | E38: 14 | F38: 70700 | G38: 989800
A39: 45810 | B39: North | C39: Laptop | D39: Rohit Nair | E39: 28 | F39: 62700 | G39: 1755600
A40: 45813 | B40: North | C40: Tablet | D40: Rohit Nair | E40: 15 | F40: 25700 | G40: 385500
... A188: 46112 | B188: South | C188: Server | D188: Pooja Chopra | E188: 25 | F188: 161400 | G188: 4035000

Sheet L4 Contribution and the 80-20 r
A1: LESSON 4 · CONTRIBUTION AND THE 80/20 RULE
A2: ★★★★☆ Which products actually pay the bills — and how few of them there are.
A3: CONCEPT · A contribution table is a total and a percentage of the grand total side by side. The percentage needs the grand total LOCKED with $ or every row will divide by a different range. Sort the shares descending and add them up: in most businesses a handful of products cross 80% long before you run out of rows. That is the Pareto principle, and it is a number, not a slogan.
A8: Date | B8: Region | C8: Product | D8: Rep | E8: Units | F8: Price | G8: Revenue | I8: # | J8: Task | K8: Your answer | L8: Check | M8: Hint
A9: 45749 | B9: East | C9: Printer | D9: Aditya Verma | E9: 12 | F9: 9800 | G9: 117600 | I9: 1 | J9: Fill the contribution table: revenue and share of total revenue for each product. | K9: → fill the grid below | L9: =IF(COUNT($K$19:$L$24)=0,"◯ Not attempted",IF(NOT(_xlfn.ISFORMULA(K19)),"✎ Use a formula",IFERROR(IF(SUMPRODUCT(--(ABS($K$19:$L$24-$O$19:$P$24)<0.01))=12,"✓ Correct","✗ "&(12-SUMPRODUCT(--(ABS($K$19:$L$24-$O$19:$P$24)<0.01)))&" cells differ"),"✗ Check the grid"))) -> ◯ Not attempted | M9: Revenue: =SUMIF($C$9:$C$188,$J19,$G$9:$G$188). Share: the same thing divided by SUM of the whole Revenue column, locked with $.
A10: 45749 | B10: South | C10: Monitor | D10: Ananya Bose | E10: 21 | F10: 15200 | G10: 319200 | I10: 2 | J10: Do the shares add up to 100%? Enter the total of the Share column. | L10: =IF(ISBLANK(K10),"◯ Not attempted",IF(NOT(_xlfn.ISFORMULA(K10)),"✎ Use a formula",IF(ISNUMBER(K10),IF(ABS(K10-$N$10)<0.0002,"✓ Correct","✗ Check again"),"✗ Not a number"))) -> ◯ Not attempted | M10: SUM the share column. It must be exactly 1 (100%). | N10: =1 -> 1
A11: 45750 | B11: East | C11: Router | D11: Aditya Verma | E11: 8 | F11: 5700 | G11: 45600 | I11: 3 | J11: Share of the single biggest product. | L11: =IF(ISBLANK(K11),"◯ Not attempted",IF(NOT(_xlfn.ISFORMULA(K11)),"✎ Use a formula",IF(ISNUMBER(K11),IF(ABS(K11-$N$11)<0.0002,"✓ Correct","✗ Check again"),"✗ Not a number"))) -> ◯ Not attempted | M11: MAX on the Share column. | N11: =0.580489 -> 0.580489
A12: 45751 | B12: South | C12: Monitor | D12: Rohit Nair | E12: 24 | F12: 15300 | G12: 367200 | I12: 4 | J12: Combined share of the top TWO products. | L12: =IF(ISBLANK(K12),"◯ Not attempted",IF(NOT(_xlfn.ISFORMULA(K12)),"✎ Use a formula",IF(ISNUMBER(K12),IF(ABS(K12-$N$12)<0.0002,"✓ Correct","✗ Check again"),"✗ Not a number"))) -> ◯ Not attempted | M12: =SUM(LARGE(shareRange,{1,2})) | N12: =0.809139 -> 0.809139
A13: 45752 | B13: Central | C13: Server | D13: Karan Mehta | E13: 16 | F13: 138700 | G13: 2219200 | I13: 5 | J13: How many products does it take, biggest first, to cross 80% of revenue? | L13: =IF(ISBLANK(K13),"◯ Not attempted",IF(NOT(_xlfn.ISFORMULA(K13)),"✎ Use a formula",IF(ISNUMBER(K13),IF(ABS(K13-$N$13)<0.005,"✓ Correct","✗ Check again"),"✗ Not a number"))) -> ◯ Not attempted | M13: Ask the same question six times: is the top 1 enough? the top 2? the top 3? SUM(LARGE(range,{1,2,3})) gives you each cumulative total in one go. | N13: =2 -> 2
A14: 45753 | B14: South | C14: Printer | D14: Rohit Nair | E14: 38 | F14: 9000 | G14: 342000 | I14: 6 | J14: Revenue of the smallest product line. | L14: =IF(ISBLANK(K14),"◯ Not attempted",IF(NOT(_xlfn.ISFORMULA(K14)),"✎ Use a formula",IF(ISNUMBER(K14),IF(ABS(K14-$N$14)<0.005,"✓ Correct","✗ Check again"),"✗ Not a number"))) -> ◯ Not attempted | M14: MIN on the Revenue column of the grid. | N14: =2232100 -> 2232100
A15: 45755 | B15: Central | C15: Printer | D15: Shreya Naik | E15: 8 | F15: 9800 | G15: 78400 | I15: 7 | J15: How many product lines contribute more than 15% each? | L15: =IF(ISBLANK(K15),"◯ Not attempted",IF(NOT(_xlfn.ISFORMULA(K15)),"✎ Use a formula",IF(ISNUMBER(K15),IF(ABS(K15-$N$15)<0.005,"✓ Correct","✗ Check again"),"✗ Not a number"))) -> ◯ Not attempted | M15: COUNTIF on the Share column with ">0.15". | N15: =2 -> 2
A16: 45759 | B16: East | C16: Monitor | D16: Shreya Naik | E16: 28 | F16: 13900 | G16: 389200
A17: 45761 | B17: West | C17: Laptop | D17: Pooja Chopra | E17: 27 | F17: 58500 | G17: 1579500 | J17: Product contribution
A18: 45764 | B18: East | C18: Tablet | D18: Karan Mehta | E18: 15 | F18: 26900 | G18: 403500 | K18: Revenue | L18: Share of total
A19: 45767 | B19: Central | C19: Server | D19: Divya Pillai | E19: 37 | F19: 160300 | G19: 5931100 | J19: Laptop | O19: =SUMIF($C$9:$C$188,$J19,$G$9:$G$188) -> 37698600 | P19: =SUMIF($C$9:$C$188,$J19,$G$9:$G$188)/SUM($G$9:$G$188) -> 0.22865028
A20: 45769 | B20: Central | C20: Printer | D20: Karan Mehta | E20: 13 | F20: 10400 | G20: 135200 | J20: Monitor | O20: =SUMIF($C$9:$C$188,$J20,$G$9:$G$188) -> 10703600 | P20: =SUMIF($C$9:$C$188,$J20,$G$9:$G$188)/SUM($G$9:$G$188) -> 0.064919681
A21: 45772 | B21: North | C21: Monitor | D21: Manish Reddy | E21: 21 | F21: 15700 | G21: 329700 | J21: Printer | O21: =SUMIF($C$9:$C$188,$J21,$G$9:$G$188) -> 5274200 | P21: =SUMIF($C$9:$C$188,$J21,$G$9:$G$188)/SUM($G$9:$G$188) -> 0.03198918
A22: 45773 | B22: East | C22: Monitor | D22: Aditya Verma | E22: 2 | F22: 15400 | G22: 30800 | J22: Router | O22: =SUMIF($C$9:$C$188,$J22,$G$9:$G$188) -> 2232100 | P22: =SUMIF($C$9:$C$188,$J22,$G$9:$G$188)/SUM($G$9:$G$188) -> 0.013538176
A23: 45776 | B23: West | C23: Tablet | D23: Shreya Naik | E23: 11 | F23: 22700 | G23: 249700 | J23: Server | O23: =SUMIF($C$9:$C$188,$J23,$G$9:$G$188) -> 95707800 | P23: =SUMIF($C$9:$C$188,$J23,$G$9:$G$188)/SUM($G$9:$G$188) -> 0.5804888
A24: 45782 | B24: Central | C24: Laptop | D24: Aditya Verma | E24: 21 | F24: 66900 | G24: 1404900 | J24: Tablet | O24: =SUMIF($C$9:$C$188,$J24,$G$9:$G$188) -> 13258200 | P24: =SUMIF($C$9:$C$188,$J24,$G$9:$G$188)/SUM($G$9:$G$188) -> 0.080413891
A25: 45782 | B25: Central | C25: Printer | D25: Pooja Chopra | E25: 13 | F25: 10300 | G25: 133900
A26: 45782 | B26: West | C26: Laptop | D26: Karan Mehta | E26: 29 | F26: 67400 | G26: 1954600
A27: 45786 | B27: South | C27: Monitor | D27: Nikhil Shetty | E27: 24 | F27: 13400 | G27: 321600
A28: 45787 | B28: East | C28: Printer | D28: Karan Mehta | E28: 21 | F28: 9900 | G28: 207900
A29: 45791 | B29: North | C29: Monitor | D29: Nikhil Shetty | E29: 21 | F29: 15200 | G29: 319200
A30: 45794 | B30: East | C30: Printer | D30: Rohit Nair | E30: 17 | F30: 10200 | G30: 173400
A31: 45797 | B31: Central | C31: Server | D31: Aditya Verma | E31: 8 | F31: 136000 | G31: 1088000
A32: 45797 | B32: South | C32: Monitor | D32: Nikhil Shetty | E32: 37 | F32: 14000 | G32: 518000
A33: 45798 | B33: Central | C33: Router | D33: Shreya Naik | E33: 19 | F33: 5000 | G33: 95000
A34: 45798 | B34: South | C34: Server | D34: Ananya Bose | E34: 18 | F34: 164300 | G34: 2957400
A35: 45800 | B35: East | C35: Printer | D35: Ananya Bose | E35: 3 | F35: 8900 | G35: 26700
A36: 45800 | B36: Central | C36: Server | D36: Shreya Naik | E36: 38 | F36: 140200 | G36: 5327600
... A188: 46112 | B188: South | C188: Server | D188: Pooja Chopra | E188: 25 | F188: 161400 | G188: 4035000

Sheet L5 Growth, running totals and i
A1: LESSON 5 · GROWTH, RUNNING TOTALS AND INDEX NUMBERS
A2: ★★★★☆ Three mixed-reference classics on one small table — then the growth questions.
A3: CONCEPT · A running total uses an EXPANDING range: =SUM($B$9:B9). Lock the start, leave the end free, fill down. An index rebases every month to the first one: =B9/$B$9*100 — lock the denominator only. A share of the year divides by a FULLY locked total. Three different lock patterns, three different questions. Getting these right is what separates a model from a spreadsheet.
A8: Month | B8: Revenue | C8: Running total | D8: Index (Apr=100) | E8: % of year | G8: # | H8: Task | I8: Your answer | J8: Check | K8: Hint
A9: Apr-25 | B9: 12537900 | G9: 1 | H9: Fill Running total: revenue from April up to and including this month. | I9: → fill column C | J9: =IF(COUNTA($C$9:$C$20)=0,"◯ Not attempted",IF(NOT(_xlfn.ISFORMULA(C9)),"✎ Use a formula",IFERROR(IF(SUMPRODUCT(--(ABS($C$9:$C$20-$M$9:$M$20)<0.05))=ROWS($C$9:$C$20),"✓ Correct","✗ "&(ROWS($C$9:$C$20)-SUMPRODUCT(--(ABS($C$9:$C$20-$M$9:$M$20)<0.05)))&" rows differ"),"✗ Check the column"))) -> ◯ Not attempted | K9: =SUM($B$9:B9) — only the FIRST cell is locked. | M9: =SUM($B$9:B9) -> 12537900 | N9: =B9/$B$9*100 -> 100 | O9: =B9/SUM($B$9:$B$20) -> 0.076045113
A10: May-25 | B10: 18545600 | G10: 2 | H10: Fill Index (Apr=100): each month as an index where April = 100. | I10: → fill column D | J10: =IF(COUNTA($D$9:$D$20)=0,"◯ Not attempted",IF(NOT(_xlfn.ISFORMULA(D9)),"✎ Use a formula",IFERROR(IF(SUMPRODUCT(--(ABS($D$9:$D$20-$N$9:$N$20)<0.02))=ROWS($D$9:$D$20),"✓ Correct","✗ "&(ROWS($D$9:$D$20)-SUMPRODUCT(--(ABS($D$9:$D$20-$N$9:$N$20)<0.02)))&" rows differ"),"✗ Check the column"))) -> ◯ Not attempted | K10: =B9/$B$9*100 — lock only the denominator. | M10: =SUM($B$9:B10) -> 31083500 | N10: =B10/$B$9*100 -> 147.91632 | O10: =B10/SUM($B$9:$B$20) -> 0.11248313
A11: Jun-25 | B11: 8361600 | G11: 3 | H11: Fill % of year: each month's share of the full-year revenue. | I11: → fill column E | J11: =IF(COUNTA($E$9:$E$20)=0,"◯ Not attempted",IF(NOT(_xlfn.ISFORMULA(E9)),"✎ Use a formula",IFERROR(IF(SUMPRODUCT(--(ABS($E$9:$E$20-$O$9:$O$20)<0.00005))=ROWS($E$9:$E$20),"✓ Correct","✗ "&(ROWS($E$9:$E$20)-SUMPRODUCT(--(ABS($E$9:$E$20-$O$9:$O$20)<0.00005)))&" rows differ"),"✗ Check the column"))) -> ◯ Not attempted | K11: =B9/SUM($B$9:$B$20) — the denominator is fully locked. | M11: =SUM($B$9:B11) -> 39445100 | N11: =B11/$B$9*100 -> 66.690594 | O11: =B11/SUM($B$9:$B$20) -> 0.050714938
A12: Jul-25 | B12: 26837400 | G12: 4 | H12: Growth from April to May, as a percentage. | J12: =IF(ISBLANK(I12),"◯ Not attempted",IF(NOT(_xlfn.ISFORMULA(I12)),"✎ Use a formula",IF(ISNUMBER(I12),IF(ABS(I12-$L$12)<0.0002,"✓ Correct","✗ Check again"),"✗ Not a number"))) -> ◯ Not attempted | K12: =B10/B9-1 | L12: =0.479163 -> 0.479163 | M12: =SUM($B$9:B12) -> 66282500 | N12: =B12/$B$9*100 -> 214.0502 | O12: =B12/SUM($B$9:$B$20) -> 0.16277472
A13: Aug-25 | B13: 25727300 | G13: 5 | H13: Which month had the highest revenue? | J13: =IF(ISBLANK(I13),"◯ Not attempted",IF(NOT(_xlfn.ISFORMULA(I13)),"✎ Use a formula",IF(UPPER(TRIM(I13&""))=UPPER(TRIM($L$13&"")),"✓ Correct","✗ Check again"))) -> ◯ Not attempted | K13: MAX, MATCH, INDEX on this small table. | L13: ="Jul-25" -> Jul-25 | M13: =SUM($B$9:B13) -> 92009800 | N13: =B13/$B$9*100 -> 205.19624 | O13: =B13/SUM($B$9:$B$20) -> 0.15604172
A14: Sep-25 | B14: 13761700 | G14: 6 | H14: The average MONTHLY growth rate over the year (from April to March, compounded). | J14: =IF(ISBLANK(I14),"◯ Not attempted",IF(NOT(_xlfn.ISFORMULA(I14)),"✎ Use a formula",IF(ISNUMBER(I14),IF(ABS(I14-$L$14)<0.0002,"✓ Correct","✗ Check again"),"✗ Not a number"))) -> ◯ Not attempted | K14: (last ÷ first) ^ (1 ÷ number of GAPS) − 1. Twelve months have eleven gaps. | L14: =-0.059453 -> -0.059453 | M14: =SUM($B$9:B14) -> 105771500 | N14: =B14/$B$9*100 -> 109.76081 | O14: =B14/SUM($B$9:$B$20) -> 0.083467728
A15: Oct-25 | B15: 12460600 | G15: 7 | H15: In which month does the running total first pass half the year's revenue? | J15: =IF(ISBLANK(I15),"◯ Not attempted",IF(NOT(_xlfn.ISFORMULA(I15)),"✎ Use a formula",IF(ISNUMBER(I15),IF(ABS(I15-$L$15)<0.005,"✓ Correct","✗ Check again"),"✗ Not a number"))) -> ◯ Not attempted | K15: Count the months still below half the total, then add 1. Use "<"&value to compare against a calculated number. | L15: =5 -> 5 | M15: =SUM($B$9:B15) -> 118232100 | N15: =B15/$B$9*100 -> 99.383469 | O15: =B15/SUM($B$9:$B$20) -> 0.075576272
A16: Nov-25 | B16: 3848600 | G16: 8 | H16: How many months were above the monthly average? | J16: =IF(ISBLANK(I16),"◯ Not attempted",IF(NOT(_xlfn.ISFORMULA(I16)),"✎ Use a formula",IF(ISNUMBER(I16),IF(ABS(I16-$L$16)<0.005,"✓ Correct","✗ Check again"),"✗ Not a number"))) -> ◯ Not attempted | K16: COUNTIF(range,">"&AVERAGE(range)). | L16: =4 -> 4 | M16: =SUM($B$9:B16) -> 122080700 | N16: =B16/$B$9*100 -> 30.695731 | O16: =B16/SUM($B$9:$B$20) -> 0.023342603
A17: Dec-25 | B17: 13194600 | M17: =SUM($B$9:B17) -> 135275300 | N17: =B17/$B$9*100 -> 105.23772 | O17: =B17/SUM($B$9:$B$20) -> 0.080028143
A18: Jan-26 | B18: 11052000 | M18: =SUM($B$9:B18) -> 146327300 | N18: =B18/$B$9*100 -> 88.148733 | O18: =B18/SUM($B$9:$B$20) -> 0.067032804
A19: Feb-26 | B19: 12158500 | M19: =SUM($B$9:B19) -> 158485800 | N19: =B19/$B$9*100 -> 96.973975 | O19: =B19/SUM($B$9:$B$20) -> 0.073743969
A20: Mar-26 | B20: 6388700 | M20: =SUM($B$9:B20) -> 164874500 | N20: =B20/$B$9*100 -> 50.955104 | O20: =B20/SUM($B$9:$B$20) -> 0.038748867

Sheet L6 Boss round — the KPI panel
A1: LESSON 6 · BOSS ROUND — THE KPI PANEL
A2: ★★★★★ Nine questions a sales director asks. No helper columns, no pivot tables.
A3: CONCEPT · Everything here is one cell. MAXIFS and AVERAGEIFS take conditions the same way SUMIFS does. COUNTIFS with ">="&DATE(...) handles a date range. SUMPRODUCT handles any condition the IFS family cannot express, including comparisons against a calculated value. PERCENTILE finds the cut-off for a top decile. Think about the shape before you type.
A8: Date | B8: Region | C8: Product | D8: Rep | E8: Units | F8: Price | G8: Revenue | I8: # | J8: Task | K8: Your answer | L8: Check | M8: Hint
A9: 45749 | B9: East | C9: Printer | D9: Aditya Verma | E9: 12 | F9: 9800 | G9: 117600 | I9: 1 | J9: How many orders were placed in Q3 (October to December 2025)? | L9: =IF(ISBLANK(K9),"◯ Not attempted",IF(NOT(_xlfn.ISFORMULA(K9)),"✎ Use a formula",IF(ISNUMBER(K9),IF(ABS(K9-$N$9)<0.005,"✓ Correct","✗ Check again"),"✗ Not a number"))) -> ◯ Not attempted | M9: Two conditions on the same Date column, joined to real DATE() values with &. | N9: =39 -> 39
A10: 45749 | B10: South | C10: Monitor | D10: Ananya Bose | E10: 21 | F10: 15200 | G10: 319200 | I10: 2 | J10: The largest single order by revenue. | L10: =IF(ISBLANK(K10),"◯ Not attempted",IF(NOT(_xlfn.ISFORMULA(K10)),"✎ Use a formula",IF(ISNUMBER(K10),IF(ABS(K10-$N$10)<0.005,"✓ Correct","✗ Check again"),"✗ Not a number"))) -> ◯ Not attempted | M10: MAX. | N10: =5931100 -> 5931100
A11: 45750 | B11: East | C11: Router | D11: Aditya Verma | E11: 8 | F11: 5700 | G11: 45600 | I11: 3 | J11: Which product was that order for? | L11: =IF(ISBLANK(K11),"◯ Not attempted",IF(NOT(_xlfn.ISFORMULA(K11)),"✎ Use a formula",IF(UPPER(TRIM(K11&""))=UPPER(TRIM($N$11&"")),"✓ Correct","✗ Check again"))) -> ◯ Not attempted | M11: MAX inside MATCH, then INDEX. | N11: ="Server" -> Server
A12: 45751 | B12: South | C12: Monitor | D12: Rohit Nair | E12: 24 | F12: 15300 | G12: 367200 | I12: 4 | J12: Average order value in the West region, counting only orders of more than 20 units. | L12: =IF(ISBLANK(K12),"◯ Not attempted",IF(NOT(_xlfn.ISFORMULA(K12)),"✎ Use a formula",IF(ISNUMBER(K12),IF(ABS(K12-$N$12)<0.05,"✓ Correct","✗ Check again"),"✗ Not a number"))) -> ◯ Not attempted | M12: AVERAGEIFS: the range to average comes first, then pairs of range and criteria. | N12: =1376857.142857 -> 1376857.1
A13: 45752 | B13: Central | C13: Server | D13: Karan Mehta | E13: 16 | F13: 138700 | G13: 2219200 | I13: 5 | J13: Revenue per unit across the whole file. | L13: =IF(ISBLANK(K13),"◯ Not attempted",IF(NOT(_xlfn.ISFORMULA(K13)),"✎ Use a formula",IF(ISNUMBER(K13),IF(ABS(K13-$N$13)<0.05,"✓ Correct","✗ Check again"),"✗ Not a number"))) -> ◯ Not attempted | M13: Total revenue ÷ total units. | N13: =47789.710145 -> 47789.71
A14: 45753 | B14: South | C14: Printer | D14: Rohit Nair | E14: 38 | F14: 9000 | G14: 342000 | I14: 6 | J14: The biggest single order in the "Server" product line. | L14: =IF(ISBLANK(K14),"◯ Not attempted",IF(NOT(_xlfn.ISFORMULA(K14)),"✎ Use a formula",IF(ISNUMBER(K14),IF(ABS(K14-$N$14)<0.005,"✓ Correct","✗ Check again"),"✗ Not a number"))) -> ◯ Not attempted | M14: MAXIFS follows the SUMIFS pattern. | N14: =5931100 -> 5931100
A15: 45755 | B15: Central | C15: Printer | D15: Shreya Naik | E15: 8 | F15: 9800 | G15: 78400 | I15: 7 | J15: Total revenue from orders that are ABOVE the average order value. | L15: =IF(ISBLANK(K15),"◯ Not attempted",IF(NOT(_xlfn.ISFORMULA(K15)),"✎ Use a formula",IF(ISNUMBER(K15),IF(ABS(K15-$N$15)<0.005,"✓ Correct","✗ Check again"),"✗ Not a number"))) -> ◯ Not attempted | M15: SUMIF can do this too, with ">"&AVERAGE(range) as the criteria. | N15: =124678700 -> 124678700
A16: 45759 | B16: East | C16: Monitor | D16: Shreya Naik | E16: 28 | F16: 13900 | G16: 389200 | I16: 8 | J16: Total revenue from the top 10% of orders by value. | L16: =IF(ISBLANK(K16),"◯ Not attempted",IF(NOT(_xlfn.ISFORMULA(K16)),"✎ Use a formula",IF(ISNUMBER(K16),IF(ABS(K16-$N$16)<0.005,"✓ Correct","✗ Check again"),"✗ Not a number"))) -> ◯ Not attempted | M16: PERCENTILE(range, 0.9) is the value that 90% of orders fall below. Sum everything at or above it. | N16: =80035100 -> 80035100
A17: 45761 | B17: West | C17: Laptop | D17: Pooja Chopra | E17: 27 | F17: 58500 | G17: 1579500 | I17: 9 | J17: What share of total revenue is that top 10%? | L17: =IF(ISBLANK(K17),"◯ Not attempted",IF(NOT(_xlfn.ISFORMULA(K17)),"✎ Use a formula",IF(ISNUMBER(K17),IF(ABS(K17-$N$17)<0.0002,"✓ Correct","✗ Check again"),"✗ Not a number"))) -> ◯ Not attempted | M17: The previous answer ÷ total revenue. | N17: =0.48543 -> 0.48543
A18: 45764 | B18: East | C18: Tablet | D18: Karan Mehta | E18: 15 | F18: 26900 | G18: 403500
A19: 45767 | B19: Central | C19: Server | D19: Divya Pillai | E19: 37 | F19: 160300 | G19: 5931100
A20: 45769 | B20: Central | C20: Printer | D20: Karan Mehta | E20: 13 | F20: 10400 | G20: 135200
A21: 45772 | B21: North | C21: Monitor | D21: Manish Reddy | E21: 21 | F21: 15700 | G21: 329700
A22: 45773 | B22: East | C22: Monitor | D22: Aditya Verma | E22: 2 | F22: 15400 | G22: 30800
A23: 45776 | B23: West | C23: Tablet | D23: Shreya Naik | E23: 11 | F23: 22700 | G23: 249700
A24: 45782 | B24: Central | C24: Laptop | D24: Aditya Verma | E24: 21 | F24: 66900 | G24: 1404900
A25: 45782 | B25: Central | C25: Printer | D25: Pooja Chopra | E25: 13 | F25: 10300 | G25: 133900
A26: 45782 | B26: West | C26: Laptop | D26: Karan Mehta | E26: 29 | F26: 67400 | G26: 1954600
A27: 45786 | B27: South | C27: Monitor | D27: Nikhil Shetty | E27: 24 | F27: 13400 | G27: 321600
A28: 45787 | B28: East | C28: Printer | D28: Karan Mehta | E28: 21 | F28: 9900 | G28: 207900
A29: 45791 | B29: North | C29: Monitor | D29: Nikhil Shetty | E29: 21 | F29: 15200 | G29: 319200
... A188: 46112 | B188: South | C188: Server | D188: Pooja Chopra | E188: 25 | F188: 161400 | G188: 4035000

Sheet Solutions
A1: SOLUTIONS & OTHER WAYS — open only after you have tried
A2: Model answers are shapes, not the only answer. If your formula gives the same result, it is right — compare the logic.
A4: L1 Revenue and segments ★★
A5: # | B5: Task | C5: Answer cell | D5: Model formula | E5: Other ways | F5: Why it works
A6: 1 | B6: Fill Revenue = Units × Price. | C6: column G | D6: =E9*F9 (row 9, then fill down) | E6: =PRODUCT(E9:F9) | F6: Double-clicking the small square at the bottom-right of the cell fills to the end of the data. It is the single biggest time-saver in Excel.
A7: 2 | B7: Total revenue for the year. | C7: K10 | D7: =SUM($G$9:$G$188) | E7: =SUMPRODUCT(E9:E188,F9:F188) — the same answer with no helper column at all
A8: 3 | B8: Total units sold. | C8: K11 | D8: =SUM($E$9:$E$188)
A9: 4 | B9: Average order value. | C9: K12 | D9: =AVERAGE($G$9:$G$188) | F9: Average order value and revenue per unit are different questions. Know which one you were asked.
A10: 5 | B10: Revenue from the West region. | C10: K13 | D10: =SUMIF($B$9:$B$188,"West",$G$9:$G$188)
A11: 6 | B11: How many orders are worth more than ₹5,00,000? | C11: K14 | D11: =COUNTIF($G$9:$G$188,">500000")
A12: 7 | B12: Revenue per unit across the whole file. | C12: K15 | D12: =SUM($G$9:$G$188)/SUM($E$9:$E$188) | F12: This is a weighted average price. Averaging the Price column instead gives a different — and wrong — number.
A14: L2 The month by region matrix ★★★
A15: # | B15: Task | C15: Answer cell | D15: Model formula | E15: Other ways | F15: Why it works
A16: 1 | B16: Fill Month as a label like "Jul-25". | C16: column H | D16: =TEXT(A9,"mmm-yy") (row 9, then fill down) | E16: =EOMONTH(A9,0) keeps it a real date you can sort chronologically =YEAR(A9)&"-"&TEXT(MONTH(A9),"00") sorts correctly as text too | F16: "mmm-yy" is readable but sorts alphabetically — Apr before Jan. For a chart axis, keep a real date underneath.
A17: 2 | B17: Fill the whole grid: revenue for each month (rows) and region (columns). | C17: the grid | D17: =SUMIFS($G$9:$G$188,$H$9:$H$188,$K18,$B$9:$B$188,L$17) (first cell, then fill right and down) | E17: =SUMPRODUCT((TEXT($A$9:$A$188,"mmm-yy")=$K12)*($B$9:$B$188=L$11)*$G$9:$G$188) — no Month column needed Insert ▸ PivotTable with Month in Rows and Region in Columns does this in four clicks — but you would not learn the references | F17: One formula for sixty cells is the difference between a five-minute job and an hour of copy-paste errors.
A18: 3 | B18: Grand total of the grid. It must equal total revenue. | C18: L11 | D18: =SUM($L$18:$P$29) | F18: Always tie a summary back to its source. A matrix that does not tie is a matrix that is missing rows.
A19: 4 | B19: The best single month in the West column of your grid. | C19: L12 | D19: =MAX(L18:L29) | F19: Reading a grid with MAX, MIN and MATCH is how a summary becomes an answer.
A20: 5 | B20: Which month was that? Return the month label. | C20: L13 | D20: =INDEX($K18:$K29,MATCH(MAX(L18:L29),L18:L29,0)) | E20: =XLOOKUP(MAX(L12:L23),L12:L23,K12:K23)
A21: 6 | B21: How many of the 60 grid cells are above ₹20,00,000? | C21: L14 | D21: =COUNTIF($L$18:$P$29,">2000000")
A23: L3 Ranking the sales team ★★★
A24: # | B24: Task | C24: Answer cell | D24: Model formula | E24: Other ways | F24: Why it works
A25: 1 | B25: Fill the scorecard: revenue, number of orders and average order value for each rep. | C25: the grid | D25: =SUMIF($D$9:$D$188,$J19,$G$9:$G$188) (first cell, then fill right and down) | E25: Avg order can also be the revenue cell divided by the orders cell — fewer passes over the data =SUMPRODUCT(($D$9:$D$188=$J12)*$G$9:$G$188) does the same as SUMIF and can handle conditions SUMIF cannot | F25: AVERAGEIF ignores blanks; revenue ÷ orders does not. On clean data they agree, on messy data they do not.
A26: 2 | B26: The top rep's revenue. | C26: K10 | D26: =MAX(K19:K28) | E26: =LARGE(K12:K21,1)
A27: 3 | B27: Which rep is that? | C27: K11 | D27: =INDEX($J19:$J28,MATCH(MAX(K19:K28),K19:K28,0)) | E27: =XLOOKUP(MAX(K12:K21),K12:K21,J12:J21)
A28: 4 | B28: Revenue of the SECOND best rep. | C28: K12 | D28: =LARGE(K19:K28,2) | E28: =SMALL(K12:K21,9) — counting from the other end
A29: 5 | B29: Combined revenue of the top 3 reps. | C29: K13 | D29: =SUM(LARGE(K19:K28,{1,2,3})) | E29: =LARGE(K12:K21,1)+LARGE(K12:K21,2)+LARGE(K12:K21,3) | F29: An array constant in {braces} is the neatest way to ask one function for several answers.
A30: 6 | B30: What share of total revenue do the top 3 reps bring in? | C30: K14 | D30: =SUM(LARGE(K19:K28,{1,2,3}))/SUM($G$9:$G$188) | F30: Concentration risk: if three people carry the number, losing one of them is a forecast problem.
A31: 7 | B31: How many reps are ABOVE the team's average revenue? | C31: K15 | D31: =COUNTIF(K19:K28,">"&AVERAGE(K19:K28)) | F31: You cannot write ">AVERAGE(...)" inside quotes. The comparison has to be built as text with &.
A33: L4 Contribution and the 80-20 r ★★★★
A34: # | B34: Task | C34: Answer cell | D34: Model formula | E34: Other ways | F34: Why it works
A35: 1 | B35: Fill the contribution table: revenue and share of total revenue for each product. | C35: the grid | D35: =SUMIF($C$9:$C$188,$J19,$G$9:$G$188) (first cell, then fill right and down) | E35: Share can also be the revenue cell ÷ the grid's own total, if you add a total row underneath | F35: The classic bug here is dividing by an unlocked SUM(G9:G188) that slides down to SUM(G10:G189) on the next row.
A36: 2 | B36: Do the shares add up to 100%? Enter the total of the Share column. | C36: K10 | D36: =SUM(L19:L24) | F36: If it is not 100%, a product is missing from your list or a label is spelled differently in the data.
A37: 3 | B37: Share of the single biggest product. | C37: K11 | D37: =MAX(L19:L24)
A38: 4 | B38: Combined share of the top TWO products. | C38: K12 | D38: =SUM(LARGE(L19:L24,{1,2}))
A39: 5 | B39: How many products does it take, biggest first, to cross 80% of revenue? | C39: K13 | D39: =IFS(LARGE(L19:L24,1)>=0.8,1,SUM(LARGE(L19:L24,{1,2}))>=0.8,2,SUM(LARGE(L19:L24,{1,2,3}))>=0.8,3,SUM(LARGE(L19:L24,{1,2,3,4}))>=0.8,4,SUM(LARGE(L19:L24,{1,2,3,4,5}))>=0.8,5,TRUE,6) | E39: Add a sorted 'cumulative share' column beside the grid, then =COUNTIF(cumulative,"<0.8")+1 =MATCH(0.8,cumulativeShares,1)+1 on an ascending cumulative column | F39: Pareto is not always 80/20. Measure it; do not assume it.
A40: 6 | B40: Revenue of the smallest product line. | C40: K14 | D40: =MIN(K19:K24)
A41: 7 | B41: How many product lines contribute more than 15% each? | C41: K15 | D41: =COUNTIF(L19:L24,">0.15")
A43: L5 Growth, running totals and i ★★★★
A44: # | B44: Task | C44: Answer cell | D44: Model formula | E44: Other ways | F44: Why it works
A45: 1 | B45: Fill Running total: revenue from April up to and including this month. | C45: column C | D45: =SUM($B$9:B9) (row 9, then fill down) | E45: =C8+B9 with a zero above it — a chain instead of an expanding range | F45: Watch the range in the formula bar as you move down the column. It should grow, never slide.
...
