Workbook

Sheet Start Here
A1: EXCEL LAB · 07 LOANS, SIPS & INVESTMENTS
A2: The money functions, properly: EMI and the true cost of a long loan, a full amortisation schedule that proves itself to zero, SIP and goal planning, NPV/IRR project appraisal, XIRR on real dates, and a prepay-or-invest boss round with a break-even rate.
A4: HOW TO USE THIS WORKBOOK
A5: 1 | B5: Work through the lessons in order — each one is harder than the last (★ to ★★★★★).
A6: 2 | B6: Read the Concept box at the top of each lesson, then look at the data.
A7: 3 | B7: Type a FORMULA in each yellow cell. The Check column marks it ✓ or ✗ instantly.
A8: 4 | B8: Blue cells are inputs. Change them and watch every answer update — that is how you know your formula is really right.
A9: 5 | B9: Stuck? Read the Hint. Still stuck? The Solutions sheet shows the model answer and other ways to do it.
A11: COLOUR CODE
B12: Yellow — your answer goes here (always a formula)
B13: Blue — an input you can change
B14: ✓ Correct — marked automatically
B15: ✗ Check again — the result does not match
B16: ✎ You typed a value — replace it with a formula
A18: # | B18: Lesson | C18: Difficulty | D18: Tasks | E18: Solved | F18: Progress
A19: 1 | B19: L1 EMI and the cost of a longer | C19: ★★☆☆☆ | D19: 7 | E19: =COUNTIF('L1 EMI and the cost of a longer'!J9:J15,"✓*") -> 0 | F19: =IFERROR(E19/D19,0) -> 0
A20: 2 | B20: L2 The amortisation schedule | C20: ★★★☆☆ | D20: 8 | E20: =COUNTIF('L2 The amortisation schedule'!J9:J16,"✓*") -> 0 | F20: =IFERROR(E20/D20,0) -> 0
A21: 3 | B21: L3 Goals, SIPs and compounding | C21: ★★★☆☆ | D21: 8 | E21: =COUNTIF('L3 Goals, SIPs and compounding'!I9:I16,"✓*") -> 0 | F21: =IFERROR(E21/D21,0) -> 0
A22: 4 | B22: L4 NPV, IRR and payback | C22: ★★★★☆ | D22: 8 | E22: =COUNTIF('L4 NPV, IRR and payback'!H9:H16,"✓*") -> 0 | F22: =IFERROR(E22/D22,0) -> 0
A23: 5 | B23: L5 Irregular dates — XNPV and X | C23: ★★★★☆ | D23: 8 | E23: =COUNTIF('L5 Irregular dates — XNPV and X'!G9:G16,"✓*") -> 0 | F23: =IFERROR(E23/D23,0) -> 0
A24: 6 | B24: L6 Boss round — prepay or inves | C24: ★★★★★ | D24: 9 | E24: =COUNTIF('L6 Boss round — prepay or inves'!I9:I17,"✓*") -> 0 | F24: =IFERROR(E24/D24,0) -> 0
B25: OVERALL | D25: =SUM(D19:D24) -> 48 | E25: =SUM(E19:E24) -> 0 | F25: =IFERROR(E25/D25,0) -> 0
A27: Excel Lab — created by Pranay · excel-lab-by-pranay.vercel.app · free for every student

Sheet L1 EMI and the cost of a longer
A1: LESSON 1 · EMI AND THE COST OF A LONGER LOAN
A2: ★★☆☆☆ Eight home-loan offers, one formula, and the number nobody shows you: total repaid.
A3: CONCEPT · PMT(rate_per_period, number_of_periods, present_value) returns the level instalment on a loan. Three rules decide whether you get it right: the rate must match the period (annual ÷ 12 for a monthly EMI), the periods must be counted the same way (years × 12), and the sign must be handled — PMT returns a negative number because money leaves you, so put a minus in front to read it as a positive EMI.
A6: Loan amount | B6: 2800000
A8: Bank | B8: Rate p.a. | C8: Years | D8: EMI | E8: Total repaid | G8: # | H8: Task | I8: Your answer | J8: Check | K8: Hint
A9: State Bank | B9: 0.0865 | C9: 20 | G9: 1 | H9: Fill EMI for every bank, rounded to whole rupees, on the loan amount in B6. | I9: → fill column D | J9: =IF(COUNTA($D$9:$D$16)=0,"◯ Not attempted",IF(NOT(_xlfn.ISFORMULA(D9)),"✎ Use a formula",IFERROR(IF(SUMPRODUCT(--(ABS($D$9:$D$16-$M$9:$M$16)<0.01))=ROWS($D$9:$D$16),"✓ Correct","✗ "&(ROWS($D$9:$D$16)-SUMPRODUCT(--(ABS($D$9:$D$16-$M$9:$M$16)<0.01)))&" rows differ"),"✗ Check the column"))) -> ◯ Not attempted | K9: =ROUND(-PMT(B9/12,C9*12,$B$6),0) — divide the rate by 12, multiply the years by 12, lock B6. | M9: =ROUND(-PMT(B9/12,C9*12,$B$6),0) -> 24566 | N9: =ROUND(-PMT(B9/12,C9*12,$B$6),0)*C9*12 -> 5895840
A10: HDFC | B10: 0.089 | C10: 20 | G10: 2 | H10: Fill Total repaid = EMI × Years × 12. | I10: → fill column E | J10: =IF(COUNTA($E$9:$E$16)=0,"◯ Not attempted",IF(NOT(_xlfn.ISFORMULA(E9)),"✎ Use a formula",IFERROR(IF(SUMPRODUCT(--(ABS($E$9:$E$16-$N$9:$N$16)<0.01))=ROWS($E$9:$E$16),"✓ Correct","✗ "&(ROWS($E$9:$E$16)-SUMPRODUCT(--(ABS($E$9:$E$16-$N$9:$N$16)<0.01)))&" rows differ"),"✗ Check the column"))) -> ◯ Not attempted | K10: =D9*C9*12 | M10: =ROUND(-PMT(B10/12,C10*12,$B$6),0) -> 25013 | N10: =ROUND(-PMT(B10/12,C10*12,$B$6),0)*C10*12 -> 6003120
A11: ICICI | B11: 0.0905 | C11: 18 | G11: 3 | H11: The lowest EMI on offer. | J11: =IF(ISBLANK(I11),"◯ Not attempted",IF(NOT(_xlfn.ISFORMULA(I11)),"✎ Use a formula",IF(ISNUMBER(I11),IF(ABS(I11-$L$11)<0.005,"✓ Correct","✗ Check again"),"✗ Not a number"))) -> ◯ Not attempted | K11: MIN over your EMI column. | L11: =SUMPRODUCT(MIN(ROUND(-PMT($B$9:$B$16/12,$C$9:$C$16*12,$B$6),0))) -> 22128 | M11: =ROUND(-PMT(B11/12,C11*12,$B$6),0) -> 26308 | N11: =ROUND(-PMT(B11/12,C11*12,$B$6),0)*C11*12 -> 5682528
A12: Axis | B12: 0.0875 | C12: 25 | G12: 4 | H12: Which bank has the lowest EMI? | J12: =IF(ISBLANK(I12),"◯ Not attempted",IF(NOT(_xlfn.ISFORMULA(I12)),"✎ Use a formula",IF(UPPER(TRIM(I12&""))=UPPER(TRIM($L$12&"")),"✓ Correct","✗ Check again"))) -> ◯ Not attempted | K12: MIN, then MATCH, then INDEX. | L12: ="LIC Housing" -> LIC Housing | M12: =ROUND(-PMT(B12/12,C12*12,$B$6),0) -> 23020 | N12: =ROUND(-PMT(B12/12,C12*12,$B$6),0)*C12*12 -> 6906000
A13: Kotak | B13: 0.092 | C13: 15 | G13: 5 | H13: Which bank costs the LEAST in total repayment? | J13: =IF(ISBLANK(I13),"◯ Not attempted",IF(NOT(_xlfn.ISFORMULA(I13)),"✎ Use a formula",IF(UPPER(TRIM(I13&""))=UPPER(TRIM($L$13&"")),"✓ Correct","✗ Check again"))) -> ◯ Not attempted | K13: Same pattern on the Total repaid column. | L13: ="Kotak" -> Kotak | M13: =ROUND(-PMT(B13/12,C13*12,$B$6),0) -> 28734 | N13: =ROUND(-PMT(B13/12,C13*12,$B$6),0)*C13*12 -> 5172120
A14: Bank of Baroda | B14: 0.085 | C14: 22 | G14: 6 | H14: The gap between the most expensive and the cheapest offer, in total repayment. | J14: =IF(ISBLANK(I14),"◯ Not attempted",IF(NOT(_xlfn.ISFORMULA(I14)),"✎ Use a formula",IF(ISNUMBER(I14),IF(ABS(I14-$L$14)<0.005,"✓ Correct","✗ Check again"),"✗ Not a number"))) -> ◯ Not attempted | K14: MAX minus MIN on the Total repaid column. | L14: =SUMPRODUCT(MAX(ROUND(-PMT($B$9:$B$16/12,$C$9:$C$16*12,$B$6),0)*$C$9:$C$16*12))-SUMPRODUCT(MIN(ROUND(-PMT($B$9:$B$16/12,$C$9:$C$16*12,$B$6),0)*$C$9:$C$16*12)) -> 2793960 | M14: =ROUND(-PMT(B14/12,C14*12,$B$6),0) -> 23475 | N14: =ROUND(-PMT(B14/12,C14*12,$B$6),0)*C14*12 -> 6197400
A15: PNB Housing | B15: 0.0955 | C15: 20 | G15: 7 | H15: How many offers have an EMI below ₹25,000? | J15: =IF(ISBLANK(I15),"◯ Not attempted",IF(NOT(_xlfn.ISFORMULA(I15)),"✎ Use a formula",IF(ISNUMBER(I15),IF(ABS(I15-$L$15)<0.005,"✓ Correct","✗ Check again"),"✗ Not a number"))) -> ◯ Not attempted | K15: COUNTIF(range,"<25000"). | L15: =SUMPRODUCT(--(ROUND(-PMT($B$9:$B$16/12,$C$9:$C$16*12,$B$6),0)<25000)) -> 4 | M15: =ROUND(-PMT(B15/12,C15*12,$B$6),0) -> 26191 | N15: =ROUND(-PMT(B15/12,C15*12,$B$6),0)*C15*12 -> 6285840
A16: LIC Housing | B16: 0.088 | C16: 30 | M16: =ROUND(-PMT(B16/12,C16*12,$B$6),0) -> 22128 | N16: =ROUND(-PMT(B16/12,C16*12,$B$6),0)*C16*12 -> 7966080

Sheet L2 The amortisation schedule
A1: LESSON 2 · THE AMORTISATION SCHEDULE
A2: ★★★☆☆ Build the table the bank will not give you — and prove the loan ends at exactly zero.
A3: CONCEPT · Every EMI splits into interest and principal. Interest for a month = opening balance × monthly rate. Principal = EMI − interest. Closing = opening − principal, and that closing becomes next month's opening. That chain is the schedule. IPMT and PPMT give the same two pieces directly for any month, and FV gives the balance after any number of payments — build the chain first so you understand it, then learn the shortcuts.
A6: Loan amount | B6: 600000 | D6: Annual rate | E6: 0.095 | G6: Years | H6: 2
A8: Month | B8: Opening | C8: Interest | D8: Principal | E8: Closing | G8: # | H8: Task | I8: Your answer | J8: Check | K8: Hint
A9: 1 | G9: 1 | H9: The EMI on this loan. Do NOT round it — the schedule must tie to the paisa. | J9: =IF(ISBLANK(I9),"◯ Not attempted",IF(NOT(_xlfn.ISFORMULA(I9)),"✎ Use a formula",IF(ISNUMBER(I9),IF(ABS(I9-$L$9)<0.02,"✓ Correct","✗ Check again"),"✗ Not a number"))) -> ◯ Not attempted | K9: =-PMT($E$6/12,$H$6*12,$B$6) | L9: =-PMT($E$6/12,$H$6*12,$B$6) -> 27548.696 | M9: =-FV($E$6/12,0,PMT($E$6/12,$H$6*12,$B$6),$B$6) -> 600000 | N9: =-IPMT($E$6/12,1,$H$6*12,$B$6) -> 4750 | O9: =-PPMT($E$6/12,1,$H$6*12,$B$6) -> 22798.696 | P9: =-FV($E$6/12,1,PMT($E$6/12,$H$6*12,$B$6),$B$6) -> 577201.3
A10: 2 | G10: 2 | H10: Fill Opening: the loan amount in month 1, then last month's closing balance. | I10: → fill column B | J10: =IF(COUNTA($B$9:$B$32)=0,"◯ Not attempted",IF(NOT(_xlfn.ISFORMULA(B9)),"✎ Use a formula",IFERROR(IF(SUMPRODUCT(--(ABS($B$9:$B$32-$M$9:$M$32)<0.5))=ROWS($B$9:$B$32),"✓ Correct","✗ "&(ROWS($B$9:$B$32)-SUMPRODUCT(--(ABS($B$9:$B$32-$M$9:$M$32)<0.5)))&" rows differ"),"✗ Check the column"))) -> ◯ Not attempted | K10: Row 1 points at the loan amount. Row 2 onwards points at the Closing cell one row above. | M10: =-FV($E$6/12,1,PMT($E$6/12,$H$6*12,$B$6),$B$6) -> 577201.3 | N10: =-IPMT($E$6/12,2,$H$6*12,$B$6) -> 4569.5103 | O10: =-PPMT($E$6/12,2,$H$6*12,$B$6) -> 22979.185 | P10: =-FV($E$6/12,2,PMT($E$6/12,$H$6*12,$B$6),$B$6) -> 554222.12
A11: 3 | G11: 3 | H11: Fill Interest = opening balance × monthly rate. | I11: → fill column C | J11: =IF(COUNTA($C$9:$C$32)=0,"◯ Not attempted",IF(NOT(_xlfn.ISFORMULA(C9)),"✎ Use a formula",IFERROR(IF(SUMPRODUCT(--(ABS($C$9:$C$32-$N$9:$N$32)<0.5))=ROWS($C$9:$C$32),"✓ Correct","✗ "&(ROWS($C$9:$C$32)-SUMPRODUCT(--(ABS($C$9:$C$32-$N$9:$N$32)<0.5)))&" rows differ"),"✗ Check the column"))) -> ◯ Not attempted | K11: =B9*$E$6/12 | M11: =-FV($E$6/12,2,PMT($E$6/12,$H$6*12,$B$6),$B$6) -> 554222.12 | N11: =-IPMT($E$6/12,3,$H$6*12,$B$6) -> 4387.5918 | O11: =-PPMT($E$6/12,3,$H$6*12,$B$6) -> 23161.104 | P11: =-FV($E$6/12,3,PMT($E$6/12,$H$6*12,$B$6),$B$6) -> 531061.01
A12: 4 | G12: 4 | H12: Fill Principal = EMI − Interest. Point at your EMI answer so one cell drives the whole table. | I12: → fill column D | J12: =IF(COUNTA($D$9:$D$32)=0,"◯ Not attempted",IF(NOT(_xlfn.ISFORMULA(D9)),"✎ Use a formula",IFERROR(IF(SUMPRODUCT(--(ABS($D$9:$D$32-$O$9:$O$32)<0.5))=ROWS($D$9:$D$32),"✓ Correct","✗ "&(ROWS($D$9:$D$32)-SUMPRODUCT(--(ABS($D$9:$D$32-$O$9:$O$32)<0.5)))&" rows differ"),"✗ Check the column"))) -> ◯ Not attempted | K12: =$I$9-C9 — lock the EMI cell with $ so it does not move as you fill down. | M12: =-FV($E$6/12,3,PMT($E$6/12,$H$6*12,$B$6),$B$6) -> 531061.01 | N12: =-IPMT($E$6/12,4,$H$6*12,$B$6) -> 4204.233 | O12: =-PPMT($E$6/12,4,$H$6*12,$B$6) -> 23344.463 | P12: =-FV($E$6/12,4,PMT($E$6/12,$H$6*12,$B$6),$B$6) -> 507716.55
A13: 5 | G13: 5 | H13: Fill Closing = Opening − Principal. | I13: → fill column E | J13: =IF(COUNTA($E$9:$E$32)=0,"◯ Not attempted",IF(NOT(_xlfn.ISFORMULA(E9)),"✎ Use a formula",IFERROR(IF(SUMPRODUCT(--(ABS($E$9:$E$32-$P$9:$P$32)<0.5))=ROWS($E$9:$E$32),"✓ Correct","✗ "&(ROWS($E$9:$E$32)-SUMPRODUCT(--(ABS($E$9:$E$32-$P$9:$P$32)<0.5)))&" rows differ"),"✗ Check the column"))) -> ◯ Not attempted | K13: =B9-D9 | M13: =-FV($E$6/12,4,PMT($E$6/12,$H$6*12,$B$6),$B$6) -> 507716.55 | N13: =-IPMT($E$6/12,5,$H$6*12,$B$6) -> 4019.4227 | O13: =-PPMT($E$6/12,5,$H$6*12,$B$6) -> 23529.273 | P13: =-FV($E$6/12,5,PMT($E$6/12,$H$6*12,$B$6),$B$6) -> 484187.28
A14: 6 | G14: 6 | H14: Total interest paid over the whole loan. | J14: =IF(ISBLANK(I14),"◯ Not attempted",IF(NOT(_xlfn.ISFORMULA(I14)),"✎ Use a formula",IF(ISNUMBER(I14),IF(ABS(I14-$L$14)<0.5,"✓ Correct","✗ Check again"),"✗ Not a number"))) -> ◯ Not attempted | K14: SUM your Interest column. | L14: =-CUMIPMT($E$6/12,$H$6*12,$B$6,1,$H$6*12,0) -> 61168.699 | M14: =-FV($E$6/12,5,PMT($E$6/12,$H$6*12,$B$6),$B$6) -> 484187.28 | N14: =-IPMT($E$6/12,6,$H$6*12,$B$6) -> 3833.1493 | O14: =-PPMT($E$6/12,6,$H$6*12,$B$6) -> 23715.547 | P14: =-FV($E$6/12,6,PMT($E$6/12,$H$6*12,$B$6),$B$6) -> 460471.73
A15: 7 | G15: 7 | H15: The closing balance in the final month. It must be zero. | J15: =IF(ISBLANK(I15),"◯ Not attempted",IF(NOT(_xlfn.ISFORMULA(I15)),"✎ Use a formula",IF(ISNUMBER(I15),IF(ABS(I15-$L$15)<0.5,"✓ Correct","✗ Check again"),"✗ Not a number"))) -> ◯ Not attempted | K15: Just point at the last cell of your Closing column. | L15: =0 -> 0 | M15: =-FV($E$6/12,6,PMT($E$6/12,$H$6*12,$B$6),$B$6) -> 460471.73 | N15: =-IPMT($E$6/12,7,$H$6*12,$B$6) -> 3645.4012 | O15: =-PPMT($E$6/12,7,$H$6*12,$B$6) -> 23903.295 | P15: =-FV($E$6/12,7,PMT($E$6/12,$H$6*12,$B$6),$B$6) -> 436568.44
A16: 8 | G16: 8 | H16: In which month does the PRINCIPAL part first become larger than the INTEREST part? | J16: =IF(ISBLANK(I16),"◯ Not attempted",IF(NOT(_xlfn.ISFORMULA(I16)),"✎ Use a formula",IF(ISNUMBER(I16),IF(ABS(I16-$L$16)<0.005,"✓ Correct","✗ Check again"),"✗ Not a number"))) -> ◯ Not attempted | K16: Count the months where interest is still the bigger half, then add one. | L16: =SUMPRODUCT(--(-IPMT($E$6/12,$A$9:$A$32,$H$6*12,$B$6)>=-PPMT($E$6/12,$A$9:$A$32,$H$6*12,$B$6)))+1 -> 1 | M16: =-FV($E$6/12,7,PMT($E$6/12,$H$6*12,$B$6),$B$6) -> 436568.44 | N16: =-IPMT($E$6/12,8,$H$6*12,$B$6) -> 3456.1668 | O16: =-PPMT($E$6/12,8,$H$6*12,$B$6) -> 24092.529 | P16: =-FV($E$6/12,8,PMT($E$6/12,$H$6*12,$B$6),$B$6) -> 412475.91
A17: 9 | M17: =-FV($E$6/12,8,PMT($E$6/12,$H$6*12,$B$6),$B$6) -> 412475.91 | N17: =-IPMT($E$6/12,9,$H$6*12,$B$6) -> 3265.4343 | O17: =-PPMT($E$6/12,9,$H$6*12,$B$6) -> 24283.262 | P17: =-FV($E$6/12,9,PMT($E$6/12,$H$6*12,$B$6),$B$6) -> 388192.65
A18: 10 | M18: =-FV($E$6/12,9,PMT($E$6/12,$H$6*12,$B$6),$B$6) -> 388192.65 | N18: =-IPMT($E$6/12,10,$H$6*12,$B$6) -> 3073.1918 | O18: =-PPMT($E$6/12,10,$H$6*12,$B$6) -> 24475.504 | P18: =-FV($E$6/12,10,PMT($E$6/12,$H$6*12,$B$6),$B$6) -> 363717.14
A19: 11 | M19: =-FV($E$6/12,10,PMT($E$6/12,$H$6*12,$B$6),$B$6) -> 363717.14 | N19: =-IPMT($E$6/12,11,$H$6*12,$B$6) -> 2879.4274 | O19: =-PPMT($E$6/12,11,$H$6*12,$B$6) -> 24669.268 | P19: =-FV($E$6/12,11,PMT($E$6/12,$H$6*12,$B$6),$B$6) -> 339047.87
A20: 12 | M20: =-FV($E$6/12,11,PMT($E$6/12,$H$6*12,$B$6),$B$6) -> 339047.87 | N20: =-IPMT($E$6/12,12,$H$6*12,$B$6) -> 2684.129 | O20: =-PPMT($E$6/12,12,$H$6*12,$B$6) -> 24864.567 | P20: =-FV($E$6/12,12,PMT($E$6/12,$H$6*12,$B$6),$B$6) -> 314183.31
A21: 13 | M21: =-FV($E$6/12,12,PMT($E$6/12,$H$6*12,$B$6),$B$6) -> 314183.31 | N21: =-IPMT($E$6/12,13,$H$6*12,$B$6) -> 2487.2845 | O21: =-PPMT($E$6/12,13,$H$6*12,$B$6) -> 25061.411 | P21: =-FV($E$6/12,13,PMT($E$6/12,$H$6*12,$B$6),$B$6) -> 289121.9
A22: 14 | M22: =-FV($E$6/12,13,PMT($E$6/12,$H$6*12,$B$6),$B$6) -> 289121.9 | N22: =-IPMT($E$6/12,14,$H$6*12,$B$6) -> 2288.8817 | O22: =-PPMT($E$6/12,14,$H$6*12,$B$6) -> 25259.814 | P22: =-FV($E$6/12,14,PMT($E$6/12,$H$6*12,$B$6),$B$6) -> 263862.08
A23: 15 | M23: =-FV($E$6/12,14,PMT($E$6/12,$H$6*12,$B$6),$B$6) -> 263862.08 | N23: =-IPMT($E$6/12,15,$H$6*12,$B$6) -> 2088.9082 | O23: =-PPMT($E$6/12,15,$H$6*12,$B$6) -> 25459.788 | P23: =-FV($E$6/12,15,PMT($E$6/12,$H$6*12,$B$6),$B$6) -> 238402.3
A24: 16 | M24: =-FV($E$6/12,15,PMT($E$6/12,$H$6*12,$B$6),$B$6) -> 238402.3 | N24: =-IPMT($E$6/12,16,$H$6*12,$B$6) -> 1887.3515 | O24: =-PPMT($E$6/12,16,$H$6*12,$B$6) -> 25661.344 | P24: =-FV($E$6/12,16,PMT($E$6/12,$H$6*12,$B$6),$B$6) -> 212740.95
A25: 17 | M25: =-FV($E$6/12,16,PMT($E$6/12,$H$6*12,$B$6),$B$6) -> 212740.95 | N25: =-IPMT($E$6/12,17,$H$6*12,$B$6) -> 1684.1992 | O25: =-PPMT($E$6/12,17,$H$6*12,$B$6) -> 25864.497 | P25: =-FV($E$6/12,17,PMT($E$6/12,$H$6*12,$B$6),$B$6) -> 186876.45
A26: 18 | M26: =-FV($E$6/12,17,PMT($E$6/12,$H$6*12,$B$6),$B$6) -> 186876.45 | N26: =-IPMT($E$6/12,18,$H$6*12,$B$6) -> 1479.4386 | O26: =-PPMT($E$6/12,18,$H$6*12,$B$6) -> 26069.257 | P26: =-FV($E$6/12,18,PMT($E$6/12,$H$6*12,$B$6),$B$6) -> 160807.2
A27: 19 | M27: =-FV($E$6/12,18,PMT($E$6/12,$H$6*12,$B$6),$B$6) -> 160807.2 | N27: =-IPMT($E$6/12,19,$H$6*12,$B$6) -> 1273.057 | O27: =-PPMT($E$6/12,19,$H$6*12,$B$6) -> 26275.639 | P27: =-FV($E$6/12,19,PMT($E$6/12,$H$6*12,$B$6),$B$6) -> 134531.56
A28: 20 | M28: =-FV($E$6/12,19,PMT($E$6/12,$H$6*12,$B$6),$B$6) -> 134531.56 | N28: =-IPMT($E$6/12,20,$H$6*12,$B$6) -> 1065.0415 | O28: =-PPMT($E$6/12,20,$H$6*12,$B$6) -> 26483.654 | P28: =-FV($E$6/12,20,PMT($E$6/12,$H$6*12,$B$6),$B$6) -> 108047.9
A29: 21 | M29: =-FV($E$6/12,20,PMT($E$6/12,$H$6*12,$B$6),$B$6) -> 108047.9 | N29: =-IPMT($E$6/12,21,$H$6*12,$B$6) -> 855.37924 | O29: =-PPMT($E$6/12,21,$H$6*12,$B$6) -> 26693.317 | P29: =-FV($E$6/12,21,PMT($E$6/12,$H$6*12,$B$6),$B$6) -> 81354.587
A30: 22 | M30: =-FV($E$6/12,21,PMT($E$6/12,$H$6*12,$B$6),$B$6) -> 81354.587 | N30: =-IPMT($E$6/12,22,$H$6*12,$B$6) -> 644.05715 | O30: =-PPMT($E$6/12,22,$H$6*12,$B$6) -> 26904.639 | P30: =-FV($E$6/12,22,PMT($E$6/12,$H$6*12,$B$6),$B$6) -> 54449.949
A31: 23 | M31: =-FV($E$6/12,22,PMT($E$6/12,$H$6*12,$B$6),$B$6) -> 54449.949 | N31: =-IPMT($E$6/12,23,$H$6*12,$B$6) -> 431.06209 | O31: =-PPMT($E$6/12,23,$H$6*12,$B$6) -> 27117.634 | P31: =-FV($E$6/12,23,PMT($E$6/12,$H$6*12,$B$6),$B$6) -> 27332.315
A32: 24 | M32: =-FV($E$6/12,23,PMT($E$6/12,$H$6*12,$B$6),$B$6) -> 27332.315 | N32: =-IPMT($E$6/12,24,$H$6*12,$B$6) -> 216.38083 | O32: =-PPMT($E$6/12,24,$H$6*12,$B$6) -> 27332.315 | P32: =-FV($E$6/12,24,PMT($E$6/12,$H$6*12,$B$6),$B$6) -> 8.1490725e-09

Sheet L3 Goals, SIPs and compounding
A1: LESSON 3 · GOALS, SIPS AND COMPOUNDING
A2: ★★★☆☆ Work backwards from what you want to what you must save every month.
A3: CONCEPT · FV(rate, periods, payment) grows a stream of savings. PMT(rate, periods, 0, target) reverses it: how much per month to land on a target. NPER answers 'how long', RATE answers 'what return would I need'. All four are the same equation rearranged, and all four need the sign convention: money you pay in is negative, money you get back is positive.
A6: Expected return p.a. | B6: 0.12
A8: Goal | B8: Target | C8: Years | D8: Monthly SIP | F8: # | G8: Task | H8: Your answer | I8: Check | J8: Hint
A9: Emergency fund | B9: 600000 | C9: 2 | F9: 1 | G9: Fill Monthly SIP: the amount to invest every month to reach each target, at the return in B6. | H9: → fill column D | I9: =IF(COUNTA($D$9:$D$15)=0,"◯ Not attempted",IF(NOT(_xlfn.ISFORMULA(D9)),"✎ Use a formula",IFERROR(IF(SUMPRODUCT(--(ABS($D$9:$D$15-$L$9:$L$15)<0.05))=ROWS($D$9:$D$15),"✓ Correct","✗ "&(ROWS($D$9:$D$15)-SUMPRODUCT(--(ABS($D$9:$D$15-$L$9:$L$15)<0.05)))&" rows differ"),"✗ Check the column"))) -> ◯ Not attempted | J9: =-PMT($B$6/12,C9*12,0,B9) — the 0 is today's value (you start from nothing), B9 is the future value you want. | L9: =-PMT($B$6/12,C9*12,0,B9) -> 22244.083
A10: New laptop | B10: 120000 | C10: 1 | F10: 2 | G10: What is a ₹10,000 monthly SIP worth after 15 years at the return in B6? | I10: =IF(ISBLANK(H10),"◯ Not attempted",IF(NOT(_xlfn.ISFORMULA(H10)),"✎ Use a formula",IF(ISNUMBER(H10),IF(ABS(H10-$K$10)<0.5,"✓ Correct","✗ Check again"),"✗ Not a number"))) -> ◯ Not attempted | J10: =FV($B$6/12,15*12,-10000) — the payment is negative because you pay it in. | K10: =FV($B$6/12,15*12,-10000) -> 4995802 | L10: =-PMT($B$6/12,C10*12,0,B10) -> 9461.8546
A11: Higher studies | B11: 2500000 | C11: 5 | F11: 3 | G11: Of that value, how much is growth rather than your own money? | I11: =IF(ISBLANK(H11),"◯ Not attempted",IF(NOT(_xlfn.ISFORMULA(H11)),"✎ Use a formula",IF(ISNUMBER(H11),IF(ABS(H11-$K$11)<0.5,"✓ Correct","✗ Check again"),"✗ Not a number"))) -> ◯ Not attempted | J11: Future value minus (10,000 × 180 months). | K11: =FV($B$6/12,15*12,-10000)-10000*15*12 -> 3195802 | L11: =-PMT($B$6/12,C11*12,0,B11) -> 30611.119
A12: Car down payment | B12: 800000 | C12: 3 | F12: 4 | G12: How many MONTHS to reach ₹25,00,000 saving ₹15,000 a month? Round up to a whole month. | I12: =IF(ISBLANK(H12),"◯ Not attempted",IF(NOT(_xlfn.ISFORMULA(H12)),"✎ Use a formula",IF(ISNUMBER(H12),IF(ABS(H12-$K$12)<0.005,"✓ Correct","✗ Check again"),"✗ Not a number"))) -> ◯ Not attempted | J12: NPER(rate, payment, present value, future value), then ROUNDUP. | K12: =ROUNDUP(NPER($B$6/12,-15000,0,2500000),0) -> 99 | L12: =-PMT($B$6/12,C12*12,0,B12) -> 18571.448
A13: House down payment | B13: 4000000 | C13: 8 | F13: 5 | G13: What ANNUAL return would turn ₹5,000 a month for 10 years into ₹12,00,000? | I13: =IF(ISBLANK(H13),"◯ Not attempted",IF(NOT(_xlfn.ISFORMULA(H13)),"✎ Use a formula",IF(ISNUMBER(H13),IF(ABS(H13-$K$13)<0.0001,"✓ Correct","✗ Check again"),"✗ Not a number"))) -> ◯ Not attempted | J13: RATE gives the MONTHLY rate — multiply by 12. | K13: =RATE(120,-5000,0,1200000)*12 -> 0.12718833 | L13: =-PMT($B$6/12,C13*12,0,B13) -> 25011.366
A14: Wedding | B14: 1800000 | C14: 4 | F14: 6 | G14: What single lump sum today becomes ₹50,00,000 in 12 years at the return in B6? | I14: =IF(ISBLANK(H14),"◯ Not attempted",IF(NOT(_xlfn.ISFORMULA(H14)),"✎ Use a formula",IF(ISNUMBER(H14),IF(ABS(H14-$K$14)<0.5,"✓ Correct","✗ Check again"),"✗ Not a number"))) -> ◯ Not attempted | J14: =-PV($B$6,12,0,5000000) — annual rate and annual periods this time, so no ÷12. | K14: =-PV($B$6,12,0,5000000) -> 1283375.5 | L14: =-PMT($B$6/12,C14*12,0,B14) -> 29400.904
A15: Retirement corpus | B15: 20000000 | C15: 25 | F15: 7 | G15: Total of all the monthly SIPs in the table. | I15: =IF(ISBLANK(H15),"◯ Not attempted",IF(NOT(_xlfn.ISFORMULA(H15)),"✎ Use a formula",IF(ISNUMBER(H15),IF(ABS(H15-$K$15)<0.05,"✓ Correct","✗ Check again"),"✗ Not a number"))) -> ◯ Not attempted | J15: SUM your SIP column. | K15: =SUMPRODUCT(-PMT($B$6/12,$C$9:$C$15*12,0,$B$9:$B$15)) -> 145945.6 | L15: =-PMT($B$6/12,C15*12,0,B15) -> 10644.828
F16: 8 | G16: Which goal needs the largest monthly SIP? | I16: =IF(ISBLANK(H16),"◯ Not attempted",IF(NOT(_xlfn.ISFORMULA(H16)),"✎ Use a formula",IF(UPPER(TRIM(H16&""))=UPPER(TRIM($K$16&"")),"✓ Correct","✗ Check again"))) -> ◯ Not attempted | J16: MAX, MATCH, INDEX. | K16: ="Higher studies" -> Higher studies

Sheet L4 NPV, IRR and payback
A1: LESSON 4 · NPV, IRR AND PAYBACK
A2: ★★★★☆ Appraise a project the way a finance committee does.
A3: CONCEPT · NPV discounts future cash flows back to today. Excel's NPV assumes the FIRST value in the range is one period away, so a year-0 outflow must be ADDED separately: =NPV(rate, year1:yearN) + year0. IRR is the discount rate that makes NPV exactly zero — it takes the whole range including year 0. Payback ignores the time value of money entirely, which is why it is a sanity check, not a decision.
A6: Discount rate | B6: 0.14
A8: Year | B8: Cash flow | C8: Cumulative | E8: # | F8: Task | G8: Your answer | H8: Check | I8: Hint
A9: 0 | B9: -4200000 | E9: 1 | F9: Fill Cumulative: the running total of cash flows from year 0 down. | G9: → fill column C | H9: =IF(COUNTA($C$9:$C$16)=0,"◯ Not attempted",IF(NOT(_xlfn.ISFORMULA(C9)),"✎ Use a formula",IFERROR(IF(SUMPRODUCT(--(ABS($C$9:$C$16-$K$9:$K$16)<0.01))=ROWS($C$9:$C$16),"✓ Correct","✗ "&(ROWS($C$9:$C$16)-SUMPRODUCT(--(ABS($C$9:$C$16-$K$9:$K$16)<0.01)))&" rows differ"),"✗ Check the column"))) -> ◯ Not attempted | I9: =SUM($B$9:B9) — lock only the START of the range so it grows as you fill down. | K9: =SUM($B$9:B9) -> -4200000
A10: 1 | B10: 620000 | E10: 2 | F10: NPV of the project at the discount rate in B6. | H10: =IF(ISBLANK(G10),"◯ Not attempted",IF(NOT(_xlfn.ISFORMULA(G10)),"✎ Use a formula",IF(ISNUMBER(G10),IF(ABS(G10-$J$10)<0.5,"✓ Correct","✗ Check again"),"✗ Not a number"))) -> ◯ Not attempted | I10: =NPV($B$6,B10:B16)+B9 — years 1 to 7 inside NPV, year 0 added outside. | J10: =NPV($B$6,B10:B16)+B9 -> 140997.51 | K10: =SUM($B$9:B10) -> -3580000
A11: 2 | B11: 880000 | E11: 3 | F11: The project's IRR. | H11: =IF(ISBLANK(G11),"◯ Not attempted",IF(NOT(_xlfn.ISFORMULA(G11)),"✎ Use a formula",IF(ISNUMBER(G11),IF(ABS(G11-$J$11)<0.0001,"✓ Correct","✗ Check again"),"✗ Not a number"))) -> ◯ Not attempted | I11: =IRR(B9:B16) — the whole range, year 0 included. | J11: =IRR($B$9:$B$16) -> 0.14996529 | K11: =SUM($B$9:B11) -> -2700000
A12: 3 | B12: 1150000 | E12: 4 | F12: In which YEAR does the cumulative cash flow first turn positive? | H12: =IF(ISBLANK(G12),"◯ Not attempted",IF(NOT(_xlfn.ISFORMULA(G12)),"✎ Use a formula",IF(ISNUMBER(G12),IF(ABS(G12-$J$12)<0.005,"✓ Correct","✗ Check again"),"✗ Not a number"))) -> ◯ Not attempted | I12: Count how many years are still negative — that count is the payback year. | J12: =5 -> 5 | K12: =SUM($B$9:B12) -> -1550000
A13: 4 | B13: 1240000 | E13: 5 | F13: Present value of the INFLOWS only (years 1 to 7). | H13: =IF(ISBLANK(G13),"◯ Not attempted",IF(NOT(_xlfn.ISFORMULA(G13)),"✎ Use a formula",IF(ISNUMBER(G13),IF(ABS(G13-$J$13)<0.5,"✓ Correct","✗ Check again"),"✗ Not a number"))) -> ◯ Not attempted | I13: The same NPV, without adding year 0. | J13: =NPV($B$6,B10:B16) -> 4340997.5 | K13: =SUM($B$9:B13) -> -310000
A14: 5 | B14: 1310000 | E14: 6 | F14: Profitability index = PV of inflows ÷ the initial outflow (as a positive number). | H14: =IF(ISBLANK(G14),"◯ Not attempted",IF(NOT(_xlfn.ISFORMULA(G14)),"✎ Use a formula",IF(ISNUMBER(G14),IF(ABS(G14-$J$14)<0.0005,"✓ Correct","✗ Check again"),"✗ Not a number"))) -> ◯ Not attempted | I14: PV of inflows ÷ −B9. | J14: =NPV($B$6,B10:B16)/-B9 -> 1.0335708 | K14: =SUM($B$9:B14) -> 1000000
A15: 6 | B15: 1180000 | E15: 7 | F15: Proof: NPV calculated AT the IRR. It must be zero. | H15: =IF(ISBLANK(G15),"◯ Not attempted",IF(NOT(_xlfn.ISFORMULA(G15)),"✎ Use a formula",IF(ISNUMBER(G15),IF(ABS(G15-$J$15)<1,"✓ Correct","✗ Check again"),"✗ Not a number"))) -> ◯ Not attempted | I15: Replace the discount rate in your NPV formula with IRR(B9:B16). | J15: =0 -> 0 | K15: =SUM($B$9:B15) -> 2180000
A16: 7 | B16: 980000 | E16: 8 | F16: NPV if every inflow came in 10% lower than forecast. | H16: =IF(ISBLANK(G16),"◯ Not attempted",IF(NOT(_xlfn.ISFORMULA(G16)),"✎ Use a formula",IF(ISNUMBER(G16),IF(ABS(G16-$J$16)<0.5,"✓ Correct","✗ Check again"),"✗ Not a number"))) -> ◯ Not attempted | I16: Multiply the inflow PV by 0.9, then add year 0. | J16: =NPV($B$6,B10:B16)*0.9+B9 -> -293102.24 | K16: =SUM($B$9:B16) -> 3160000

Sheet L5 Irregular dates — XNPV and X
A1: LESSON 5 · IRREGULAR DATES — XNPV AND XIRR
A2: ★★★★☆ Real money does not arrive on 31 March. Value it on the dates it actually moved.
A3: CONCEPT · NPV and IRR assume every cash flow is exactly one period apart. Real investments are not like that. XNPV(rate, values, dates) and XIRR(values, dates) take the actual dates and discount on a 365-day basis, so a payment two weeks late is worth slightly less. Both need at least one negative and one positive value, and the dates must line up with the values one for one.
A6: Discount rate | B6: 0.12
A8: Date | B8: Cash flow | D8: # | E8: Task | F8: Your answer | G8: Check | H8: Hint
A9: 45397 | B9: -500000 | D9: 1 | E9: XNPV of the whole series at the rate in B6. | G9: =IF(ISBLANK(F9),"◯ Not attempted",IF(NOT(_xlfn.ISFORMULA(F9)),"✎ Use a formula",IF(ISNUMBER(F9),IF(ABS(F9-$I$9)<0.5,"✓ Correct","✗ Check again"),"✗ Not a number"))) -> ◯ Not attempted | H9: =XNPV($B$6,B9:B18,A9:A18) — values first, dates second. | I9: =XNPV($B$6,$B$9:$B$18,$A$9:$A$18) -> 119981.37
A10: 45481 | B10: -250000 | D10: 2 | E10: The XIRR of the series — the annualised return actually earned. | G10: =IF(ISBLANK(F10),"◯ Not attempted",IF(NOT(_xlfn.ISFORMULA(F10)),"✎ Use a formula",IF(ISNUMBER(F10),IF(ABS(F10-$I$10)<0.0001,"✓ Correct","✗ Check again"),"✗ Not a number"))) -> ◯ Not attempted | H10: =XIRR(B9:B18,A9:A18) — values first, dates second, no rate needed. | I10: =XIRR($B$9:$B$18,$A$9:$A$18) -> 0.17614123
A11: 45618 | B11: -300000 | D11: 3 | E11: What would plain IRR say if you ignored the dates? (You are meant to see the difference.) | G11: =IF(ISBLANK(F11),"◯ Not attempted",IF(NOT(_xlfn.ISFORMULA(F11)),"✎ Use a formula",IF(ISNUMBER(F11),IF(ABS(F11-$I$11)<0.0001,"✓ Correct","✗ Check again"),"✗ Not a number"))) -> ◯ Not attempted | H11: =IRR(B9:B18). | I11: =IRR($B$9:$B$18) -> 0.050759172
A12: 45702 | B12: -200000 | D12: 4 | E12: Total invested (the sum of the negative flows). | G12: =IF(ISBLANK(F12),"◯ Not attempted",IF(NOT(_xlfn.ISFORMULA(F12)),"✎ Use a formula",IF(ISNUMBER(F12),IF(ABS(F12-$I$12)<0.005,"✓ Correct","✗ Check again"),"✗ Not a number"))) -> ◯ Not attempted | H12: SUMIF(range,"<0") — with no third argument it sums the range it tested. | I12: =-1400000 -> -1400000
A13: 45811 | B13: 180000 | D13: 5 | E13: Total received (the sum of the positive flows). | G13: =IF(ISBLANK(F13),"◯ Not attempted",IF(NOT(_xlfn.ISFORMULA(F13)),"✎ Use a formula",IF(ISNUMBER(F13),IF(ABS(F13-$I$13)<0.005,"✓ Correct","✗ Check again"),"✗ Not a number"))) -> ◯ Not attempted | H13: SUMIF(range,">0"). | I13: =1865000 -> 1865000
A14: 45927 | B14: -150000 | D14: 6 | E14: Absolute return: total received ÷ total invested, minus 1. | G14: =IF(ISBLANK(F14),"◯ Not attempted",IF(NOT(_xlfn.ISFORMULA(F14)),"✎ Use a formula",IF(ISNUMBER(F14),IF(ABS(F14-$I$14)<0.0001,"✓ Correct","✗ Check again"),"✗ Not a number"))) -> ◯ Not attempted | H14: Received ÷ invested − 1. Remember the invested total is negative, so negate it. | I14: =0.332143 -> 0.332143
A15: 46031 | B15: 420000 | D15: 7 | E15: How many days span the first and last cash flow? | G15: =IF(ISBLANK(F15),"◯ Not attempted",IF(NOT(_xlfn.ISFORMULA(F15)),"✎ Use a formula",IF(ISNUMBER(F15),IF(ABS(F15-$I$15)<0.005,"✓ Correct","✗ Check again"),"✗ Not a number"))) -> ◯ Not attempted | H15: Dates are just numbers — subtract them. | I15: =1020 -> 1020
A16: 46160 | B16: 310000 | D16: 8 | E16: Proof: XNPV calculated at the XIRR. It must be zero. | G16: =IF(ISBLANK(F16),"◯ Not attempted",IF(NOT(_xlfn.ISFORMULA(F16)),"✎ Use a formula",IF(ISNUMBER(F16),IF(ABS(F16-$I$16)<1,"✓ Correct","✗ Check again"),"✗ Not a number"))) -> ◯ Not attempted | H16: Feed the XIRR straight into XNPV as the rate. | I16: =0 -> 0
A17: 46267 | B17: 265000
A18: 46417 | B18: 690000

Sheet L6 Boss round — prepay or inves
A1: LESSON 6 · BOSS ROUND — PREPAY OR INVEST
A2: ★★★★★ The ₹3 lakh question, answered with arithmetic instead of opinions.
A3: CONCEPT · You have a surplus. Put it into the loan and you save interest at the loan rate, guaranteed and tax-free. Invest it and you might earn more, with risk. The honest comparison is: rupees of interest saved versus rupees of investment gain, over the SAME number of months. Everything here comes from five blue cells — change any of them and the recommendation changes with it.
A6: Outstanding | B6: 1850000 | D6: Rate p.a. | E6: 0.089 | G6: Months left | H6: 144 | J6: Invest return | K6: 0.115 | M6: Surplus | N6: 300000
A8: Prepay amount | B8: New tenure (months) | C8: Months saved | D8: Interest saved | F8: # | G8: Task | H8: Your answer | I8: Check | J8: Hint
A9: 100000 | F9: 1 | G9: The EMI on the outstanding loan. | I9: =IF(ISBLANK(H9),"◯ Not attempted",IF(NOT(_xlfn.ISFORMULA(H9)),"✎ Use a formula",IF(ISNUMBER(H9),IF(ABS(H9-$K$9)<0.05,"✓ Correct","✗ Check again"),"✗ Not a number"))) -> ◯ Not attempted | J9: =-PMT($E$6/12,$H$6,$B$6) — months are already months, so no ×12 here. | K9: =-PMT($E$6/12,$H$6,$B$6) -> 20949.513 | L9: =NPER($E$6/12,PMT($E$6/12,$H$6,$B$6),$B$6-A9) -> 130.78203 | M9: =$H$6-NPER($E$6/12,PMT($E$6/12,$H$6,$B$6),$B$6-A9) -> 13.217972 | N9: =-PMT($E$6/12,$H$6,$B$6)*($H$6-NPER($E$6/12,PMT($E$6/12,$H$6,$B$6),$B$6-A9))-A9 -> 176910.09
A10: 200000 | F10: 2 | G10: Fill New tenure: how many months the loan would run if you prepaid each amount today and kept the same EMI. | H10: → fill column B | I10: =IF(COUNTA($B$9:$B$14)=0,"◯ Not attempted",IF(NOT(_xlfn.ISFORMULA(B9)),"✎ Use a formula",IFERROR(IF(SUMPRODUCT(--(ABS($B$9:$B$14-$L$9:$L$14)<0.02))=ROWS($B$9:$B$14),"✓ Correct","✗ "&(ROWS($B$9:$B$14)-SUMPRODUCT(--(ABS($B$9:$B$14-$L$9:$L$14)<0.02)))&" rows differ"),"✗ Check the column"))) -> ◯ Not attempted | J10: =NPER($E$6/12,-$H$9,$B$6-A9) — the payment is negative, the balance is positive. | L10: =NPER($E$6/12,PMT($E$6/12,$H$6,$B$6),$B$6-A10) -> 118.74098 | M10: =$H$6-NPER($E$6/12,PMT($E$6/12,$H$6,$B$6),$B$6-A10) -> 25.259025 | N10: =-PMT($E$6/12,$H$6,$B$6)*($H$6-NPER($E$6/12,PMT($E$6/12,$H$6,$B$6),$B$6-A10))-A10 -> 329164.27
A11: 300000 | F11: 3 | G11: Fill Months saved = original months left − new tenure. | H11: → fill column C | I11: =IF(COUNTA($C$9:$C$14)=0,"◯ Not attempted",IF(NOT(_xlfn.ISFORMULA(C9)),"✎ Use a formula",IFERROR(IF(SUMPRODUCT(--(ABS($C$9:$C$14-$M$9:$M$14)<0.02))=ROWS($C$9:$C$14),"✓ Correct","✗ "&(ROWS($C$9:$C$14)-SUMPRODUCT(--(ABS($C$9:$C$14-$M$9:$M$14)<0.02)))&" rows differ"),"✗ Check the column"))) -> ◯ Not attempted | J11: =$H$6-B9 | L11: =NPER($E$6/12,PMT($E$6/12,$H$6,$B$6),$B$6-A11) -> 107.68429 | M11: =$H$6-NPER($E$6/12,PMT($E$6/12,$H$6,$B$6),$B$6-A11) -> 36.315713 | N11: =-PMT($E$6/12,$H$6,$B$6)*($H$6-NPER($E$6/12,PMT($E$6/12,$H$6,$B$6),$B$6-A11))-A11 -> 460796.5
A12: 400000 | F12: 4 | G12: Fill Interest saved = EMI × months saved − the prepayment. | H12: → fill column D | I12: =IF(COUNTA($D$9:$D$14)=0,"◯ Not attempted",IF(NOT(_xlfn.ISFORMULA(D9)),"✎ Use a formula",IFERROR(IF(SUMPRODUCT(--(ABS($D$9:$D$14-$N$9:$N$14)<0.5))=ROWS($D$9:$D$14),"✓ Correct","✗ "&(ROWS($D$9:$D$14)-SUMPRODUCT(--(ABS($D$9:$D$14-$N$9:$N$14)<0.5)))&" rows differ"),"✗ Check the column"))) -> ◯ Not attempted | J12: =$I$9*C9-A9 — you stop paying the EMI for those months, but you did hand over the prepayment. | L12: =NPER($E$6/12,PMT($E$6/12,$H$6,$B$6),$B$6-A12) -> 97.463111 | M12: =$H$6-NPER($E$6/12,PMT($E$6/12,$H$6,$B$6),$B$6-A12) -> 46.536889 | N12: =-PMT($E$6/12,$H$6,$B$6)*($H$6-NPER($E$6/12,PMT($E$6/12,$H$6,$B$6),$B$6-A12))-A12 -> 574925.18
A13: 500000 | F13: 5 | G13: Interest saved if you prepay exactly the surplus in N6. | I13: =IF(ISBLANK(H13),"◯ Not attempted",IF(NOT(_xlfn.ISFORMULA(H13)),"✎ Use a formula",IF(ISNUMBER(H13),IF(ABS(H13-$K$13)<0.5,"✓ Correct","✗ Check again"),"✗ Not a number"))) -> ◯ Not attempted | J13: The same formula as the column, with N6 in place of the prepayment amount. | K13: =-PMT($E$6/12,$H$6,$B$6)*($H$6-NPER($E$6/12,PMT($E$6/12,$H$6,$B$6),$B$6-$N$6))-$N$6 -> 460796.5 | L13: =NPER($E$6/12,PMT($E$6/12,$H$6,$B$6),$B$6-A13) -> 87.959996 | M13: =$H$6-NPER($E$6/12,PMT($E$6/12,$H$6,$B$6),$B$6-A13) -> 56.040004 | N13: =-PMT($E$6/12,$H$6,$B$6)*($H$6-NPER($E$6/12,PMT($E$6/12,$H$6,$B$6),$B$6-A13))-A13 -> 674010.8
A14: 750000 | F14: 6 | G14: What the surplus would grow to if you INVESTED it instead, for the original months left. | I14: =IF(ISBLANK(H14),"◯ Not attempted",IF(NOT(_xlfn.ISFORMULA(H14)),"✎ Use a formula",IF(ISNUMBER(H14),IF(ABS(H14-$K$14)<0.5,"✓ Correct","✗ Check again"),"✗ Not a number"))) -> ◯ Not attempted | J14: =FV($K$6/12,$H$6,0,-$N$6) — no monthly addition, just one lump sum compounding. | K14: =FV($K$6/12,$H$6,0,-$N$6) -> 1184661 | L14: =NPER($E$6/12,PMT($E$6/12,$H$6,$B$6),$B$6-A14) -> 66.766764 | M14: =$H$6-NPER($E$6/12,PMT($E$6/12,$H$6,$B$6),$B$6-A14) -> 77.233236 | N14: =-PMT($E$6/12,$H$6,$B$6)*($H$6-NPER($E$6/12,PMT($E$6/12,$H$6,$B$6),$B$6-A14))-A14 -> 867998.7
F15: 7 | G15: The investment GAIN (future value minus the surplus you put in). | I15: =IF(ISBLANK(H15),"◯ Not attempted",IF(NOT(_xlfn.ISFORMULA(H15)),"✎ Use a formula",IF(ISNUMBER(H15),IF(ABS(H15-$K$15)<0.5,"✓ Correct","✗ Check again"),"✗ Not a number"))) -> ◯ Not attempted | J15: Future value − N6. | K15: =FV($K$6/12,$H$6,0,-$N$6)-$N$6 -> 884660.98
F16: 8 | G16: The verdict: "Prepay" if the interest saved beats the investment gain, otherwise "Invest". | I16: =IF(ISBLANK(H16),"◯ Not attempted",IF(NOT(_xlfn.ISFORMULA(H16)),"✎ Use a formula",IF(UPPER(TRIM(H16&""))=UPPER(TRIM($K$16&"")),"✓ Correct","✗ Check again"))) -> ◯ Not attempted | J16: IF, comparing your answer to task 5 against your answer to task 7. | K16: =IF(-PMT($E$6/12,$H$6,$B$6)*($H$6-NPER($E$6/12,PMT($E$6/12,$H$6,$B$6),$B$6-$N$6))-$N$6>FV($K$6/12,$H$6,0,-$N$6)-$N$6,"Prepay","Invest") -> Invest
F17: 9 | G17: The break-even investment return (annual) at which both options are worth exactly the same. | I17: =IF(ISBLANK(H17),"◯ Not attempted",IF(NOT(_xlfn.ISFORMULA(H17)),"✎ Use a formula",IF(ISNUMBER(H17),IF(ABS(H17-$K$17)<0.0002,"✓ Correct","✗ Check again"),"✗ Not a number"))) -> ◯ Not attempted | J17: RATE(months, 0, −surplus, surplus + interest saved) × 12 — what return turns the surplus into the same gain? | K17: =RATE($H$6,0,-$N$6,$N$6+(-PMT($E$6/12,$H$6,$B$6)*($H$6-NPER($E$6/12,PMT($E$6/12,$H$6,$B$6),$B$6-$N$6))-$N$6))*12 -> 0.077799735

Sheet Solutions
A1: SOLUTIONS & OTHER WAYS — open only after you have tried
A2: Model answers are shapes, not the only answer. If your formula gives the same result, it is right — compare the logic.
A4: L1 EMI and the cost of a longer ★★
A5: # | B5: Task | C5: Answer cell | D5: Model formula | E5: Other ways | F5: Why it works
A6: 1 | B6: Fill EMI for every bank, rounded to whole rupees, on the loan amount in B6. | C6: column D | D6: =ROUND(-PMT(B9/12,C9*12,$B$6),0) (row 9, then fill down) | E6: =ROUND(PMT(B9/12,C9*12,-$B$6),0) — a negative loan amount flips the sign instead =ROUND($B$6*(B9/12)/(1-(1+B9/12)^(-C9*12)),0) — the textbook EMI formula, if you want to see the machinery | F6: The classic mistake is PMT(B9, C9, ...) with an annual rate and a count of years. It gives an answer, and the answer is nonsense.
A7: 2 | B7: Fill Total repaid = EMI × Years × 12. | C7: column E | D7: =D9*C9*12 (row 9, then fill down) | F7: The EMI is what you can afford. This is what it actually costs.
A8: 3 | B8: The lowest EMI on offer. | C8: I11 | D8: =MIN($D$9:$D$16) | E8: =SMALL(D9:D16,1)
A9: 4 | B9: Which bank has the lowest EMI? | C9: I12 | D9: =INDEX($A$9:$A$16,MATCH(MIN($D$9:$D$16),$D$9:$D$16,0)) | E9: =XLOOKUP(MIN(D9:D16),D9:D16,A9:A16) | F9: The lowest EMI and the cheapest loan are almost never the same offer — look at the next two answers.
A10: 5 | B10: Which bank costs the LEAST in total repayment? | C10: I13 | D10: =INDEX($A$9:$A$16,MATCH(MIN($E$9:$E$16),$E$9:$E$16,0)) | F10: A 30-year loan at a lower rate can still cost far more than a 15-year loan at a higher one.
A11: 6 | B11: The gap between the most expensive and the cheapest offer, in total repayment. | C11: I14 | D11: =MAX($E$9:$E$16)-MIN($E$9:$E$16) | F11: This is the number worth negotiating over.
A12: 7 | B12: How many offers have an EMI below ₹25,000? | C12: I15 | D12: =COUNTIF($D$9:$D$16,"<25000")
A14: L2 The amortisation schedule ★★★
A15: # | B15: Task | C15: Answer cell | D15: Model formula | E15: Other ways | F15: Why it works
A16: 1 | B16: The EMI on this loan. Do NOT round it — the schedule must tie to the paisa. | C16: I9 | D16: =-PMT($E$6/12,$H$6*12,$B$6) | F16: Round the EMI and the last month will not land on zero. Banks solve that by adjusting the final instalment.
A17: 2 | B17: Fill Opening: the loan amount in month 1, then last month's closing balance. | C17: column B | D17: =$B$6 in the first row, then =E9 (the row above's closing) filled down | E17: =-FV($E$6/12,A9-1,PMT($E$6/12,$H$6*12,$B$6),$B$6) — the closed form: balance after A9−1 payments, no chain at all | F17: A chain is easy to read and easy to break. A closed form survives sorting, filtering and inserted rows.
A18: 3 | B18: Fill Interest = opening balance × monthly rate. | C18: column C | D18: =B9*$E$6/12 (row 9, then fill down) | E18: =-IPMT($E$6/12,A9,$H$6*12,$B$6) — the interest part of instalment number A9 | F18: Interest is charged on what you still owe, which is why it shrinks every month.
A19: 4 | B19: Fill Principal = EMI − Interest. Point at your EMI answer so one cell drives the whole table. | C19: column D | D19: =$I$9-C9 (row 9, then fill down) | E19: =-PPMT($E$6/12,A9,$H$6*12,$B$6) | F19: Never retype a number that already exists in a cell. Point at it, and one correction fixes everything.
A20: 5 | B20: Fill Closing = Opening − Principal. | C20: column E | D20: =B9-D9 (row 9, then fill down) | E20: =B9+C9-$I$9 — opening plus interest minus EMI says the same thing
A21: 6 | B21: Total interest paid over the whole loan. | C21: I14 | D21: =SUM($C$9:$C$32) | E21: =-CUMIPMT($E$6/12,$H$6*12,$B$6,1,$H$6*12,0) — cumulative interest between any two instalment numbers =$I$9*$H$6*12-$B$6 — total paid minus the amount borrowed
A22: 7 | B22: The closing balance in the final month. It must be zero. | C22: I15 | D22: =E32 | F22: If it is not zero, your chain has a broken link — and you now know exactly where to look.
A23: 8 | B23: In which month does the PRINCIPAL part first become larger than the INTEREST part? | C23: I16 | D23: =SUMPRODUCT(--($C$9:$C$32>=$D$9:$D$32))+1 | F23: On a 20-year home loan that crossover takes years — which is the real argument for prepaying early.
A25: L3 Goals, SIPs and compounding ★★★
A26: # | B26: Task | C26: Answer cell | D26: Model formula | E26: Other ways | F26: Why it works
A27: 1 | B27: Fill Monthly SIP: the amount to invest every month to reach each target, at the return in B6. | C27: column D | D27: =-PMT($B$6/12,C9*12,0,B9) (row 9, then fill down) | E27: =B9*($B$6/12)/((1+$B$6/12)^(C9*12)-1) — the future-value-of-an-annuity formula, rearranged | F27: The third argument of PMT is the present value. Leave it 0 for a pure SIP; use it when you already have a corpus.
A28: 2 | B28: What is a ₹10,000 monthly SIP worth after 15 years at the return in B6? | C28: H10 | D28: =FV($B$6/12,15*12,-10000)
A29: 3 | B29: Of that value, how much is growth rather than your own money? | C29: H11 | D29: =FV($B$6/12,15*12,-10000)-10000*15*12 | F29: Eighteen lakh in, and the rest is compounding. That difference is the entire argument for starting early.
A30: 4 | B30: How many MONTHS to reach ₹25,00,000 saving ₹15,000 a month? Round up to a whole month. | C30: H12 | D30: =ROUNDUP(NPER($B$6/12,-15000,0,2500000),0)
A31: 5 | B31: What ANNUAL return would turn ₹5,000 a month for 10 years into ₹12,00,000? | C31: H13 | D31: =RATE(120,-5000,0,1200000)*12 | E31: =(1+RATE(120,-5000,0,1200000))^12-1 — the compounded annual equivalent, slightly higher | F31: RATE returns the rate for one period. Forgetting to annualise it is the most common error in this whole family.
A32: 6 | B32: What single lump sum today becomes ₹50,00,000 in 12 years at the return in B6? | C32: H14 | D32: =-PV($B$6,12,0,5000000)
A33: 7 | B33: Total of all the monthly SIPs in the table. | C33: H15 | D33: =SUM($D$9:$D$15) | F33: This is the monthly number that decides whether the plan is real or a wish list.
A34: 8 | B34: Which goal needs the largest monthly SIP? | C34: H16 | D34: =INDEX($A$9:$A$15,MATCH(MAX($D$9:$D$15),$D$9:$D$15,0)) | F34: Not always the biggest target — a short horizon is far more expensive than a big number.
A36: L4 NPV, IRR and payback ★★★★
A37: # | B37: Task | C37: Answer cell | D37: Model formula | E37: Other ways | F37: Why it works
A38: 1 | B38: Fill Cumulative: the running total of cash flows from year 0 down. | C38: column C | D38: =SUM($B$9:B9) (row 9, then fill down) | E38: =C8+B9 with a 0 above — the chain version =SUMIF($A$9:A9,"<="&A9,$B$9:B9) — overkill, but it works | F38: An expanding range is the cleanest running total in Excel. The $ goes on the first cell only.
A39: 2 | B39: NPV of the project at the discount rate in B6. | C39: G10 | D39: =NPV($B$6,B10:B16)+B9 | E39: =SUMPRODUCT(B9:B16/(1+$B$6)^A9:A16) — discount each year yourself; this one is unambiguous about timing | F39: Putting year 0 inside NPV discounts it by a year it never waited. It is the single most common NPV bug.
A40: 3 | B40: The project's IRR. | C40: G11 | D40: =IRR($B$9:$B$16) | F40: IRR needs at least one negative and one positive flow, or it returns #NUM!.
A41: 4 | B41: In which YEAR does the cumulative cash flow first turn positive? | C41: G12 | D41: =COUNTIF($C$9:$C$16,"<0") | E41: =MATCH(TRUE,INDEX(C9:C16>0,0),0)-1
A42: 5 | B42: Present value of the INFLOWS only (years 1 to 7). | C42: G13 | D42: =NPV($B$6,B10:B16)
A43: 6 | B43: Profitability index = PV of inflows ÷ the initial outflow (as a positive number). | C43: G14 | D43: =NPV($B$6,B10:B16)/-B9 | F43: Above 1.0 the project creates value. It is NPV expressed per rupee invested, which lets you rank projects of different sizes.
A44: 7 | B44: Proof: NPV calculated AT the IRR. It must be zero. | C44: G15 | D44: =NPV(IRR($B$9:$B$16),B10:B16)+B9 | F44: This is the definition of IRR, and proving it once means you will never confuse the two again.
...
