Workbook

Sheet Start Here
A1: EXCEL LAB · 01 FOUNDATIONS BOOTCAMP
A2: Six lessons from your first SUM to a mixed boss round: totals, the $ sign, IF logic, rounding, text cleanup. Every answer cell marks itself.
A4: HOW TO USE THIS WORKBOOK
A5: 1 | B5: Work through the lessons in order — each one is harder than the last (★ to ★★★★★).
A6: 2 | B6: Read the Concept box at the top of each lesson, then look at the data.
A7: 3 | B7: Type a FORMULA in each yellow cell. The Check column marks it ✓ or ✗ instantly.
A8: 4 | B8: Blue cells are inputs. Change them and watch every answer update — that is how you know your formula is really right.
A9: 5 | B9: Stuck? Read the Hint. Still stuck? The Solutions sheet shows the model answer and other ways to do it.
A11: COLOUR CODE
B12: Yellow — your answer goes here (always a formula)
B13: Blue — an input you can change
B14: ✓ Correct — marked automatically
B15: ✗ Check again — the result does not match
B16: ✎ You typed a value — replace it with a formula
A18: # | B18: Lesson | C18: Difficulty | D18: Tasks | E18: Solved | F18: Progress
A19: 1 | B19: L1 Totals and counts | C19: ★☆☆☆☆ | D19: 6 | E19: =COUNTIF('L1 Totals and counts'!J9:J14,"✓*") -> 0 | F19: =IFERROR(E19/D19,0) -> 0
A20: 2 | B20: L2 References and the $ sign | C20: ★★☆☆☆ | D20: 4 | E20: =COUNTIF('L2 References and the $ sign'!J9:J12,"✓*") -> 0 | F20: =IFERROR(E20/D20,0) -> 0
A21: 3 | B21: L3 IF logic | C21: ★★☆☆☆ | D21: 5 | E21: =COUNTIF('L3 IF logic'!K9:K13,"✓*") -> 0 | F21: =IFERROR(E21/D21,0) -> 0
A22: 4 | B22: L4 Rounding and percentages | C22: ★★★☆☆ | D22: 6 | E22: =COUNTIF('L4 Rounding and percentages'!K9:K14,"✓*") -> 0 | F22: =IFERROR(E22/D22,0) -> 0
A23: 5 | B23: L5 Text cleanup | C23: ★★★☆☆ | D23: 5 | E23: =COUNTIF('L5 Text cleanup'!K9:K13,"✓*") -> 0 | F23: =IFERROR(E23/D23,0) -> 0
A24: 6 | B24: L6 Boss round — foundations | C24: ★★★★☆ | D24: 5 | E24: =COUNTIF('L6 Boss round — foundations'!K9:K13,"✓*") -> 0 | F24: =IFERROR(E24/D24,0) -> 0
B25: OVERALL | D25: =SUM(D19:D24) -> 31 | E25: =SUM(E19:E24) -> 0 | F25: =IFERROR(E25/D25,0) -> 0
A27: Excel Lab — created by Pranay · excel-lab-by-pranay.vercel.app · free for every student

Sheet L1 Totals and counts
A1: LESSON 1 · TOTALS AND COUNTS
A2: ★☆☆☆☆ Add, count and average a sales register — the five functions you'll use every day.
A3: CONCEPT · SUM adds numbers, COUNT counts numbers, COUNTA counts anything that isn't empty, AVERAGE is SUM ÷ COUNT, MAX and MIN find the extremes. Every one takes a range like E9:E38. Select the range with the mouse or type it; press Enter to finish.
A8: Invoice | B8: Date | C8: Party | D8: State | E8: Taxable | G8: # | H8: Task | I8: Your answer | J8: Check | K8: Hint
A9: INV-0001 | B9: 45796 | C9: Patel & Co | D9: Delhi | E9: 191500 | G9: 1 | H9: Total taxable value of all invoices. | J9: =IF(ISBLANK(I9),"◯ Not attempted",IF(NOT(_xlfn.ISFORMULA(I9)),"✎ Use a formula",IF(ISNUMBER(I9),IF(ABS(I9-$L$9)<0.005,"✓ Correct","✗ Check again"),"✗ Not a number"))) -> ◯ Not attempted | K9: SUM over the Taxable column. | L9: =SUM($E$9:$E$38) -> 5962500
A10: INV-0002 | B10: 45823 | C10: ABC Traders | D10: Delhi | E10: 117500 | G10: 2 | H10: How many invoices are in the register? Count the invoice numbers. | J10: =IF(ISBLANK(I10),"◯ Not attempted",IF(NOT(_xlfn.ISFORMULA(I10)),"✎ Use a formula",IF(ISNUMBER(I10),IF(ABS(I10-$L$10)<0.005,"✓ Correct","✗ Check again"),"✗ Not a number"))) -> ◯ Not attempted | K10: Invoice numbers are text, so COUNT returns 0. COUNTA counts non-empty cells. | L10: =COUNTA($A$9:$A$38) -> 30
A11: INV-0003 | B11: 45858 | C11: Patel & Co | D11: Karnataka | E11: 256500 | G11: 3 | H11: Average taxable value per invoice. | J11: =IF(ISBLANK(I11),"◯ Not attempted",IF(NOT(_xlfn.ISFORMULA(I11)),"✎ Use a formula",IF(ISNUMBER(I11),IF(ABS(I11-$L$11)<0.005,"✓ Correct","✗ Check again"),"✗ Not a number"))) -> ◯ Not attempted | K11: AVERAGE over the Taxable column. | L11: =AVERAGE($E$9:$E$38) -> 198750
A12: INV-0004 | B12: 45892 | C12: Patel & Co | D12: Karnataka | E12: 232000 | G12: 4 | H12: The largest single invoice. | J12: =IF(ISBLANK(I12),"◯ Not attempted",IF(NOT(_xlfn.ISFORMULA(I12)),"✎ Use a formula",IF(ISNUMBER(I12),IF(ABS(I12-$L$12)<0.005,"✓ Correct","✗ Check again"),"✗ Not a number"))) -> ◯ Not attempted | K12: MAX finds the biggest number. | L12: =MAX($E$9:$E$38) -> 368500
A13: INV-0005 | B13: 45903 | C13: Kiran Agencies | D13: Gujarat | E13: 90000 | G13: 5 | H13: The smallest single invoice. | J13: =IF(ISBLANK(I13),"◯ Not attempted",IF(NOT(_xlfn.ISFORMULA(I13)),"✎ Use a formula",IF(ISNUMBER(I13),IF(ABS(I13-$L$13)<0.005,"✓ Correct","✗ Check again"),"✗ Not a number"))) -> ◯ Not attempted | K13: MIN finds the smallest number. | L13: =MIN($E$9:$E$38) -> 11000
A14: INV-0006 | B14: 45933 | C14: Orbit Systems | D14: Delhi | E14: 195500 | G14: 6 | H14: How many invoices are above ₹1,00,000? | J14: =IF(ISBLANK(I14),"◯ Not attempted",IF(NOT(_xlfn.ISFORMULA(I14)),"✎ Use a formula",IF(ISNUMBER(I14),IF(ABS(I14-$L$14)<0.005,"✓ Correct","✗ Check again"),"✗ Not a number"))) -> ◯ Not attempted | K14: COUNTIF(range,">100000") — the condition goes in quotes. | L14: =COUNTIF($E$9:$E$38,">100000") -> 23
A15: INV-0007 | B15: 45968 | C15: Orbit Systems | D15: Karnataka | E15: 130000
A16: INV-0008 | B16: 46012 | C16: Vaibhav Textiles | D16: Tamil Nadu | E16: 114500
A17: INV-0009 | B17: 45750 | C17: Vaibhav Textiles | D17: Tamil Nadu | E17: 163500
A18: INV-0010 | B18: 45784 | C18: Shree Enterprises | D18: Delhi | E18: 356000
A19: INV-0011 | B19: 45819 | C19: Bharat Electricals | D19: Karnataka | E19: 210000
A20: INV-0012 | B20: 45864 | C20: Vaibhav Textiles | D20: Gujarat | E20: 224500
A21: INV-0013 | B21: 45872 | C21: Vaibhav Textiles | D21: Tamil Nadu | E21: 11000
A22: INV-0014 | B22: 45915 | C22: Patel & Co | D22: Delhi | E22: 56000
A23: INV-0015 | B23: 45942 | C23: ABC Traders | D23: Karnataka | E23: 368500
A24: INV-0016 | B24: 45973 | C24: ABC Traders | D24: Karnataka | E24: 296500
A25: INV-0017 | B25: 46018 | C25: Nova Industries | D25: Maharashtra | E25: 229000
A26: INV-0018 | B26: 45753 | C26: Kiran Agencies | D26: Maharashtra | E26: 85000
... A38: INV-0030 | B38: 45856 | C38: Sagar Metals | D38: Karnataka | E38: 245000

Sheet L2 References and the $ sign
A1: LESSON 2 · REFERENCES AND THE $ SIGN
A2: ★★☆☆☆ Write one formula, fill it down, and keep the tax rate locked in place.
A3: CONCEPT · A1 is a relative reference — it moves when you copy it. $B$6 is absolute — it stays put. Press F4 while typing a reference to add the dollar signs. Put the formula in the first yellow row, then double-click the fill handle (bottom-right corner) to copy it down.
A6: GST rate | B6: 0.18
A8: Invoice | B8: Party | C8: Taxable | D8: GST Amount | E8: Invoice Total | G8: # | H8: Task | I8: Your answer | J8: Check | K8: Hint
A9: INV-0001 | B9: ABC Traders | C9: 54250 | G9: 1 | H9: Fill GST Amount for every invoice: Taxable × the GST rate in B6, rounded to 2 decimals. | I9: → fill column D | J9: =IF(COUNTA($D$9:$D$33)=0,"◯ Not attempted",IF(NOT(_xlfn.ISFORMULA(D9)),"✎ Use a formula",IFERROR(IF(SUMPRODUCT(--(ABS($D$9:$D$33-$M$9:$M$33)<0.01))=ROWS($D$9:$D$33),"✓ Correct","✗ "&(ROWS($D$9:$D$33)-SUMPRODUCT(--(ABS($D$9:$D$33-$M$9:$M$33)<0.01)))&" rows differ"),"✗ Check the column"))) -> ◯ Not attempted | K9: =ROUND(C9*$B$6,2) — the $ keeps B6 fixed as you fill down. | M9: =ROUND(C9*$B$6,2) -> 9765 | N9: =C9+ROUND(C9*$B$6,2) -> 64015
A10: INV-0002 | B10: Kiran Agencies | C10: 178750 | G10: 2 | H10: Fill Invoice Total: Taxable + GST Amount. | I10: → fill column E | J10: =IF(COUNTA($E$9:$E$33)=0,"◯ Not attempted",IF(NOT(_xlfn.ISFORMULA(E9)),"✎ Use a formula",IFERROR(IF(SUMPRODUCT(--(ABS($E$9:$E$33-$N$9:$N$33)<0.01))=ROWS($E$9:$E$33),"✓ Correct","✗ "&(ROWS($E$9:$E$33)-SUMPRODUCT(--(ABS($E$9:$E$33-$N$9:$N$33)<0.01)))&" rows differ"),"✗ Check the column"))) -> ◯ Not attempted | K10: =C9+D9, filled down. | M10: =ROUND(C10*$B$6,2) -> 32175 | N10: =C10+ROUND(C10*$B$6,2) -> 210925
A11: INV-0003 | B11: Deccan Supplies | C11: 28000 | G11: 3 | H11: Total GST payable for the register. | J11: =IF(ISBLANK(I11),"◯ Not attempted",IF(NOT(_xlfn.ISFORMULA(I11)),"✎ Use a formula",IF(ISNUMBER(I11),IF(ABS(I11-$L$11)<0.005,"✓ Correct","✗ Check again"),"✗ Not a number"))) -> ◯ Not attempted | K11: SUM your GST column. | L11: =SUMPRODUCT(ROUND($C$9:$C$33*$B$6,2)) -> 520245 | M11: =ROUND(C11*$B$6,2) -> 5040 | N11: =C11+ROUND(C11*$B$6,2) -> 33040
A12: INV-0004 | B12: Kiran Agencies | C12: 244750 | G12: 4 | H12: Change B6 to 12% and back to 18%. Now: the total of all Invoice Totals. | J12: =IF(ISBLANK(I12),"◯ Not attempted",IF(NOT(_xlfn.ISFORMULA(I12)),"✎ Use a formula",IF(ISNUMBER(I12),IF(ABS(I12-$L$12)<0.005,"✓ Correct","✗ Check again"),"✗ Not a number"))) -> ◯ Not attempted | K12: If your answers changed when you edited B6, your references are right. | L12: =SUM($C$9:$C$33)+SUMPRODUCT(ROUND($C$9:$C$33*$B$6,2)) -> 3410495 | M12: =ROUND(C12*$B$6,2) -> 44055 | N12: =C12+ROUND(C12*$B$6,2) -> 288805
A13: INV-0005 | B13: Nova Industries | C13: 69000 | M13: =ROUND(C13*$B$6,2) -> 12420 | N13: =C13+ROUND(C13*$B$6,2) -> 81420
A14: INV-0006 | B14: Orbit Systems | C14: 57250 | M14: =ROUND(C14*$B$6,2) -> 10305 | N14: =C14+ROUND(C14*$B$6,2) -> 67555
A15: INV-0007 | B15: Vaibhav Textiles | C15: 33500 | M15: =ROUND(C15*$B$6,2) -> 6030 | N15: =C15+ROUND(C15*$B$6,2) -> 39530
A16: INV-0008 | B16: Sagar Metals | C16: 209750 | M16: =ROUND(C16*$B$6,2) -> 37755 | N16: =C16+ROUND(C16*$B$6,2) -> 247505
A17: INV-0009 | B17: Deccan Supplies | C17: 67500 | M17: =ROUND(C17*$B$6,2) -> 12150 | N17: =C17+ROUND(C17*$B$6,2) -> 79650
A18: INV-0010 | B18: Shree Enterprises | C18: 76750 | M18: =ROUND(C18*$B$6,2) -> 13815 | N18: =C18+ROUND(C18*$B$6,2) -> 90565
A19: INV-0011 | B19: Bharat Electricals | C19: 232000 | M19: =ROUND(C19*$B$6,2) -> 41760 | N19: =C19+ROUND(C19*$B$6,2) -> 273760
A20: INV-0012 | B20: Nova Industries | C20: 8000 | M20: =ROUND(C20*$B$6,2) -> 1440 | N20: =C20+ROUND(C20*$B$6,2) -> 9440
A21: INV-0013 | B21: ABC Traders | C21: 167000 | M21: =ROUND(C21*$B$6,2) -> 30060 | N21: =C21+ROUND(C21*$B$6,2) -> 197060
A22: INV-0014 | B22: Vaibhav Textiles | C22: 224250 | M22: =ROUND(C22*$B$6,2) -> 40365 | N22: =C22+ROUND(C22*$B$6,2) -> 264615
A23: INV-0015 | B23: Nandini Foods | C23: 122250 | M23: =ROUND(C23*$B$6,2) -> 22005 | N23: =C23+ROUND(C23*$B$6,2) -> 144255
A24: INV-0016 | B24: Bharat Electricals | C24: 150750 | M24: =ROUND(C24*$B$6,2) -> 27135 | N24: =C24+ROUND(C24*$B$6,2) -> 177885
... A33: INV-0025 | B33: Deccan Supplies | C33: 178750 | M33: =ROUND(C33*$B$6,2) -> 32175 | N33: =C33+ROUND(C33*$B$6,2) -> 210925

Sheet L3 IF logic
A1: LESSON 3 · IF LOGIC
A2: ★★☆☆☆ Make the sheet decide: flag overdue invoices and prioritise the risky ones.
A3: CONCEPT · IF(test, value_if_true, value_if_false). The test is a comparison like D9>90. Text results go in double quotes: "Overdue". AND(test1,test2) is TRUE only when both are true — put it inside IF for two conditions.
A8: Invoice | B8: Party | C8: Amount | D8: Days | E8: Status | F8: Priority | H8: # | I8: Task | J8: Your answer | K8: Check | L8: Hint
A9: INV-0001 | B9: Deccan Supplies | C9: 216000 | D9: 105 | H9: 1 | I9: Fill Status: "Overdue" if Days is more than 90, otherwise "Current". | J9: → fill column E | K9: =IF(COUNTA($E$9:$E$38)=0,"◯ Not attempted",IF(NOT(_xlfn.ISFORMULA(E9)),"✎ Use a formula",IFERROR(IF(SUMPRODUCT(--(UPPER(TRIM($E$9:$E$38&""))=UPPER(TRIM($N$9:$N$38&""))))=ROWS($E$9:$E$38),"✓ Correct","✗ "&(ROWS($E$9:$E$38)-SUMPRODUCT(--(UPPER(TRIM($E$9:$E$38&""))=UPPER(TRIM($N$9:$N$38&"")))))&" rows differ"),"✗ Check the column"))) -> ◯ Not attempted | L9: =IF(D9>90,"Overdue","Current") | N9: =IF(D9>90,"Overdue","Current") -> Overdue | O9: =IF(AND(C9>200000,D9>60),"High","Normal") -> High
A10: INV-0002 | B10: Bharat Electricals | C10: 37500 | D10: 59 | H10: 2 | I10: How many invoices are overdue? | K10: =IF(ISBLANK(J10),"◯ Not attempted",IF(NOT(_xlfn.ISFORMULA(J10)),"✎ Use a formula",IF(ISNUMBER(J10),IF(ABS(J10-$M$10)<0.005,"✓ Correct","✗ Check again"),"✗ Not a number"))) -> ◯ Not attempted | L10: COUNTIF on your Status column. | M10: =COUNTIF($D$9:$D$38,">90") -> 19 | N10: =IF(D10>90,"Overdue","Current") -> Current | O10: =IF(AND(C10>200000,D10>60),"High","Normal") -> Normal
A11: INV-0003 | B11: Sagar Metals | C11: 43500 | D11: 58 | H11: 3 | I11: Fill Priority: "High" if Amount is over 2,00,000 AND Days is over 60, otherwise "Normal". | J11: → fill column F | K11: =IF(COUNTA($F$9:$F$38)=0,"◯ Not attempted",IF(NOT(_xlfn.ISFORMULA(F9)),"✎ Use a formula",IFERROR(IF(SUMPRODUCT(--(UPPER(TRIM($F$9:$F$38&""))=UPPER(TRIM($O$9:$O$38&""))))=ROWS($F$9:$F$38),"✓ Correct","✗ "&(ROWS($F$9:$F$38)-SUMPRODUCT(--(UPPER(TRIM($F$9:$F$38&""))=UPPER(TRIM($O$9:$O$38&"")))))&" rows differ"),"✗ Check the column"))) -> ◯ Not attempted | L11: Put AND(…,…) inside IF. | N11: =IF(D11>90,"Overdue","Current") -> Current | O11: =IF(AND(C11>200000,D11>60),"High","Normal") -> Normal
A12: INV-0004 | B12: Nova Industries | C12: 350000 | D12: 33 | H12: 4 | I12: Total amount of overdue invoices. | K12: =IF(ISBLANK(J12),"◯ Not attempted",IF(NOT(_xlfn.ISFORMULA(J12)),"✎ Use a formula",IF(ISNUMBER(J12),IF(ABS(J12-$M$12)<0.005,"✓ Correct","✗ Check again"),"✗ Not a number"))) -> ◯ Not attempted | L12: SUMIF(test range, criteria, sum range). | M12: =SUMIF($D$9:$D$38,">90",$C$9:$C$38) -> 4014500 | N12: =IF(D12>90,"Overdue","Current") -> Current | O12: =IF(AND(C12>200000,D12>60),"High","Normal") -> Normal
A13: INV-0005 | B13: Nova Industries | C13: 185000 | D13: 34 | H13: 5 | I13: How many invoices are High priority? | K13: =IF(ISBLANK(J13),"◯ Not attempted",IF(NOT(_xlfn.ISFORMULA(J13)),"✎ Use a formula",IF(ISNUMBER(J13),IF(ABS(J13-$M$13)<0.005,"✓ Correct","✗ Check again"),"✗ Not a number"))) -> ◯ Not attempted | L13: COUNTIFS takes pairs of range and criteria. | M13: =COUNTIFS($C$9:$C$38,">200000",$D$9:$D$38,">60") -> 12 | N13: =IF(D13>90,"Overdue","Current") -> Current | O13: =IF(AND(C13>200000,D13>60),"High","Normal") -> Normal
A14: INV-0006 | B14: Deccan Supplies | C14: 22000 | D14: 117 | N14: =IF(D14>90,"Overdue","Current") -> Overdue | O14: =IF(AND(C14>200000,D14>60),"High","Normal") -> Normal
A15: INV-0007 | B15: Bharat Electricals | C15: 113500 | D15: 176 | N15: =IF(D15>90,"Overdue","Current") -> Overdue | O15: =IF(AND(C15>200000,D15>60),"High","Normal") -> Normal
A16: INV-0008 | B16: Bharat Electricals | C16: 361500 | D16: 96 | N16: =IF(D16>90,"Overdue","Current") -> Overdue | O16: =IF(AND(C16>200000,D16>60),"High","Normal") -> High
A17: INV-0009 | B17: Sagar Metals | C17: 349000 | D17: 163 | N17: =IF(D17>90,"Overdue","Current") -> Overdue | O17: =IF(AND(C17>200000,D17>60),"High","Normal") -> High
A18: INV-0010 | B18: Sagar Metals | C18: 116500 | D18: 35 | N18: =IF(D18>90,"Overdue","Current") -> Current | O18: =IF(AND(C18>200000,D18>60),"High","Normal") -> Normal
A19: INV-0011 | B19: Orbit Systems | C19: 289000 | D19: 145 | N19: =IF(D19>90,"Overdue","Current") -> Overdue | O19: =IF(AND(C19>200000,D19>60),"High","Normal") -> High
A20: INV-0012 | B20: Deccan Supplies | C20: 163500 | D20: 176 | N20: =IF(D20>90,"Overdue","Current") -> Overdue | O20: =IF(AND(C20>200000,D20>60),"High","Normal") -> Normal
A21: INV-0013 | B21: Kiran Agencies | C21: 386000 | D21: 68 | N21: =IF(D21>90,"Overdue","Current") -> Current | O21: =IF(AND(C21>200000,D21>60),"High","Normal") -> High
A22: INV-0014 | B22: Patel & Co | C22: 232500 | D22: 55 | N22: =IF(D22>90,"Overdue","Current") -> Current | O22: =IF(AND(C22>200000,D22>60),"High","Normal") -> Normal
A23: INV-0015 | B23: Orbit Systems | C23: 162000 | D23: 13 | N23: =IF(D23>90,"Overdue","Current") -> Current | O23: =IF(AND(C23>200000,D23>60),"High","Normal") -> Normal
A24: INV-0016 | B24: Patel & Co | C24: 35000 | D24: 151 | N24: =IF(D24>90,"Overdue","Current") -> Overdue | O24: =IF(AND(C24>200000,D24>60),"High","Normal") -> Normal
A25: INV-0017 | B25: Deccan Supplies | C25: 388500 | D25: 115 | N25: =IF(D25>90,"Overdue","Current") -> Overdue | O25: =IF(AND(C25>200000,D25>60),"High","Normal") -> High
... A38: INV-0030 | B38: Shree Enterprises | C38: 85000 | D38: 123 | N38: =IF(D38>90,"Overdue","Current") -> Overdue | O38: =IF(AND(C38>200000,D38>60),"High","Normal") -> Normal

Sheet L4 Rounding and percentages
A1: LESSON 4 · ROUNDING AND PERCENTAGES
A2: ★★★☆☆ Price a purchase order properly — discounts, rounding and shares of total.
A3: CONCEPT · Percentages are fractions: 5% is stored as 0.05. Net = Gross × (1 − Discount). ROUND(x,2) rounds to paise; ROUND(x,-2) to the nearest hundred; ROUNDUP always rounds away from zero — use it when you can't buy half a carton.
A8: Item | B8: Qty | C8: Rate | D8: Discount | E8: Gross | F8: Net | H8: # | I8: Task | J8: Your answer | K8: Check | L8: Hint
A9: A4 paper ream | B9: 109 | C9: 1104.94 | D9: 0 | H9: 1 | I9: Fill Gross = Qty × Rate. | J9: → fill column E | K9: =IF(COUNTA($E$9:$E$28)=0,"◯ Not attempted",IF(NOT(_xlfn.ISFORMULA(E9)),"✎ Use a formula",IFERROR(IF(SUMPRODUCT(--(ABS($E$9:$E$28-$N$9:$N$28)<0.01))=ROWS($E$9:$E$28),"✓ Correct","✗ "&(ROWS($E$9:$E$28)-SUMPRODUCT(--(ABS($E$9:$E$28-$N$9:$N$28)<0.01)))&" rows differ"),"✗ Check the column"))) -> ◯ Not attempted | L9: =B9*C9 | N9: =B9*C9 -> 120438.46 | O9: =ROUND(B9*C9*(1-D9),2) -> 120438.46
A10: Toner cartridge | B10: 64 | C10: 3527.56 | D10: 0.125 | H10: 2 | I10: Fill Net = Gross after discount, rounded to 2 decimals. | J10: → fill column F | K10: =IF(COUNTA($F$9:$F$28)=0,"◯ Not attempted",IF(NOT(_xlfn.ISFORMULA(F9)),"✎ Use a formula",IFERROR(IF(SUMPRODUCT(--(ABS($F$9:$F$28-$O$9:$O$28)<0.01))=ROWS($F$9:$F$28),"✓ Correct","✗ "&(ROWS($F$9:$F$28)-SUMPRODUCT(--(ABS($F$9:$F$28-$O$9:$O$28)<0.01)))&" rows differ"),"✗ Check the column"))) -> ◯ Not attempted | L10: =ROUND(E9*(1-D9),2) | N10: =B10*C10 -> 225763.84 | O10: =ROUND(B10*C10*(1-D10),2) -> 197543.36
A11: Office chair | B11: 139 | C11: 982.44 | D11: 0.02 | H11: 3 | I11: Total net value of the order. | K11: =IF(ISBLANK(J11),"◯ Not attempted",IF(NOT(_xlfn.ISFORMULA(J11)),"✎ Use a formula",IF(ISNUMBER(J11),IF(ABS(J11-$M$11)<0.005,"✓ Correct","✗ Check again"),"✗ Not a number"))) -> ◯ Not attempted | L11: SUM your Net column. | M11: =SUMPRODUCT(ROUND($B$9:$B$28*$C$9:$C$28*(1-$D$9:$D$28),2)) -> 8885563.3 | N11: =B11*C11 -> 136559.16 | O11: =ROUND(B11*C11*(1-D11),2) -> 133827.98
A12: LED monitor | B12: 52 | C12: 6397.89 | D12: 0.02 | H12: 4 | I12: What share of the total net value is the single largest line? (as a %) | K12: =IF(ISBLANK(J12),"◯ Not attempted",IF(NOT(_xlfn.ISFORMULA(J12)),"✎ Use a formula",IF(ISNUMBER(J12),IF(ABS(J12-$M$12)<0.0005,"✓ Correct","✗ Check again"),"✗ Not a number"))) -> ◯ Not attempted | L12: Largest ÷ total. Format the cell as %. | M12: =SUMPRODUCT(MAX(ROUND($B$9:$B$28*$C$9:$C$28*(1-$D$9:$D$28),2)))/SUMPRODUCT(ROUND($B$9:$B$28*$C$9:$C$28*(1-$D$9:$D$28),2)) -> 0.13519869 | N12: =B12*C12 -> 332690.28 | O12: =ROUND(B12*C12*(1-D12),2) -> 326036.47
A13: Keyboard | B13: 52 | C13: 4422.38 | D13: 0 | H13: 5 | I13: Cartons needed if 12 units fit in one carton (round up). | K13: =IF(ISBLANK(J13),"◯ Not attempted",IF(NOT(_xlfn.ISFORMULA(J13)),"✎ Use a formula",IF(ISNUMBER(J13),IF(ABS(J13-$M$13)<0.005,"✓ Correct","✗ Check again"),"✗ Not a number"))) -> ◯ Not attempted | L13: ROUNDUP(total units ÷ 12, 0). | M13: =ROUNDUP(SUM($B$9:$B$28)/12,0) -> 136 | N13: =B13*C13 -> 229963.76 | O13: =ROUND(B13*C13*(1-D13),2) -> 229963.76
A14: Mouse | B14: 51 | C14: 8787.32 | D14: 0.125 | H14: 6 | I14: Total net value rounded to the nearest hundred. | K14: =IF(ISBLANK(J14),"◯ Not attempted",IF(NOT(_xlfn.ISFORMULA(J14)),"✎ Use a formula",IF(ISNUMBER(J14),IF(ABS(J14-$M$14)<0.005,"✓ Correct","✗ Check again"),"✗ Not a number"))) -> ◯ Not attempted | L14: A negative digits argument rounds left of the decimal point. | M14: =ROUND(SUMPRODUCT(ROUND($B$9:$B$28*$C$9:$C$28*(1-$D$9:$D$28),2)),-2) -> 8885600 | N14: =B14*C14 -> 448153.32 | O14: =ROUND(B14*C14*(1-D14),2) -> 392134.16
A15: Desk lamp | B15: 133 | C15: 8632.08 | D15: 0 | N15: =B15*C15 -> 1148066.6 | O15: =ROUND(B15*C15*(1-D15),2) -> 1148066.6
A16: Notebook pack | B16: 138 | C16: 9163.36 | D16: 0.05 | N16: =B16*C16 -> 1264543.7 | O16: =ROUND(B16*C16*(1-D16),2) -> 1201316.5
A17: Pen box | B17: 133 | C17: 8861.67 | D17: 0.1 | N17: =B17*C17 -> 1178602.1 | O17: =ROUND(B17*C17*(1-D17),2) -> 1060741.9
A18: Stapler | B18: 126 | C18: 8898.77 | D18: 0 | N18: =B18*C18 -> 1121245 | O18: =ROUND(B18*C18*(1-D18),2) -> 1121245
A19: File cabinet | B19: 31 | C19: 9685.96 | D19: 0.075 | N19: =B19*C19 -> 300264.76 | O19: =ROUND(B19*C19*(1-D19),2) -> 277744.9
A20: Printer | B20: 26 | C20: 9739.35 | D20: 0.075 | N20: =B20*C20 -> 253223.1 | O20: =ROUND(B20*C20*(1-D20),2) -> 234231.37
A21: Router | B21: 37 | C21: 6873.74 | D21: 0 | N21: =B21*C21 -> 254328.38 | O21: =ROUND(B21*C21*(1-D21),2) -> 254328.38
A22: USB drive | B22: 76 | C22: 6722.95 | D22: 0 | N22: =B22*C22 -> 510944.2 | O22: =ROUND(B22*C22*(1-D22),2) -> 510944.2
A23: Whiteboard | B23: 27 | C23: 2944.44 | D23: 0.02 | N23: =B23*C23 -> 79499.88 | O23: =ROUND(B23*C23*(1-D23),2) -> 77909.88
A24: Projector | B24: 45 | C24: 7100.18 | D24: 0.075 | N24: =B24*C24 -> 319508.1 | O24: =ROUND(B24*C24*(1-D24),2) -> 295544.99
A25: Laptop stand | B25: 100 | C25: 1522.09 | D25: 0.125 | N25: =B25*C25 -> 152209 | O25: =ROUND(B25*C25*(1-D25),2) -> 133182.88
A26: Headset | B26: 88 | C26: 6844.89 | D26: 0.02 | N26: =B26*C26 -> 602350.32 | O26: =ROUND(B26*C26*(1-D26),2) -> 590303.31
... A28: Extension board | B28: 123 | C28: 2417.36 | D28: 0.075 | N28: =B28*C28 -> 297335.28 | O28: =ROUND(B28*C28*(1-D28),2) -> 275035.13

Sheet L5 Text cleanup
A1: LESSON 5 · TEXT CLEANUP
A2: ★★★☆☆ Turn a messy vendor export into clean, matchable data.
A3: CONCEPT · TRIM removes extra spaces, PROPER capitalises each word, UPPER makes capitals. LEFT(text,n) takes the first n characters; MID(text,start,n) takes n characters from a position. A GSTIN holds the state code in characters 1–2 and the PAN in characters 3–12.
A8: Party | B8: GSTIN | C8: City | D8: Clean Party | E8: State Code | F8: PAN | H8: # | I8: Task | J8: Your answer | K8: Check | L8: Hint
A9: Nova Industries | B9: 07AABCF9118O1ZP | C9: New delhi | H9: 1 | I9: Fill Clean Party: remove extra spaces and capitalise each word. | J9: → fill column D | K9: =IF(COUNTA($D$9:$D$33)=0,"◯ Not attempted",IF(NOT(_xlfn.ISFORMULA(D9)),"✎ Use a formula",IFERROR(IF(SUMPRODUCT(--(UPPER(TRIM($D$9:$D$33&""))=UPPER(TRIM($N$9:$N$33&""))))=ROWS($D$9:$D$33),"✓ Correct","✗ "&(ROWS($D$9:$D$33)-SUMPRODUCT(--(UPPER(TRIM($D$9:$D$33&""))=UPPER(TRIM($N$9:$N$33&"")))))&" rows differ"),"✗ Check the column"))) -> ◯ Not attempted | L9: =PROPER(TRIM(A9)) — TRIM first, then PROPER. | N9: =PROPER(TRIM(A9)) -> Nova Industries | O9: =LEFT(B9,2) -> 07 | P9: =UPPER(MID(B9,3,10)) -> AABCF9118O
A10: abc traders | B10: 24aabck1630h1zj | C10: surat | H10: 2 | I10: Fill State Code: the first two characters of the GSTIN. | J10: → fill column E | K10: =IF(COUNTA($E$9:$E$33)=0,"◯ Not attempted",IF(NOT(_xlfn.ISFORMULA(E9)),"✎ Use a formula",IFERROR(IF(SUMPRODUCT(--(UPPER(TRIM($E$9:$E$33&""))=UPPER(TRIM($O$9:$O$33&""))))=ROWS($E$9:$E$33),"✓ Correct","✗ "&(ROWS($E$9:$E$33)-SUMPRODUCT(--(UPPER(TRIM($E$9:$E$33&""))=UPPER(TRIM($O$9:$O$33&"")))))&" rows differ"),"✗ Check the column"))) -> ◯ Not attempted | L10: =LEFT(B9,2) | N10: =PROPER(TRIM(A10)) -> Abc Traders | O10: =LEFT(B10,2) -> 24 | P10: =UPPER(MID(B10,3,10)) -> AABCK1630H
A11: Nova Industries | B11: 29AABCS7050Y1ZZ | C11: Nagpur | H11: 3 | I11: Fill PAN: characters 3 to 12 of the GSTIN, in capitals. | J11: → fill column F | K11: =IF(COUNTA($F$9:$F$33)=0,"◯ Not attempted",IF(NOT(_xlfn.ISFORMULA(F9)),"✎ Use a formula",IFERROR(IF(SUMPRODUCT(--(UPPER(TRIM($F$9:$F$33&""))=UPPER(TRIM($P$9:$P$33&""))))=ROWS($F$9:$F$33),"✓ Correct","✗ "&(ROWS($F$9:$F$33)-SUMPRODUCT(--(UPPER(TRIM($F$9:$F$33&""))=UPPER(TRIM($P$9:$P$33&"")))))&" rows differ"),"✗ Check the column"))) -> ◯ Not attempted | L11: =UPPER(MID(B9,3,10)) | N11: =PROPER(TRIM(A11)) -> Nova Industries | O11: =LEFT(B11,2) -> 29 | P11: =UPPER(MID(B11,3,10)) -> AABCS7050Y
A12: ABC Traders | B12: 33AABCV5945C1ZF | C12: New delhi | H12: 4 | I12: How many party names had extra spaces? | K12: =IF(ISBLANK(J12),"◯ Not attempted",IF(NOT(_xlfn.ISFORMULA(J12)),"✎ Use a formula",IF(ISNUMBER(J12),IF(ABS(J12-$M$12)<0.005,"✓ Correct","✗ Check again"),"✗ Not a number"))) -> ◯ Not attempted | L12: If TRIM changes the length, there were extra spaces. | M12: =SUMPRODUCT(--(LEN($A$9:$A$33)<>LEN(TRIM($A$9:$A$33)))) -> 14 | N12: =PROPER(TRIM(A12)) -> Abc Traders | O12: =LEFT(B12,2) -> 33 | P12: =UPPER(MID(B12,3,10)) -> AABCV5945C
A13: ABC TRADERS | B13: 33aabcb6799b1zh | C13: surat | H13: 5 | I13: How many GSTINs are from Maharashtra (state code 27)? | K13: =IF(ISBLANK(J13),"◯ Not attempted",IF(NOT(_xlfn.ISFORMULA(J13)),"✎ Use a formula",IF(ISNUMBER(J13),IF(ABS(J13-$M$13)<0.005,"✓ Correct","✗ Check again"),"✗ Not a number"))) -> ◯ Not attempted | L13: COUNTIF on your State Code column. | M13: =SUMPRODUCT(--(LEFT($B$9:$B$33,2)="27")) -> 1 | N13: =PROPER(TRIM(A13)) -> Abc Traders | O13: =LEFT(B13,2) -> 33 | P13: =UPPER(MID(B13,3,10)) -> AABCB6799B
A14: Shree Enterprises | B14: 24AABCN8183I1ZL | C14: chennai | N14: =PROPER(TRIM(A14)) -> Shree Enterprises | O14: =LEFT(B14,2) -> 24 | P14: =UPPER(MID(B14,3,10)) -> AABCN8183I
A15: nandini foods | B15: 29AABCM3262Y1ZF | C15: MUMBAI | N15: =PROPER(TRIM(A15)) -> Nandini Foods | O15: =LEFT(B15,2) -> 29 | P15: =UPPER(MID(B15,3,10)) -> AABCM3262Y
A16: Vaibhav Textiles | B16: 07aabcb1882q1zd | C16: chennai | N16: =PROPER(TRIM(A16)) -> Vaibhav Textiles | O16: =LEFT(B16,2) -> 07 | P16: =UPPER(MID(B16,3,10)) -> AABCB1882Q
A17: ORBIT SYSTEMS | B17: 29AABCO7109T1ZJ | C17: MUMBAI | N17: =PROPER(TRIM(A17)) -> Orbit Systems | O17: =LEFT(B17,2) -> 29 | P17: =UPPER(MID(B17,3,10)) -> AABCO7109T
A18: Nova Industries | B18: 33AABCX2048M1ZD | C18: BENGALURU | N18: =PROPER(TRIM(A18)) -> Nova Industries | O18: =LEFT(B18,2) -> 33 | P18: =UPPER(MID(B18,3,10)) -> AABCX2048M
A19: ABC Traders | B19: 33AABCI6664M1ZF | C19: MUMBAI | N19: =PROPER(TRIM(A19)) -> Abc Traders | O19: =LEFT(B19,2) -> 33 | P19: =UPPER(MID(B19,3,10)) -> AABCI6664M
A20: Meera Pharma | B20: 07AABCQ7836X1ZN | C20: pune | N20: =PROPER(TRIM(A20)) -> Meera Pharma | O20: =LEFT(B20,2) -> 07 | P20: =UPPER(MID(B20,3,10)) -> AABCQ7836X
A21: Deccan Supplies | B21: 07aabcd1208f1zi | C21: MUMBAI | N21: =PROPER(TRIM(A21)) -> Deccan Supplies | O21: =LEFT(B21,2) -> 07 | P21: =UPPER(MID(B21,3,10)) -> AABCD1208F
A22: Sagar Metals | B22: 29aabcq5039r1zs | C22: MUMBAI | N22: =PROPER(TRIM(A22)) -> Sagar Metals | O22: =LEFT(B22,2) -> 29 | P22: =UPPER(MID(B22,3,10)) -> AABCQ5039R
A23: ABC TRADERS | B23: 07AABCG8803D1ZT | C23: Nagpur | N23: =PROPER(TRIM(A23)) -> Abc Traders | O23: =LEFT(B23,2) -> 07 | P23: =UPPER(MID(B23,3,10)) -> AABCG8803D
A24: nova industries | B24: 24aabcf3597p1zn | C24: Nagpur | N24: =PROPER(TRIM(A24)) -> Nova Industries | O24: =LEFT(B24,2) -> 24 | P24: =UPPER(MID(B24,3,10)) -> AABCF3597P
A25: SHREE ENTERPRISES | B25: 07AABCI3935V1ZA | C25: MUMBAI | N25: =PROPER(TRIM(A25)) -> Shree Enterprises | O25: =LEFT(B25,2) -> 07 | P25: =UPPER(MID(B25,3,10)) -> AABCI3935V
... A33: bharat electricals | B33: 29AABCZ1007F1ZB | C33: BENGALURU | N33: =PROPER(TRIM(A33)) -> Bharat Electricals | O33: =LEFT(B33,2) -> 29 | P33: =UPPER(MID(B33,3,10)) -> AABCZ1007F

Sheet L6 Boss round — foundations
A1: LESSON 6 · BOSS ROUND — FOUNDATIONS
A2: ★★★★☆ Five questions, no hand-holding. Everything from lessons 1–5.
A3: CONCEPT · Rate is stored as a whole number (18 means 18%), so divide by 100. Think about which function each question needs before you type.
A8: Invoice | B8: Party | C8: State | D8: Taxable | E8: Rate | F8: Days | H8: # | I8: Task | J8: Your answer | K8: Check | L8: Hint
A9: INV-0001 | B9: Bharat Electricals | C9: Gujarat | D9: 362500 | E9: 28 | F9: 181 | H9: 1 | I9: Total GST on the whole register, without adding a helper column. | K9: =IF(ISBLANK(J9),"◯ Not attempted",IF(NOT(_xlfn.ISFORMULA(J9)),"✎ Use a formula",IF(ISNUMBER(J9),IF(ABS(J9-$M$9)<0.005,"✓ Correct","✗ Check again"),"✗ Not a number"))) -> ◯ Not attempted | L9: SUMPRODUCT multiplies two columns row by row, then adds. | M9: =SUMPRODUCT($D$9:$D$48,$E$9:$E$48)/100 -> 1213005
A10: INV-0002 | B10: Patel & Co | C10: Gujarat | D10: 191500 | E10: 12 | F10: 5 | H10: 2 | I10: Average taxable value of invoices more than 90 days old. | K10: =IF(ISBLANK(J10),"◯ Not attempted",IF(NOT(_xlfn.ISFORMULA(J10)),"✎ Use a formula",IF(ISNUMBER(J10),IF(ABS(J10-$M$10)<0.005,"✓ Correct","✗ Check again"),"✗ Not a number"))) -> ◯ Not attempted | L10: AVERAGEIF(test range, criteria, average range). | M10: =AVERAGEIF($F$9:$F$48,">90",$D$9:$D$48) -> 192714.29
A11: INV-0003 | B11: Orbit Systems | C11: Tamil Nadu | D11: 394000 | E11: 12 | F11: 81 | H11: 3 | I11: What percentage of invoices are more than 90 days old? | K11: =IF(ISBLANK(J11),"◯ Not attempted",IF(NOT(_xlfn.ISFORMULA(J11)),"✎ Use a formula",IF(ISNUMBER(J11),IF(ABS(J11-$M$11)<0.0005,"✓ Correct","✗ Check again"),"✗ Not a number"))) -> ◯ Not attempted | L11: Count overdue ÷ count all. | M11: =COUNTIF($F$9:$F$48,">90")/COUNTA($A$9:$A$48) -> 0.525
A12: INV-0004 | B12: Deccan Supplies | C12: Tamil Nadu | D12: 41000 | E12: 28 | F12: 173 | H12: 4 | I12: Taxable value billed in Maharashtra at the 18% rate. | K12: =IF(ISBLANK(J12),"◯ Not attempted",IF(NOT(_xlfn.ISFORMULA(J12)),"✎ Use a formula",IF(ISNUMBER(J12),IF(ABS(J12-$M$12)<0.005,"✓ Correct","✗ Check again"),"✗ Not a number"))) -> ◯ Not attempted | L12: SUMIFS with two conditions. | M12: =SUMIFS($D$9:$D$48,$C$9:$C$48,"Maharashtra",$E$9:$E$48,18) -> 451000
A13: INV-0005 | B13: Deccan Supplies | C13: Tamil Nadu | D13: 365000 | E13: 5 | F13: 180 | H13: 5 | I13: Which party has the single largest invoice? | K13: =IF(ISBLANK(J13),"◯ Not attempted",IF(NOT(_xlfn.ISFORMULA(J13)),"✎ Use a formula",IF(UPPER(TRIM(J13&""))=UPPER(TRIM($M$13&"")),"✓ Correct","✗ Check again"))) -> ◯ Not attempted | L13: MAX finds the amount; MATCH finds its row; INDEX returns the party. | M13: =INDEX($B$9:$B$48,MATCH(MAX($D$9:$D$48),$D$9:$D$48,0)) -> Shree Enterprises
A14: INV-0006 | B14: Orbit Systems | C14: Karnataka | D14: 26000 | E14: 5 | F14: 95
A15: INV-0007 | B15: Nandini Foods | C15: Karnataka | D15: 173500 | E15: 5 | F15: 16
A16: INV-0008 | B16: Orbit Systems | C16: Maharashtra | D16: 199000 | E16: 18 | F16: 59
A17: INV-0009 | B17: Patel & Co | C17: Karnataka | D17: 95000 | E17: 12 | F17: 36
A18: INV-0010 | B18: Sagar Metals | C18: Delhi | D18: 152000 | E18: 18 | F18: 150
A19: INV-0011 | B19: Meera Pharma | C19: Maharashtra | D19: 79500 | E19: 18 | F19: 179
A20: INV-0012 | B20: ABC Traders | C20: Delhi | D20: 99500 | E20: 28 | F20: 173
A21: INV-0013 | B21: Nandini Foods | C21: Karnataka | D21: 150500 | E21: 18 | F21: 147
A22: INV-0014 | B22: Meera Pharma | C22: Karnataka | D22: 80500 | E22: 28 | F22: 173
A23: INV-0015 | B23: Sagar Metals | C23: Delhi | D23: 406000 | E23: 12 | F23: 113
A24: INV-0016 | B24: ABC Traders | C24: Maharashtra | D24: 163500 | E24: 18 | F24: 52
A25: INV-0017 | B25: Deccan Supplies | C25: Gujarat | D25: 406000 | E25: 12 | F25: 21
... A48: INV-0040 | B48: Bharat Electricals | C48: Maharashtra | D48: 236500 | E48: 12 | F48: 53

Sheet Solutions
A1: SOLUTIONS & OTHER WAYS — open only after you have tried
A2: Model answers are shapes, not the only answer. If your formula gives the same result, it is right — compare the logic.
A4: L1 Totals and counts ★
A5: # | B5: Task | C5: Answer cell | D5: Model formula | E5: Other ways | F5: Why it works
A6: 1 | B6: Total taxable value of all invoices. | C6: I9 | D6: =SUM($E$9:$E$38) | E6: =SUMPRODUCT(E9:E38) | F6: SUM adds every number in the range and ignores text and blanks.
A7: 2 | B7: How many invoices are in the register? Count the invoice numbers. | C7: I10 | D7: =COUNTA($A$9:$A$38) | E7: =ROWS(A9:A38) =COUNT(E9:E38) — counts the amounts instead | F7: COUNT only counts numbers; COUNTA counts any filled cell.
A8: 3 | B8: Average taxable value per invoice. | C8: I11 | D8: =AVERAGE($E$9:$E$38) | E8: =SUM(E9:E38)/COUNT(E9:E38) | F8: AVERAGE is the total divided by how many numbers there are.
A9: 4 | B9: The largest single invoice. | C9: I12 | D9: =MAX($E$9:$E$38) | E9: =LARGE(E9:E38,1)
A10: 5 | B10: The smallest single invoice. | C10: I13 | D10: =MIN($E$9:$E$38) | E10: =SMALL(E9:E38,1)
A11: 6 | B11: How many invoices are above ₹1,00,000? | C11: I14 | D11: =COUNTIF($E$9:$E$38,">100000") | E11: =SUMPRODUCT(--(E9:E38>100000)) =COUNTIFS(E9:E38,">100000") | F11: COUNTIF counts cells that meet one condition.
A13: L2 References and the $ sign ★★
A14: # | B14: Task | C14: Answer cell | D14: Model formula | E14: Other ways | F14: Why it works
A15: 1 | B15: Fill GST Amount for every invoice: Taxable × the GST rate in B6, rounded to 2 decimals. | C15: column D | D15: =ROUND(C9*$B$6,2) (row 9, then fill down) | E15: =C9*$B$6 then format to 2 decimals — displays the same but isn't really rounded | F15: Without $, row 10 would read C10*B7, an empty cell.
A16: 2 | B16: Fill Invoice Total: Taxable + GST Amount. | C16: column E | D16: =C9+D9 (row 9, then fill down) | E16: =SUM(C9:D9)
A17: 3 | B17: Total GST payable for the register. | C17: I11 | D17: =SUM($D$9:$D$33) | E17: =ROUND(SUM(C9:C33)*$B$6,2) — can differ by a few paise: round each row first, then add | F17: Rounding per row matches how invoices are actually printed.
A18: 4 | B18: Change B6 to 12% and back to 18%. Now: the total of all Invoice Totals. | C18: I12 | D18: =SUM($E$9:$E$33) | F18: A model is only right if changing an input flows through every formula.
A20: L3 IF logic ★★
A21: # | B21: Task | C21: Answer cell | D21: Model formula | E21: Other ways | F21: Why it works
A22: 1 | B22: Fill Status: "Overdue" if Days is more than 90, otherwise "Current". | C22: column E | D22: =IF(D9>90,"Overdue","Current") (row 9, then fill down) | E22: =IF(D9<=90,"Current","Overdue") | F22: The comparison produces TRUE or FALSE; IF turns that into a label.
A23: 2 | B23: How many invoices are overdue? | C23: J10 | D23: =COUNTIF($E$9:$E$38,"Overdue") | E23: =COUNTIF(D9:D38,">90")
A24: 3 | B24: Fill Priority: "High" if Amount is over 2,00,000 AND Days is over 60, otherwise "Normal". | C24: column F | D24: =IF(AND(C9>200000,D9>60),"High","Normal") (row 9, then fill down) | E24: =IF((C9>200000)*(D9>60),"High","Normal") — multiplying two tests is AND in array logic | F24: AND returns TRUE only if every test is TRUE.
A25: 4 | B25: Total amount of overdue invoices. | C25: J12 | D25: =SUMIF($D$9:$D$38,">90",$C$9:$C$38) | E25: =SUMIFS(C9:C38,D9:D38,">90") =SUMIF(E9:E38,"Overdue",C9:C38)
A26: 5 | B26: How many invoices are High priority? | C26: J13 | D26: =COUNTIFS($C$9:$C$38,">200000",$D$9:$D$38,">60") | E26: =COUNTIF(F9:F38,"High")
A28: L4 Rounding and percentages ★★★
A29: # | B29: Task | C29: Answer cell | D29: Model formula | E29: Other ways | F29: Why it works
A30: 1 | B30: Fill Gross = Qty × Rate. | C30: column E | D30: =B9*C9 (row 9, then fill down)
A31: 2 | B31: Fill Net = Gross after discount, rounded to 2 decimals. | C31: column F | D31: =ROUND(E9*(1-D9),2) (row 9, then fill down) | E31: =ROUND(E9-E9*D9,2) | F31: 1 − 5% = 0.95, so you keep 95% of the gross.
A32: 3 | B32: Total net value of the order. | C32: J11 | D32: =SUM($F$9:$F$28)
A33: 4 | B33: What share of the total net value is the single largest line? (as a %) | C33: J12 | D33: =MAX($F$9:$F$28)/SUM($F$9:$F$28) | E33: =LARGE(F9:F28,1)/SUM(F9:F28)
A34: 5 | B34: Cartons needed if 12 units fit in one carton (round up). | C34: J13 | D34: =ROUNDUP(SUM($B$9:$B$28)/12,0) | E34: =CEILING(SUM(B9:B28)/12,1) =INT((SUM(B9:B28)+11)/12)
A35: 6 | B35: Total net value rounded to the nearest hundred. | C35: J14 | D35: =ROUND(SUM($F$9:$F$28),-2)
A37: L5 Text cleanup ★★★
A38: # | B38: Task | C38: Answer cell | D38: Model formula | E38: Other ways | F38: Why it works
A39: 1 | B39: Fill Clean Party: remove extra spaces and capitalise each word. | C39: column D | D39: =PROPER(TRIM(A9)) (row 9, then fill down) | F39: Clean keys are the difference between a lookup that works and one that returns #N/A.
A40: 2 | B40: Fill State Code: the first two characters of the GSTIN. | C40: column E | D40: =LEFT(B9,2) (row 9, then fill down) | E40: =MID(B9,1,2)
A41: 3 | B41: Fill PAN: characters 3 to 12 of the GSTIN, in capitals. | C41: column F | D41: =UPPER(MID(B9,3,10)) (row 9, then fill down)
A42: 4 | B42: How many party names had extra spaces? | C42: J12 | D42: =SUMPRODUCT(--(LEN($A$9:$A$33)<>LEN(TRIM($A$9:$A$33)))) | E42: Helper column =LEN(A9)<>LEN(TRIM(A9)), then COUNTIF(…,TRUE)
A43: 5 | B43: How many GSTINs are from Maharashtra (state code 27)? | C43: J13 | D43: =COUNTIF($E$9:$E$33,"27")
A45: L6 Boss round — foundations ★★★★
A46: # | B46: Task | C46: Answer cell | D46: Model formula | E46: Other ways | F46: Why it works
...
